Workbook

Sheet 主线杀怪
C1: 伤害溢出修正 | E1: 技能目标误差修正
C2: 0.8 | E2: 0.8
C4: 怪物属性设计 | N4: 目标玩家能力（简易版，仅有计算玩家基础属性,不计算化神，宠物，以后再添加特殊属性和化神等因素） | Y4: 怪物属性
A5: 怪物名字 | B5: 怪物等级 | C5: 属性等级 | D5: 怪物类型 | E5: 能力模板 | F5: 怪物受击 | G5: 玩家受击 | H5: 防御抵消比例 | I5: 玩家对怪物命中 | J5: 怪物对玩家命中 | K5: 怪物技能系数 | L5: 围攻怪物个数 | M5: 攻击间隔/s | N5: 生命 | O5: 攻击 | P5: 防御 | Q5: 命中 | R5: 闪避 | S5: 技能固定伤害 | T5: 回血间隔 | U5: 回血量 | V5: 每招平均目标 | W5: 每招平均技能伤害 | X5: 每招平均固伤 | Y5: 生命 | Z5: 攻击 | AA5: 防御 | AB5: 命中 | AC5: 闪避
A6: 任务100012小怪 | B6: 24 | C6: 24 | D6: 小怪 | E6: 非R | F6: =6/10*V6/0.6 -> 2.3 | G6: 0 | H6: 0 | I6: 1 | J6: 1 | K6: 2 | L6: 15 | M6: 2 | N6: =HLOOKUP(N$5,[1]非R能力!$B$8:$F$558,$B6+1,0) -> 2560 | O6: =HLOOKUP(O$5,[1]非R能力!$B$8:$F$558,$B6+1,0) -> 820.07692 | P6: =HLOOKUP(P$5,[1]非R能力!$B$8:$F$558,$B6+1,0) -> 416 | Q6: =HLOOKUP(Q$5,[1]非R能力!$B$8:$F$558,$B6+1,0) -> 185.33333 | R6: =HLOOKUP(R$5,[1]非R能力!$B$8:$F$558,$B6+1,0) -> 181.17949 | S6: =INDEX([1]非R能力!$H$9:$H$558,C6) -> 0 | T6: =IF(D6="小怪",0,IF(INDEX([1]非R能力!$FK$9:$FK$558,B6)=0,0,10)) -> 0 | U6: =IF(D6="小怪",0,IF(INDEX([1]非R能力!$FH$9:$FH$558,B6)=0,0,5000)) -> 0 | V6: =HLOOKUP(V$5,[2]人物技能基础!$O$3:$Q$553,$B6+1,0) -> 2.3 | W6: =HLOOKUP(W$5,[2]人物技能基础!$O$3:$Q$553,$B6+1,0) -> 1.485 | X6: =HLOOKUP(X$5,[2]人物技能基础!$O$3:$Q$553,$B6+1,0) -> 57.5 | Y6: =INT(((O6-AA6)*W6+(X6+S6))*F6*I6*$C$2) -> 2346 | Z6: =IF(G6=0,IF(T6=0,INT(P6/5),IF(U6=0,INT(P6/5),INT((U6/T6)/(1/M6*L6)/K6+P6))),INT((IF(T6=0,0,U6/T6/(1/M6*L6))+N6/G6)/K6+P6)) -> 83 | AA6: =INT(O6*H6) -> 0 | AB6: =INT(J6*R6) -> 181 | AC6: =INT(Q6/I6) -> 185 | AF6: （（攻击-怪物防御）*技能系数+技能固伤）*怪物受击*玩家命中*伤害溢出修正
A7: 任务100018小怪 | B7: 33 | C7: 33 | D7: 小怪 | E7: 非R | F7: =6/10*V7/0.6 -> 2.6 | G7: 0 | H7: 0 | I7: 1 | J7: 1 | K7: 2 | L7: 15 | M7: 2 | N7: =HLOOKUP(N$5,[1]非R能力!$B$8:$F$558,$B7+1,0) -> 3727 | O7: =HLOOKUP(O$5,[1]非R能力!$B$8:$F$558,$B7+1,0) -> 1156.4444 | P7: =HLOOKUP(P$5,[1]非R能力!$B$8:$F$558,$B7+1,0) -> 862.04762 | Q7: =HLOOKUP(Q$5,[1]非R能力!$B$8:$F$558,$B7+1,0) -> 266.7619 | R7: =HLOOKUP(R$5,[1]非R能力!$B$8:$F$558,$B7+1,0) -> 266.79487 | S7: =INDEX([1]非R能力!$H$9:$H$558,C7) -> 0 | T7: =IF(D7="小怪",0,IF(INDEX([1]非R能力!$FK$9:$FK$558,B7)=0,0,10)) -> 0 | U7: =IF(D7="小怪",0,IF(INDEX([1]非R能力!$FH$9:$FH$558,B7)=0,0,5000)) -> 0 | V7: =HLOOKUP(V$5,[2]人物技能基础!$O$3:$Q$553,$B7+1,0) -> 2.6 | W7: =HLOOKUP(W$5,[2]人物技能基础!$O$3:$Q$553,$B7+1,0) -> 1.625 | X7: =HLOOKUP(X$5,[2]人物技能基础!$O$3:$Q$553,$B7+1,0) -> 67.5 | Y7: =INT(((O7-AA7)*W7+(X7+S7))*F7*I7*$C$2) -> 4049 | Z7: =IF(G7=0,IF(T7=0,INT(P7/5),IF(U7=0,INT(P7/5),INT((U7/T7)/(1/M7*L7)/K7+P7))),INT((IF(T7=0,0,U7/T7/(1/M7*L7))+N7/G7)/K7+P7)) -> 172 | AA7: =INT(O7*H7) -> 0 | AB7: =INT(J7*R7) -> 266 | AC7: =INT(Q7/I7) -> 266
A8: 任务100021小怪 | B8: 41 | C8: 41 | D8: 小怪 | E8: 非R | F8: =6/10*V8/0.6 -> 2.9 | G8: 0 | H8: 0 | I8: 1 | J8: 1 | K8: 2 | L8: 15 | M8: 2 | N8: =HLOOKUP(N$5,[1]非R能力!$B$8:$F$558,$B8+1,0) -> 5151 | O8: =HLOOKUP(O$5,[1]非R能力!$B$8:$F$558,$B8+1,0) -> 1364.2222 | P8: =HLOOKUP(P$5,[1]非R能力!$B$8:$F$558,$B8+1,0) -> 956.2381 | Q8: =HLOOKUP(Q$5,[1]非R能力!$B$8:$F$558,$B8+1,0) -> 293.80952 | R8: =HLOOKUP(R$5,[1]非R能力!$B$8:$F$558,$B8+1,0) -> 342.89744 | S8: =INDEX([1]非R能力!$H$9:$H$558,C8) -> 0 | T8: =IF(D8="小怪",0,IF(INDEX([1]非R能力!$FK$9:$FK$558,B8)=0,0,10)) -> 0 | U8: =IF(D8="小怪",0,IF(INDEX([1]非R能力!$FH$9:$FH$558,B8)=0,0,5000)) -> 0 | V8: =HLOOKUP(V$5,[2]人物技能基础!$O$3:$Q$553,$B8+1,0) -> 2.9 | W8: =HLOOKUP(W$5,[2]人物技能基础!$O$3:$Q$553,$B8+1,0) -> 1.7675 | X8: =HLOOKUP(X$5,[2]人物技能基础!$O$3:$Q$553,$B8+1,0) -> 78.75 | Y8: =INT(((O8-AA8)*W8+(X8+S8))*F8*I8*$C$2) -> 5776 | Z8: =IF(G8=0,IF(T8=0,INT(P8/5),IF(U8=0,INT(P8/5),INT((U8/T8)/(1/M8*L8)/K8+P8))),INT((IF(T8=0,0,U8/T8/(1/M8*L8))+N8/G8)/K8+P8)) -> 191 | AA8: =INT(O8*H8) -> 0 | AB8: =INT(J8*R8) -> 342 | AC8: =INT(Q8/I8) -> 293
F11: 时间/（每只受击次数*0.6）*群攻效率=10
F12: 每只受击次数=时间/10*群攻效率/0.6

Sheet 关卡
D1: 伤害溢出修正 | F1: 技能目标误差修正
D2: 0.8 | F2: 0.8
D4: 怪物属性设计 | O4: 目标玩家能力（简易版，仅有计算玩家基础属性,不计算化神，宠物，以后再添加特殊属性和化神等因素） | Z4: 怪物属性
A5: 关卡数 | B5: 怪物名字 | C5: 怪物等级 | D5: 属性等级 | E5: 怪物类型 | F5: 能力模板 | G5: 怪物受击 | H5: 玩家受击 | I5: 防御抵消比例 | J5: 玩家对怪物命中 | K5: 怪物对玩家命中 | L5: 怪物技能系数 | M5: 围攻怪物个数 | N5: 攻击间隔/s | O5: 生命 | P5: 攻击 | Q5: 防御 | R5: 命中 | S5: 闪避 | T5: 技能固定伤害 | U5: 回血间隔 | V5: 回血量 | W5: 每招平均目标 | X5: 每招平均技能伤害 | Y5: 每招平均固伤 | Z5: 生命 | AA5: 攻击 | AB5: 防御 | AC5: 命中 | AD5: 闪避 | AF5: 怪物属性算法
A6: 1 | B6: ="关卡"&A6&E6 -> 关卡1小怪 | C6: =INDEX([3]关卡!$J$19:$J$2018,A6) -> 45 | D6: =INDEX([3]关卡!$N$19:$N$2018,A6) -> 30 | E6: 小怪 | F6: 非R | G6: 1 | H6: 0 | I6: 0 | J6: 1 | K6: 1 | L6: 2 | M6: 15 | N6: 2 | O6: =HLOOKUP(O$5,[1]非R能力!$B$8:$F$558,$C6+1,0) -> 5935 | P6: =HLOOKUP(P$5,[1]非R能力!$B$8:$F$558,$C6+1,0) -> 1477.1111 | Q6: =HLOOKUP(Q$5,[1]非R能力!$B$8:$F$558,$C6+1,0) -> 1006.3333 | R6: =HLOOKUP(R$5,[1]非R能力!$B$8:$F$558,$C6+1,0) -> 307.33333 | S6: =HLOOKUP(S$5,[1]非R能力!$B$8:$F$558,$C6+1,0) -> 380.94872 | T6: =INDEX([1]非R能力!$H$9:$H$558,D6) -> 0 | U6: =IF(E6="小怪",0,IF(INDEX([1]非R能力!$FK$9:$FK$558,C6)=0,0,10)) -> 0 | V6: =IF(E6="小怪",0,IF(INDEX([1]非R能力!$FH$9:$FH$558,C6)=0,0,5000)) -> 0 | W6: =HLOOKUP(W$5,[2]人物技能基础!$O$3:$Q$553,$C6+1,0) -> 3.38 | X6: =HLOOKUP(X$5,[2]人物技能基础!$O$3:$Q$553,$C6+1,0) -> 1.8965 | Y6: =HLOOKUP(Y$5,[2]人物技能基础!$O$3:$Q$553,$C6+1,0) -> 89.25 | Z6: =INT(((P6-AB6)*X6+(Y6+T6))*G6*J6*$D$2) -> 2312 | AA6: =IF(H6=0,IF(U6=0,INT(Q6/5),IF(V6=0,INT(Q6/5),INT((V6/U6)/(1/N6*M6)/L6+Q6))),INT((IF(U6=0,0,V6/U6/(1/N6*M6))+O6/H6)/L6+Q6)) -> 201 | AB6: =INT(P6*I6) -> 0 | AC6: =INT(K6*S6) -> 380 | AD6: =INT(R6/J6) -> 307 | AF6: 生命 | AG6: （（攻击-怪物防御）*技能系数+技能固伤）*怪物受击*玩家命中*伤害溢出修正
A7: 2 | B7: ="关卡"&A7&E7 -> 关卡2小怪 | C7: =INDEX([3]关卡!$J$19:$J$2018,A7) -> 47 | D7: =INDEX([3]关卡!$N$19:$N$2018,A7) -> 32 | E7: 小怪 | F7: 非R | G7: 1 | H7: 0 | I7: 0 | J7: 1 | K7: 1 | L7: 2 | M7: 15 | N7: 2 | O7: =HLOOKUP(O$5,[1]非R能力!$B$8:$F$558,$C7+1,0) -> 6327 | P7: =HLOOKUP(P$5,[1]非R能力!$B$8:$F$558,$C7+1,0) -> 1533.5556 | Q7: =HLOOKUP(Q$5,[1]非R能力!$B$8:$F$558,$C7+1,0) -> 1031.381 | R7: =HLOOKUP(R$5,[1]非R能力!$B$8:$F$558,$C7+1,0) -> 314.09524 | S7: =HLOOKUP(S$5,[1]非R能力!$B$8:$F$558,$C7+1,0) -> 399.97436 | T7: =INDEX([1]非R能力!$H$9:$H$558,D7) -> 0 | U7: =IF(E7="小怪",0,IF(INDEX([1]非R能力!$FK$9:$FK$558,C7)=0,0,10)) -> 0 | V7: =IF(E7="小怪",0,IF(INDEX([1]非R能力!$FH$9:$FH$558,C7)=0,0,5000)) -> 0 | W7: =HLOOKUP(W$5,[2]人物技能基础!$O$3:$Q$553,$C7+1,0) -> 3.38 | X7: =HLOOKUP(X$5,[2]人物技能基础!$O$3:$Q$553,$C7+1,0) -> 1.8965 | Y7: =HLOOKUP(Y$5,[2]人物技能基础!$O$3:$Q$553,$C7+1,0) -> 89.25 | Z7: =INT(((P7-AB7)*X7+(Y7+T7))*G7*J7*$D$2) -> 2398 | AA7: =IF(H7=0,IF(U7=0,INT(Q7/5),IF(V7=0,INT(Q7/5),INT((V7/U7)/(1/N7*M7)/L7+Q7))),INT((IF(U7=0,0,V7/U7/(1/N7*M7))+O7/H7)/L7+Q7)) -> 206 | AB7: =INT(P7*I7) -> 0 | AC7: =INT(K7*S7) -> 399 | AD7: =INT(R7/J7) -> 314 | AF7: 防御 | AG7: 攻击*防御抵消
A8: 3 | B8: ="关卡"&A8&E8 -> 关卡3小怪 | C8: =INDEX([3]关卡!$J$19:$J$2018,A8) -> 48 | D8: =INDEX([3]关卡!$N$19:$N$2018,A8) -> 33 | E8: 小怪 | F8: 非R | G8: 1 | H8: 0 | I8: 0 | J8: 1 | K8: 1 | L8: 2 | M8: 15 | N8: 2 | O8: =HLOOKUP(O$5,[1]非R能力!$B$8:$F$558,$C8+1,0) -> 6523 | P8: =HLOOKUP(P$5,[1]非R能力!$B$8:$F$558,$C8+1,0) -> 1561.7778 | Q8: =HLOOKUP(Q$5,[1]非R能力!$B$8:$F$558,$C8+1,0) -> 1043.9048 | R8: =HLOOKUP(R$5,[1]非R能力!$B$8:$F$558,$C8+1,0) -> 317.47619 | S8: =HLOOKUP(S$5,[1]非R能力!$B$8:$F$558,$C8+1,0) -> 409.48718 | T8: =INDEX([1]非R能力!$H$9:$H$558,D8) -> 0 | U8: =IF(E8="小怪",0,IF(INDEX([1]非R能力!$FK$9:$FK$558,C8)=0,0,10)) -> 0 | V8: =IF(E8="小怪",0,IF(INDEX([1]非R能力!$FH$9:$FH$558,C8)=0,0,5000)) -> 0 | W8: =HLOOKUP(W$5,[2]人物技能基础!$O$3:$Q$553,$C8+1,0) -> 3.38 | X8: =HLOOKUP(X$5,[2]人物技能基础!$O$3:$Q$553,$C8+1,0) -> 1.8965 | Y8: =HLOOKUP(Y$5,[2]人物技能基础!$O$3:$Q$553,$C8+1,0) -> 89.25 | Z8: =INT(((P8-AB8)*X8+(Y8+T8))*G8*J8*$D$2) -> 2440 | AA8: =IF(H8=0,IF(U8=0,INT(Q8/5),IF(V8=0,INT(Q8/5),INT((V8/U8)/(1/N8*M8)/L8+Q8))),INT((IF(U8=0,0,V8/U8/(1/N8*M8))+O8/H8)/L8+Q8)) -> 208 | AB8: =INT(P8*I8) -> 0 | AC8: =INT(K8*S8) -> 409 | AD8: =INT(R8/J8) -> 317 | AF8: 攻击 | AG8: 当玩家受击=0时
A9: 4 | B9: ="关卡"&A9&E9 -> 关卡4小怪 | C9: =INDEX([3]关卡!$J$19:$J$2018,A9) -> 60 | D9: =INDEX([3]关卡!$N$19:$N$2018,A9) -> 52 | E9: 小怪 | F9: 非R | G9: 1.25 | H9: 0 | I9: 0 | J9: 1 | K9: 1 | L9: 2 | M9: 15 | N9: 2 | O9: =HLOOKUP(O$5,[1]非R能力!$B$8:$F$558,$C9+1,0) -> 9797.2707 | P9: =HLOOKUP(P$5,[1]非R能力!$B$8:$F$558,$C9+1,0) -> 1941.8325 | Q9: =HLOOKUP(Q$5,[1]非R能力!$B$8:$F$558,$C9+1,0) -> 1342.2775 | R9: =HLOOKUP(R$5,[1]非R能力!$B$8:$F$558,$C9+1,0) -> 471.30769 | S9: =HLOOKUP(S$5,[1]非R能力!$B$8:$F$558,$C9+1,0) -> 653.14286 | T9: =INDEX([1]非R能力!$H$9:$H$558,D9) -> 0 | U9: =IF(E9="小怪",0,IF(INDEX([1]非R能力!$FK$9:$FK$558,C9)=0,0,10)) -> 0 | V9: =IF(E9="小怪",0,IF(INDEX([1]非R能力!$FH$9:$FH$558,C9)=0,0,5000)) -> 0 | W9: =HLOOKUP(W$5,[2]人物技能基础!$O$3:$Q$553,$C9+1,0) -> 3.6371429 | X9: =HLOOKUP(X$5,[2]人物技能基础!$O$3:$Q$553,$C9+1,0) -> 2.0186429 | Y9: =HLOOKUP(Y$5,[2]人物技能基础!$O$3:$Q$553,$C9+1,0) -> 99.964286 | Z9: =INT(((P9-AB9)*X9+(Y9+T9))*G9*J9*$D$2) -> 4019 | AA9: =IF(H9=0,IF(U9=0,INT(Q9/5),IF(V9=0,INT(Q9/5),INT((V9/U9)/(1/N9*M9)/L9+Q9))),INT((IF(U9=0,0,V9/U9/(1/N9*M9))+O9/H9)/L9+Q9)) -> 268 | AB9: =INT(P9*I9) -> 0 | AC9: =INT(K9*S9) -> 653 | AD9: =INT(R9/J9) -> 471 | AH9: 当回血间隔=0或回血量=0时
A10: 5 | B10: ="关卡"&A10&E10 -> 关卡5小怪 | C10: =INDEX([3]关卡!$J$19:$J$2018,A10) -> 62 | D10: =INDEX([3]关卡!$N$19:$N$2018,A10) -> 54 | E10: 小怪 | F10: 非R | G10: 1.5 | H10: 0 | I10: 0 | J10: 1 | K10: 1 | L10: 2 | M10: 15 | N10: 2 | O10: =HLOOKUP(O$5,[1]非R能力!$B$8:$F$558,$C10+1,0) -> 10994.353 | P10: =HLOOKUP(P$5,[1]非R能力!$B$8:$F$558,$C10+1,0) -> 2023.1627 | Q10: =HLOOKUP(Q$5,[1]非R能力!$B$8:$F$558,$C10+1,0) -> 1435.2057 | R10: =HLOOKUP(R$5,[1]非R能力!$B$8:$F$558,$C10+1,0) -> 506.38462 | S10: =HLOOKUP(S$5,[1]非R能力!$B$8:$F$558,$C10+1,0) -> 695.71429 | T10: =INDEX([1]非R能力!$H$9:$H$558,D10) -> 0 | U10: =IF(E10="小怪",0,IF(INDEX([1]非R能力!$FK$9:$FK$558,C10)=0,0,10)) -> 0 | V10: =IF(E10="小怪",0,IF(INDEX([1]非R能力!$FH$9:$FH$558,C10)=0,0,5000)) -> 0 | W10: =HLOOKUP(W$5,[2]人物技能基础!$O$3:$Q$553,$C10+1,0) -> 3.6371429 | X10: =HLOOKUP(X$5,[2]人物技能基础!$O$3:$Q$553,$C10+1,0) -> 2.0186429 | Y10: =HLOOKUP(Y$5,[2]人物技能基础!$O$3:$Q$553,$C10+1,0) -> 99.964286 | Z10: =INT(((P10-AB10)*X10+(Y10+T10))*G10*J10*$D$2) -> 5020 | AA10: =IF(H10=0,IF(U10=0,INT(Q10/5),IF(V10=0,INT(Q10/5),INT((V10/U10)/(1/N10*M10)/L10+Q10))),INT((IF(U10=0,0,V10/U10/(1/N10*M10))+O10/H10)/L10+Q10)) -> 287 | AB10: =INT(P10*I10) -> 0 | AC10: =INT(K10*S10) -> 695 | AD10: =INT(R10/J10) -> 506 | AH10: 攻击=玩家防御/5，本来是攻击=玩家防御即可，这里是为了保险，以后可能调整
A11: 6 | B11: ="关卡"&A11&E11 -> 关卡6小怪 | C11: =INDEX([3]关卡!$J$19:$J$2018,A11) -> 64 | D11: =INDEX([3]关卡!$N$19:$N$2018,A11) -> 56 | E11: 小怪 | F11: 非R | G11: 1.75 | H11: 0 | I11: 0 | J11: 1 | K11: 1 | L11: 2 | M11: 15 | N11: 2 | O11: =HLOOKUP(O$5,[1]非R能力!$B$8:$F$558,$C11+1,0) -> 11767.979 | P11: =HLOOKUP(P$5,[1]非R能力!$B$8:$F$558,$C11+1,0) -> 2104.4928 | Q11: =HLOOKUP(Q$5,[1]非R能力!$B$8:$F$558,$C11+1,0) -> 1528.134 | R11: =HLOOKUP(R$5,[1]非R能力!$B$8:$F$558,$C11+1,0) -> 541.46154 | S11: =HLOOKUP(S$5,[1]非R能力!$B$8:$F$558,$C11+1,0) -> 747.83333 | T11: =INDEX([1]非R能力!$H$9:$H$558,D11) -> 0 | U11: =IF(E11="小怪",0,IF(INDEX([1]非R能力!$FK$9:$FK$558,C11)=0,0,10)) -> 0 | V11: =IF(E11="小怪",0,IF(INDEX([1]非R能力!$FH$9:$FH$558,C11)=0,0,5000)) -> 0 | W11: =HLOOKUP(W$5,[2]人物技能基础!$O$3:$Q$553,$C11+1,0) -> 3.6371429 | X11: =HLOOKUP(X$5,[2]人物技能基础!$O$3:$Q$553,$C11+1,0) -> 2.0186429 | Y11: =HLOOKUP(Y$5,[2]人物技能基础!$O$3:$Q$553,$C11+1,0) -> 99.964286 | Z11: =INT(((P11-AB11)*X11+(Y11+T11))*G11*J11*$D$2) -> 6087 | AA11: =IF(H11=0,IF(U11=0,INT(Q11/5),IF(V11=0,INT(Q11/5),INT((V11/U11)/(1/N11*M11)/L11+Q11))),INT((IF(U11=0,0,V11/U11/(1/N11*M11))+O11/H11)/L11+Q11)) -> 305 | AB11: =INT(P11*I11) -> 0 | AC11: =INT(K11*S11) -> 747 | AD11: =INT(R11/J11) -> 541 | AH11: 当回血间隔不等于0时
A12: 7 | B12: ="关卡"&A12&E12 -> 关卡7小怪 | C12: =INDEX([3]关卡!$J$19:$J$2018,A12) -> 66 | D12: =INDEX([3]关卡!$N$19:$N$2018,A12) -> 59 | E12: 小怪 | F12: 非R | G12: 2 | H12: 0 | I12: 0 | J12: 1 | K12: 1 | L12: 2 | M12: 15 | N12: 2 | O12: =HLOOKUP(O$5,[1]非R能力!$B$8:$F$558,$C12+1,0) -> 12130.373 | P12: =HLOOKUP(P$5,[1]非R能力!$B$8:$F$558,$C12+1,0) -> 2464.7268 | Q12: =HLOOKUP(Q$5,[1]非R能力!$B$8:$F$558,$C12+1,0) -> 1621.4018 | R12: =HLOOKUP(R$5,[1]非R能力!$B$8:$F$558,$C12+1,0) -> 572.07589 | S12: =HLOOKUP(S$5,[1]非R能力!$B$8:$F$558,$C12+1,0) -> 809.70376 | T12: =INDEX([1]非R能力!$H$9:$H$558,D12) -> 0 | U12: =IF(E12="小怪",0,IF(INDEX([1]非R能力!$FK$9:$FK$558,C12)=0,0,10)) -> 0 | V12: =IF(E12="小怪",0,IF(INDEX([1]非R能力!$FH$9:$FH$558,C12)=0,0,5000)) -> 0 | W12: =HLOOKUP(W$5,[2]人物技能基础!$O$3:$Q$553,$C12+1,0) -> 3.6371429 | X12: =HLOOKUP(X$5,[2]人物技能基础!$O$3:$Q$553,$C12+1,0) -> 2.0186429 | Y12: =HLOOKUP(Y$5,[2]人物技能基础!$O$3:$Q$553,$C12+1,0) -> 99.964286 | Z12: =INT(((P12-AB12)*X12+(Y12+T12))*G12*J12*$D$2) -> 8120 | AA12: =IF(H12=0,IF(U12=0,INT(Q12/5),IF(V12=0,INT(Q12/5),INT((V12/U12)/(1/N12*M12)/L12+Q12))),INT((IF(U12=0,0,V12/U12/(1/N12*M12))+O12/H12)/L12+Q12)) -> 324 | AB12: =INT(P12*I12) -> 0 | AC12: =INT(K12*S12) -> 809 | AD12: =INT(R12/J12) -> 572 | AH12: 每秒回血=回血量/回血间隔
A13: 8 | B13: ="关卡"&A13&E13 -> 关卡8小怪 | C13: =INDEX([3]关卡!$J$19:$J$2018,A13) -> 67 | D13: =INDEX([3]关卡!$N$19:$N$2018,A13) -> 60 | E13: 小怪 | F13: 非R | G13: 2.25 | H13: 0 | I13: 0 | J13: 1 | K13: 1 | L13: 2 | M13: 15 | N13: 2 | O13: =HLOOKUP(O$5,[1]非R能力!$B$8:$F$558,$C13+1,0) -> 12311.57 | P13: =HLOOKUP(P$5,[1]非R能力!$B$8:$F$558,$C13+1,0) -> 2783.6165 | Q13: =HLOOKUP(Q$5,[1]非R能力!$B$8:$F$558,$C13+1,0) -> 1668.0357 | R13: =HLOOKUP(R$5,[1]非R能力!$B$8:$F$558,$C13+1,0) -> 585.07538 | S13: =HLOOKUP(S$5,[1]非R能力!$B$8:$F$558,$C13+1,0) -> 840.63897 | T13: =INDEX([1]非R能力!$H$9:$H$558,D13) -> 0 | U13: =IF(E13="小怪",0,IF(INDEX([1]非R能力!$FK$9:$FK$558,C13)=0,0,10)) -> 0 | V13: =IF(E13="小怪",0,IF(INDEX([1]非R能力!$FH$9:$FH$558,C13)=0,0,5000)) -> 0 | W13: =HLOOKUP(W$5,[2]人物技能基础!$O$3:$Q$553,$C13+1,0) -> 3.6371429 | X13: =HLOOKUP(X$5,[2]人物技能基础!$O$3:$Q$553,$C13+1,0) -> 2.0186429 | Y13: =HLOOKUP(Y$5,[2]人物技能基础!$O$3:$Q$553,$C13+1,0) -> 99.964286 | Z13: =INT(((P13-AB13)*X13+(Y13+T13))*G13*J13*$D$2) -> 10294 | AA13: =IF(H13=0,IF(U13=0,INT(Q13/5),IF(V13=0,INT(Q13/5),INT((V13/U13)/(1/N13*M13)/L13+Q13))),INT((IF(U13=0,0,V13/U13/(1/N13*M13))+O13/H13)/L13+Q13)) -> 333 | AB13: =INT(P13*I13) -> 0 | AC13: =INT(K13*S13) -> 840 | AD13: =INT(R13/J13) -> 585 | AH13: 每秒被攻击次数=1/攻击间隔*怪物数量
A14: 9 | B14: ="关卡"&A14&E14 -> 关卡9小怪 | C14: =INDEX([3]关卡!$J$19:$J$2018,A14) -> 69 | D14: =INDEX([3]关卡!$N$19:$N$2018,A14) -> 63 | E14: 小怪 | F14: 非R | G14: 2.5 | H14: 0 | I14: 0 | J14: 1 | K14: 1 | L14: 2 | M14: 15 | N14: 2 | O14: =HLOOKUP(O$5,[1]非R能力!$B$8:$F$558,$C14+1,0) -> 12673.963 | P14: =HLOOKUP(P$5,[1]非R能力!$B$8:$F$558,$C14+1,0) -> 3166.3959 | Q14: =HLOOKUP(Q$5,[1]非R能力!$B$8:$F$558,$C14+1,0) -> 1761.3035 | R14: =HLOOKUP(R$5,[1]非R能力!$B$8:$F$558,$C14+1,0) -> 611.07435 | S14: =HLOOKUP(S$5,[1]非R能力!$B$8:$F$558,$C14+1,0) -> 902.50939 | T14: =INDEX([1]非R能力!$H$9:$H$558,D14) -> 0 | U14: =IF(E14="小怪",0,IF(INDEX([1]非R能力!$FK$9:$FK$558,C14)=0,0,10)) -> 0 | V14: =IF(E14="小怪",0,IF(INDEX([1]非R能力!$FH$9:$FH$558,C14)=0,0,5000)) -> 0 | W14: =HLOOKUP(W$5,[2]人物技能基础!$O$3:$Q$553,$C14+1,0) -> 3.6371429 | X14: =HLOOKUP(X$5,[2]人物技能基础!$O$3:$Q$553,$C14+1,0) -> 2.0186429 | Y14: =HLOOKUP(Y$5,[2]人物技能基础!$O$3:$Q$553,$C14+1,0) -> 99.964286 | Z14: =INT(((P14-AB14)*X14+(Y14+T14))*G14*J14*$D$2) -> 12983 | AA14: =IF(H14=0,IF(U14=0,INT(Q14/5),IF(V14=0,INT(Q14/5),INT((V14/U14)/(1/N14*M14)/L14+Q14))),INT((IF(U14=0,0,V14/U14/(1/N14*M14))+O14/H14)/L14+Q14)) -> 352 | AB14: =INT(P14*I14) -> 0 | AC14: =INT(K14*S14) -> 902 | AD14: =INT(R14/J14) -> 611 | AH14: 每次攻击扣血=每秒回血/每秒被攻击次数
A15: 10 | B15: ="关卡"&A15&E15 -> 关卡10小怪 | C15: =INDEX([3]关卡!$J$19:$J$2018,A15) -> 70 | D15: =INDEX([3]关卡!$N$19:$N$2018,A15) -> 64 | E15: 小怪 | F15: 非R | G15: 2.75 | H15: 0 | I15: 0 | J15: 1 | K15: 1 | L15: 2 | M15: 15 | N15: 2 | O15: =HLOOKUP(O$5,[1]非R能力!$B$8:$F$558,$C15+1,0) -> 12949.476 | P15: =HLOOKUP(P$5,[1]非R能力!$B$8:$F$558,$C15+1,0) -> 3264.1862 | Q15: =HLOOKUP(Q$5,[1]非R能力!$B$8:$F$558,$C15+1,0) -> 1811.8673 | R15: =HLOOKUP(R$5,[1]非R能力!$B$8:$F$558,$C15+1,0) -> 624.07384 | S15: =HLOOKUP(S$5,[1]非R能力!$B$8:$F$558,$C15+1,0) -> 910.38905 | T15: =INDEX([1]非R能力!$H$9:$H$558,D15) -> 0 | U15: =IF(E15="小怪",0,IF(INDEX([1]非R能力!$FK$9:$FK$558,C15)=0,0,10)) -> 0 | V15: =IF(E15="小怪",0,IF(INDEX([1]非R能力!$FH$9:$FH$558,C15)=0,0,5000)) -> 0 | W15: =HLOOKUP(W$5,[2]人物技能基础!$O$3:$Q$553,$C15+1,0) -> 3.6371429 | X15: =HLOOKUP(X$5,[2]人物技能基础!$O$3:$Q$553,$C15+1,0) -> 2.0186429 | Y15: =HLOOKUP(Y$5,[2]人物技能基础!$O$3:$Q$553,$C15+1,0) -> 99.964286 | Z15: =INT(((P15-AB15)*X15+(Y15+T15))*G15*J15*$D$2) -> 14716 | AA15: =IF(H15=0,IF(U15=0,INT(Q15/5),IF(V15=0,INT(Q15/5),INT((V15/U15)/(1/N15*M15)/L15+Q15))),INT((IF(U15=0,0,V15/U15/(1/N15*M15))+O15/H15)/L15+Q15)) -> 362 | AB15: =INT(P15*I15) -> 0 | AC15: =INT(K15*S15) -> 910 | AD15: =INT(R15/J15) -> 624 | AH15: 攻击=（每次攻击扣血-怪物固定伤害【这个以后加】）/怪物技能系数+玩家防御
A16: 11 | B16: ="关卡"&A16&E16 -> 关卡11小怪 | C16: =INDEX([3]关卡!$J$19:$J$2018,A16) -> 72 | D16: =INDEX([3]关卡!$N$19:$N$2018,A16) -> 67 | E16: 小怪 | F16: 非R | G16: 3 | H16: 0 | I16: 0 | J16: 1 | K16: 1 | L16: 2 | M16: 15 | N16: 2 | O16: =HLOOKUP(O$5,[1]非R能力!$B$8:$F$558,$C16+1,0) -> 13500.501 | P16: =HLOOKUP(P$5,[1]非R能力!$B$8:$F$558,$C16+1,0) -> 3459.7668 | Q16: =HLOOKUP(Q$5,[1]非R能力!$B$8:$F$558,$C16+1,0) -> 1912.9947 | R16: =HLOOKUP(R$5,[1]非R能力!$B$8:$F$558,$C16+1,0) -> 650.07281 | S16: =HLOOKUP(S$5,[1]非R能力!$B$8:$F$558,$C16+1,0) -> 926.14836 | T16: =INDEX([1]非R能力!$H$9:$H$558,D16) -> 28.459063 | U16: =IF(E16="小怪",0,IF(INDEX([1]非R能力!$FK$9:$FK$558,C16)=0,0,10)) -> 0 | V16: =IF(E16="小怪",0,IF(INDEX([1]非R能力!$FH$9:$FH$558,C16)=0,0,5000)) -> 0 | W16: =HLOOKUP(W$5,[2]人物技能基础!$O$3:$Q$553,$C16+1,0) -> 3.6371429 | X16: =HLOOKUP(X$5,[2]人物技能基础!$O$3:$Q$553,$C16+1,0) -> 2.0186429 | Y16: =HLOOKUP(Y$5,[2]人物技能基础!$O$3:$Q$553,$C16+1,0) -> 99.964286 | Z16: =INT(((P16-AB16)*X16+(Y16+T16))*G16*J16*$D$2) -> 17069 | AA16: =IF(H16=0,IF(U16=0,INT(Q16/5),IF(V16=0,INT(Q16/5),INT((V16/U16)/(1/N16*M16)/L16+Q16))),INT((IF(U16=0,0,V16/U16/(1/N16*M16))+O16/H16)/L16+Q16)) -> 382 | AB16: =INT(P16*I16) -> 0 | AC16: =INT(K16*S16) -> 926 | AD16: =INT(R16/J16) -> 650 | AG16: 当玩家受击不等于0时
A17: 12 | B17: ="关卡"&A17&E17 -> 关卡12小怪 | C17: =INDEX([3]关卡!$J$19:$J$2018,A17) -> 73 | D17: =INDEX([3]关卡!$N$19:$N$2018,A17) -> 68 | E17: 小怪 | F17: 非R | G17: 3 | H17: 0 | I17: 0 | J17: 1 | K17: 1 | L17: 2 | M17: 15 | N17: 2 | O17: =HLOOKUP(O$5,[1]非R能力!$B$8:$F$558,$C17+1,0) -> 13776.014 | P17: =HLOOKUP(P$5,[1]非R能力!$B$8:$F$558,$C17+1,0) -> 3557.5571 | Q17: =HLOOKUP(Q$5,[1]非R能力!$B$8:$F$558,$C17+1,0) -> 1963.5585 | R17: =HLOOKUP(R$5,[1]非R能力!$B$8:$F$558,$C17+1,0) -> 663.07229 | S17: =HLOOKUP(S$5,[1]非R能力!$B$8:$F$558,$C17+1,0) -> 934.02801 | T17: =INDEX([1]非R能力!$H$9:$H$558,D17) -> 28.459063 | U17: =IF(E17="小怪",0,IF(INDEX([1]非R能力!$FK$9:$FK$558,C17)=0,0,10)) -> 0 | V17: =IF(E17="小怪",0,IF(INDEX([1]非R能力!$FH$9:$FH$558,C17)=0,0,5000)) -> 0 | W17: =HLOOKUP(W$5,[2]人物技能基础!$O$3:$Q$553,$C17+1,0) -> 3.6371429 | X17: =HLOOKUP(X$5,[2]人物技能基础!$O$3:$Q$553,$C17+1,0) -> 2.0186429 | Y17: =HLOOKUP(Y$5,[2]人物技能基础!$O$3:$Q$553,$C17+1,0) -> 99.964286 | Z17: =INT(((P17-AB17)*X17+(Y17+T17))*G17*J17*$D$2) -> 17543 | AA17: =IF(H17=0,IF(U17=0,INT(Q17/5),IF(V17=0,INT(Q17/5),INT((V17/U17)/(1/N17*M17)/L17+Q17))),INT((IF(U17=0,0,V17/U17/(1/N17*M17))+O17/H17)/L17+Q17)) -> 392 | AB17: =INT(P17*I17) -> 0 | AC17: =INT(K17*S17) -> 934 | AD17: =INT(R17/J17) -> 663 | AH17: 每秒回血=回血量/回血间隔
A18: 13 | B18: ="关卡"&A18&E18 -> 关卡13小怪 | C18: =INDEX([3]关卡!$J$19:$J$2018,A18) -> 74 | D18: =INDEX([3]关卡!$N$19:$N$2018,A18) -> 70 | E18: 小怪 | F18: 非R | G18: 3 | H18: 0 | I18: 0 | J18: 1 | K18: 1 | L18: 2 | M18: 15 | N18: 2 | O18: =HLOOKUP(O$5,[1]非R能力!$B$8:$F$558,$C18+1,0) -> 14051.527 | P18: =HLOOKUP(P$5,[1]非R能力!$B$8:$F$558,$C18+1,0) -> 3655.3474 | Q18: =HLOOKUP(Q$5,[1]非R能力!$B$8:$F$558,$C18+1,0) -> 2014.1222 | R18: =HLOOKUP(R$5,[1]非R能力!$B$8:$F$558,$C18+1,0) -> 676.07178 | S18: =HLOOKUP(S$5,[1]非R能力!$B$8:$F$558,$C18+1,0) -> 941.90767 | T18: =INDEX([1]非R能力!$H$9:$H$558,D18) -> 28.459063 | U18: =IF(E18="小怪",0,IF(INDEX([1]非R能力!$FK$9:$FK$558,C18)=0,0,10)) -> 0 | V18: =IF(E18="小怪",0,IF(INDEX([1]非R能力!$FH$9:$FH$558,C18)=0,0,5000)) -> 0 | W18: =HLOOKUP(W$5,[2]人物技能基础!$O$3:$Q$553,$C18+1,0) -> 3.6371429 | X18: =HLOOKUP(X$5,[2]人物技能基础!$O$3:$Q$553,$C18+1,0) -> 2.0186429 | Y18: =HLOOKUP(Y$5,[2]人物技能基础!$O$3:$Q$553,$C18+1,0) -> 99.964286 | Z18: =INT(((P18-AB18)*X18+(Y18+T18))*G18*J18*$D$2) -> 18017 | AA18: =IF(H18=0,IF(U18=0,INT(Q18/5),IF(V18=0,INT(Q18/5),INT((V18/U18)/(1/N18*M18)/L18+Q18))),INT((IF(U18=0,0,V18/U18/(1/N18*M18))+O18/H18)/L18+Q18)) -> 402 | AB18: =INT(P18*I18) -> 0 | AC18: =INT(K18*S18) -> 941 | AD18: =INT(R18/J18) -> 676 | AH18: 每秒被攻击次数=1/攻击间隔*怪物数量
A19: 14 | B19: ="关卡"&A19&E19 -> 关卡14小怪 | C19: =INDEX([3]关卡!$J$19:$J$2018,A19) -> 75 | D19: =INDEX([3]关卡!$N$19:$N$2018,A19) -> 71 | E19: 小怪 | F19: 非R | G19: 3 | H19: 0 | I19: 0 | J19: 1 | K19: 1 | L19: 2 | M19: 15 | N19: 2 | O19: =HLOOKUP(O$5,[1]非R能力!$B$8:$F$558,$C19+1,0) -> 14327.039 | P19: =HLOOKUP(P$5,[1]非R能力!$B$8:$F$558,$C19+1,0) -> 3753.1377 | Q19: =HLOOKUP(Q$5,[1]非R能力!$B$8:$F$558,$C19+1,0) -> 2064.6859 | R19: =HLOOKUP(R$5,[1]非R能力!$B$8:$F$558,$C19+1,0) -> 689.07126 | S19: =HLOOKUP(S$5,[1]非R能力!$B$8:$F$558,$C19+1,0) -> 949.78732 | T19: =INDEX([1]非R能力!$H$9:$H$558,D19) -> 28.459063 | U19: =IF(E19="小怪",0,IF(INDEX([1]非R能力!$FK$9:$FK$558,C19)=0,0,10)) -> 0 | V19: =IF(E19="小怪",0,IF(INDEX([1]非R能力!$FH$9:$FH$558,C19)=0,0,5000)) -> 0 | W19: =HLOOKUP(W$5,[2]人物技能基础!$O$3:$Q$553,$C19+1,0) -> 3.6371429 | X19: =HLOOKUP(X$5,[2]人物技能基础!$O$3:$Q$553,$C19+1,0) -> 2.0186429 | Y19: =HLOOKUP(Y$5,[2]人物技能基础!$O$3:$Q$553,$C19+1,0) -> 99.964286 | Z19: =INT(((P19-AB19)*X19+(Y19+T19))*G19*J19*$D$2) -> 18491 | AA19: =IF(H19=0,IF(U19=0,INT(Q19/5),IF(V19=0,INT(Q19/5),INT((V19/U19)/(1/N19*M19)/L19+Q19))),INT((IF(U19=0,0,V19/U19/(1/N19*M19))+O19/H19)/L19+Q19)) -> 412 | AB19: =INT(P19*I19) -> 0 | AC19: =INT(K19*S19) -> 949 | AD19: =INT(R19/J19) -> 689 | AH19: 每次攻击扣血=每秒回血/每秒被攻击次数+玩家血量/玩家受击次数
A20: 15 | B20: ="关卡"&A20&E20 -> 关卡15小怪 | C20: =INDEX([3]关卡!$J$19:$J$2018,A20) -> 76 | D20: =INDEX([3]关卡!$N$19:$N$2018,A20) -> 73 | E20: 小怪 | F20: 非R | G20: 3 | H20: 0 | I20: 0 | J20: 1 | K20: 1 | L20: 2 | M20: 15 | N20: 2 | O20: =HLOOKUP(O$5,[1]非R能力!$B$8:$F$558,$C20+1,0) -> 14602.552 | P20: =HLOOKUP(P$5,[1]非R能力!$B$8:$F$558,$C20+1,0) -> 3850.928 | Q20: =HLOOKUP(Q$5,[1]非R能力!$B$8:$F$558,$C20+1,0) -> 2115.2497 | R20: =HLOOKUP(R$5,[1]非R能力!$B$8:$F$558,$C20+1,0) -> 702.07075 | S20: =HLOOKUP(S$5,[1]非R能力!$B$8:$F$558,$C20+1,0) -> 957.66698 | T20: =INDEX([1]非R能力!$H$9:$H$558,D20) -> 57.022275 | U20: =IF(E20="小怪",0,IF(INDEX([1]非R能力!$FK$9:$FK$558,C20)=0,0,10)) -> 0 | V20: =IF(E20="小怪",0,IF(INDEX([1]非R能力!$FH$9:$FH$558,C20)=0,0,5000)) -> 0 | W20: =HLOOKUP(W$5,[2]人物技能基础!$O$3:$Q$553,$C20+1,0) -> 3.6371429 | X20: =HLOOKUP(X$5,[2]人物技能基础!$O$3:$Q$553,$C20+1,0) -> 2.0186429 | Y20: =HLOOKUP(Y$5,[2]人物技能基础!$O$3:$Q$553,$C20+1,0) -> 99.964286 | Z20: =INT(((P20-AB20)*X20+(Y20+T20))*G20*J20*$D$2) -> 19033 | AA20: =IF(H20=0,IF(U20=0,INT(Q20/5),IF(V20=0,INT(Q20/5),INT((V20/U20)/(1/N20*M20)/L20+Q20))),INT((IF(U20=0,0,V20/U20/(1/N20*M20))+O20/H20)/L20+Q20)) -> 423 | AB20: =INT(P20*I20) -> 0 | AC20: =INT(K20*S20) -> 957 | AD20: =INT(R20/J20) -> 702 | AH20: 攻击=（每次攻击扣血-怪物固定伤害【这个以后加】）/怪物技能系数+玩家防御
A21: 16 | B21: ="关卡"&A21&E21 -> 关卡16小怪 | C21: =INDEX([3]关卡!$J$19:$J$2018,A21) -> 76 | D21: =INDEX([3]关卡!$N$19:$N$2018,A21) -> 73 | E21: 小怪 | F21: 非R | G21: 3 | H21: 0 | I21: 0 | J21: 1 | K21: 1 | L21: 2 | M21: 15 | N21: 2 | O21: =HLOOKUP(O$5,[1]非R能力!$B$8:$F$558,$C21+1,0) -> 14602.552 | P21: =HLOOKUP(P$5,[1]非R能力!$B$8:$F$558,$C21+1,0) -> 3850.928 | Q21: =HLOOKUP(Q$5,[1]非R能力!$B$8:$F$558,$C21+1,0) -> 2115.2497 | R21: =HLOOKUP(R$5,[1]非R能力!$B$8:$F$558,$C21+1,0) -> 702.07075 | S21: =HLOOKUP(S$5,[1]非R能力!$B$8:$F$558,$C21+1,0) -> 957.66698 | T21: =INDEX([1]非R能力!$H$9:$H$558,D21) -> 57.022275 | U21: =IF(E21="小怪",0,IF(INDEX([1]非R能力!$FK$9:$FK$558,C21)=0,0,10)) -> 0 | V21: =IF(E21="小怪",0,IF(INDEX([1]非R能力!$FH$9:$FH$558,C21)=0,0,5000)) -> 0 | W21: =HLOOKUP(W$5,[2]人物技能基础!$O$3:$Q$553,$C21+1,0) -> 3.6371429 | X21: =HLOOKUP(X$5,[2]人物技能基础!$O$3:$Q$553,$C21+1,0) -> 2.0186429 | Y21: =HLOOKUP(Y$5,[2]人物技能基础!$O$3:$Q$553,$C21+1,0) -> 99.964286 | Z21: =INT(((P21-AB21)*X21+(Y21+T21))*G21*J21*$D$2) -> 19033 | AA21: =IF(H21=0,IF(U21=0,INT(Q21/5),IF(V21=0,INT(Q21/5),INT((V21/U21)/(1/N21*M21)/L21+Q21))),INT((IF(U21=0,0,V21/U21/(1/N21*M21))+O21/H21)/L21+Q21)) -> 423 | AB21: =INT(P21*I21) -> 0 | AC21: =INT(K21*S21) -> 957 | AD21: =INT(R21/J21) -> 702 | AF21: 命中 | AG21: 怪物对玩家命中率*玩家闪避
A22: 17 | B22: ="关卡"&A22&E22 -> 关卡17小怪 | C22: =INDEX([3]关卡!$J$19:$J$2018,A22) -> 77 | D22: =INDEX([3]关卡!$N$19:$N$2018,A22) -> 74 | E22: 小怪 | F22: 非R | G22: 3 | H22: 0 | I22: 0 | J22: 1 | K22: 1 | L22: 2 | M22: 15 | N22: 2 | O22: =HLOOKUP(O$5,[1]非R能力!$B$8:$F$558,$C22+1,0) -> 14878.065 | P22: =HLOOKUP(P$5,[1]非R能力!$B$8:$F$558,$C22+1,0) -> 3948.7183 | Q22: =HLOOKUP(Q$5,[1]非R能力!$B$8:$F$558,$C22+1,0) -> 2165.8134 | R22: =HLOOKUP(R$5,[1]非R能力!$B$8:$F$558,$C22+1,0) -> 715.07023 | S22: =HLOOKUP(S$5,[1]非R能力!$B$8:$F$558,$C22+1,0) -> 965.54664 | T22: =INDEX([1]非R能力!$H$9:$H$558,D22) -> 57.022275 | U22: =IF(E22="小怪",0,IF(INDEX([1]非R能力!$FK$9:$FK$558,C22)=0,0,10)) -> 0 | V22: =IF(E22="小怪",0,IF(INDEX([1]非R能力!$FH$9:$FH$558,C22)=0,0,5000)) -> 0 | W22: =HLOOKUP(W$5,[2]人物技能基础!$O$3:$Q$553,$C22+1,0) -> 3.6371429 | X22: =HLOOKUP(X$5,[2]人物技能基础!$O$3:$Q$553,$C22+1,0) -> 2.0186429 | Y22: =HLOOKUP(Y$5,[2]人物技能基础!$O$3:$Q$553,$C22+1,0) -> 99.964286 | Z22: =INT(((P22-AB22)*X22+(Y22+T22))*G22*J22*$D$2) -> 19507 | AA22: =IF(H22=0,IF(U22=0,INT(Q22/5),IF(V22=0,INT(Q22/5),INT((V22/U22)/(1/N22*M22)/L22+Q22))),INT((IF(U22=0,0,V22/U22/(1/N22*M22))+O22/H22)/L22+Q22)) -> 433 | AB22: =INT(P22*I22) -> 0 | AC22: =INT(K22*S22) -> 965 | AD22: =INT(R22/J22) -> 715 | AF22: 闪避 | AG22: 玩家命中/玩家对怪物命中
A23: 18 | B23: ="关卡"&A23&E23 -> 关卡18小怪 | C23: =INDEX([3]关卡!$J$19:$J$2018,A23) -> 78 | D23: =INDEX([3]关卡!$N$19:$N$2018,A23) -> 76 | E23: 小怪 | F23: 非R | G23: 3 | H23: 0 | I23: 0 | J23: 1 | K23: 1 | L23: 2 | M23: 15 | N23: 2 | O23: =HLOOKUP(O$5,[1]非R能力!$B$8:$F$558,$C23+1,0) -> 15153.577 | P23: =HLOOKUP(P$5,[1]非R能力!$B$8:$F$558,$C23+1,0) -> 4046.5086 | Q23: =HLOOKUP(Q$5,[1]非R能力!$B$8:$F$558,$C23+1,0) -> 2216.3772 | R23: =HLOOKUP(R$5,[1]非R能力!$B$8:$F$558,$C23+1,0) -> 728.06972 | S23: =HLOOKUP(S$5,[1]非R能力!$B$8:$F$558,$C23+1,0) -> 973.42629 | T23: =INDEX([1]非R能力!$H$9:$H$558,D23) -> 57.022275 | U23: =IF(E23="小怪",0,IF(INDEX([1]非R能力!$FK$9:$FK$558,C23)=0,0,10)) -> 0 | V23: =IF(E23="小怪",0,IF(INDEX([1]非R能力!$FH$9:$FH$558,C23)=0,0,5000)) -> 0 | W23: =HLOOKUP(W$5,[2]人物技能基础!$O$3:$Q$553,$C23+1,0) -> 3.6371429 | X23: =HLOOKUP(X$5,[2]人物技能基础!$O$3:$Q$553,$C23+1,0) -> 2.0186429 | Y23: =HLOOKUP(Y$5,[2]人物技能基础!$O$3:$Q$553,$C23+1,0) -> 99.964286 | Z23: =INT(((P23-AB23)*X23+(Y23+T23))*G23*J23*$D$2) -> 19981 | AA23: =IF(H23=0,IF(U23=0,INT(Q23/5),IF(V23=0,INT(Q23/5),INT((V23/U23)/(1/N23*M23)/L23+Q23))),INT((IF(U23=0,0,V23/U23/(1/N23*M23))+O23/H23)/L23+Q23)) -> 443 | AB23: =INT(P23*I23) -> 0 | AC23: =INT(K23*S23) -> 973 | AD23: =INT(R23/J23) -> 728
A24: 19 | B24: ="关卡"&A24&E24 -> 关卡19小怪 | C24: =INDEX([3]关卡!$J$19:$J$2018,A24) -> 93 | D24: =INDEX([3]关卡!$N$19:$N$2018,A24) -> 93 | E24: 小怪 | F24: 非R | G24: 3 | H24: 0 | I24: 0 | J24: 1 | K24: 1 | L24: 2 | M24: 15 | N24: 2 | O24: =HLOOKUP(O$5,[1]非R能力!$B$8:$F$558,$C24+1,0) -> 29232.008 | P24: =HLOOKUP(P$5,[1]非R能力!$B$8:$F$558,$C24+1,0) -> 7406.1151 | Q24: =HLOOKUP(Q$5,[1]非R能力!$B$8:$F$558,$C24+1,0) -> 4079.2834 | R24: =HLOOKUP(R$5,[1]非R能力!$B$8:$F$558,$C24+1,0) -> 1192.1403 | S24: =HLOOKUP(S$5,[1]非R能力!$B$8:$F$558,$C24+1,0) -> 1643.868 | T24: =INDEX([1]非R能力!$H$9:$H$558,D24) -> 85.690488 | U24: =IF(E24="小怪",0,IF(INDEX([1]非R能力!$FK$9:$FK$558,C24)=0,0,10)) -> 0 | V24: =IF(E24="小怪",0,IF(INDEX([1]非R能力!$FH$9:$FH$558,C24)=0,0,5000)) -> 0 | W24: =HLOOKUP(W$5,[2]人物技能基础!$O$3:$Q$553,$C24+1,0) -> 3.6371429 | X24: =HLOOKUP(X$5,[2]人物技能基础!$O$3:$Q$553,$C24+1,0) -> 2.0186429 | Y24: =HLOOKUP(Y$5,[2]人物技能基础!$O$3:$Q$553,$C24+1,0) -> 99.964286 | Z24: =INT(((P24-AB24)*X24+(Y24+T24))*G24*J24*$D$2) -> 36326 | AA24: =IF(H24=0,IF(U24=0,INT(Q24/5),IF(V24=0,INT(Q24/5),INT((V24/U24)/(1/N24*M24)/L24+Q24))),INT((IF(U24=0,0,V24/U24/(1/N24*M24))+O24/H24)/L24+Q24)) -> 815 | AB24: =INT(P24*I24) -> 0 | AC24: =INT(K24*S24) -> 1643 | AD24: =INT(R24/J24) -> 1192
A25: 20 | B25: ="关卡"&A25&E25 -> 关卡20小怪 | C25: =INDEX([3]关卡!$J$19:$J$2018,A25) -> 85 | D25: =INDEX([3]关卡!$N$19:$N$2018,A25) -> 85 | E25: 小怪 | F25: 非R | G25: 3 | H25: 0 | I25: 0 | J25: 1 | K25: 1 | L25: 2 | M25: 15 | N25: 2 | O25: =HLOOKUP(O$5,[1]非R能力!$B$8:$F$558,$C25+1,0) -> 23084.677 | P25: =HLOOKUP(P$5,[1]非R能力!$B$8:$F$558,$C25+1,0) -> 5832.4081 | Q25: =HLOOKUP(Q$5,[1]非R能力!$B$8:$F$558,$C25+1,0) -> 3127.3318 | R25: =HLOOKUP(R$5,[1]非R能力!$B$8:$F$558,$C25+1,0) -> 960.20929 | S25: =HLOOKUP(S$5,[1]非R能力!$B$8:$F$558,$C25+1,0) -> 1345.3545 | T25: =INDEX([1]非R能力!$H$9:$H$558,D25) -> 85.690488 | U25: =IF(E25="小怪",0,IF(INDEX([1]非R能力!$FK$9:$FK$558,C25)=0,0,10)) -> 0 | V25: =IF(E25="小怪",0,IF(INDEX([1]非R能力!$FH$9:$FH$558,C25)=0,0,5000)) -> 0 | W25: =HLOOKUP(W$5,[2]人物技能基础!$O$3:$Q$553,$C25+1,0) -> 3.6371429 | X25: =HLOOKUP(X$5,[2]人物技能基础!$O$3:$Q$553,$C25+1,0) -> 2.0186429 | Y25: =HLOOKUP(Y$5,[2]人物技能基础!$O$3:$Q$553,$C25+1,0) -> 99.964286 | Z25: =INT(((P25-AB25)*X25+(Y25+T25))*G25*J25*$D$2) -> 28702 | AA25: =IF(H25=0,IF(U25=0,INT(Q25/5),IF(V25=0,INT(Q25/5),INT((V25/U25)/(1/N25*M25)/L25+Q25))),INT((IF(U25=0,0,V25/U25/(1/N25*M25))+O25/H25)/L25+Q25)) -> 625 | AB25: =INT(P25*I25) -> 0 | AC25: =INT(K25*S25) -> 1345 | AD25: =INT(R25/J25) -> 960
A26: 21 | B26: ="关卡"&A26&E26 -> 关卡21小怪 | C26: =INDEX([3]关卡!$J$19:$J$2018,A26) -> 86 | D26: =INDEX([3]关卡!$N$19:$N$2018,A26) -> 86 | E26: 小怪 | F26: 非R | G26: 3 | H26: 0 | I26: 0 | J26: 1 | K26: 1 | L26: 2 | M26: 15 | N26: 2 | O26: =HLOOKUP(O$5,[1]非R能力!$B$8:$F$558,$C26+1,0) -> 24475.237 | P26: =HLOOKUP(P$5,[1]非R能力!$B$8:$F$558,$C26+1,0) -> 6288.2963 | Q26: =HLOOKUP(Q$5,[1]非R能力!$B$8:$F$558,$C26+1,0) -> 3242.2644 | R26: =HLOOKUP(R$5,[1]非R能力!$B$8:$F$558,$C26+1,0) -> 1006.73 | S26: =HLOOKUP(S$5,[1]非R能力!$B$8:$F$558,$C26+1,0) -> 1472.8432 | T26: =INDEX([1]非R能力!$H$9:$H$558,D26) -> 85.690488 | U26: =IF(E26="小怪",0,IF(INDEX([1]非R能力!$FK$9:$FK$558,C26)=0,0,10)) -> 0 | V26: =IF(E26="小怪",0,IF(INDEX([1]非R能力!$FH$9:$FH$558,C26)=0,0,5000)) -> 0 | W26: =HLOOKUP(W$5,[2]人物技能基础!$O$3:$Q$553,$C26+1,0) -> 3.6371429 | X26: =HLOOKUP(X$5,[2]人物技能基础!$O$3:$Q$553,$C26+1,0) -> 2.0186429 | Y26: =HLOOKUP(Y$5,[2]人物技能基础!$O$3:$Q$553,$C26+1,0) -> 99.964286 | Z26: =INT(((P26-AB26)*X26+(Y26+T26))*G26*J26*$D$2) -> 30910 | AA26: =IF(H26=0,IF(U26=0,INT(Q26/5),IF(V26=0,INT(Q26/5),INT((V26/U26)/(1/N26*M26)/L26+Q26))),INT((IF(U26=0,0,V26/U26/(1/N26*M26))+O26/H26)/L26+Q26)) -> 648 | AB26: =INT(P26*I26) -> 0 | AC26: =INT(K26*S26) -> 1472 | AD26: =INT(R26/J26) -> 1006
A27: 22 | B27: ="关卡"&A27&E27 -> 关卡22小怪 | C27: =INDEX([3]关卡!$J$19:$J$2018,A27) -> 87 | D27: =INDEX([3]关卡!$N$19:$N$2018,A27) -> 87 | E27: 小怪 | F27: 非R | G27: 3 | H27: 0 | I27: 0 | J27: 1 | K27: 1 | L27: 2 | M27: 15 | N27: 2 | O27: =HLOOKUP(O$5,[1]非R能力!$B$8:$F$558,$C27+1,0) -> 26027.31 | P27: =HLOOKUP(P$5,[1]非R能力!$B$8:$F$558,$C27+1,0) -> 6483.5662 | Q27: =HLOOKUP(Q$5,[1]非R能力!$B$8:$F$558,$C27+1,0) -> 3344.0008 | R27: =HLOOKUP(R$5,[1]非R能力!$B$8:$F$558,$C27+1,0) -> 1053.2531 | S27: =HLOOKUP(S$5,[1]非R能力!$B$8:$F$558,$C27+1,0) -> 1497.2686 | T27: =INDEX([1]非R能力!$H$9:$H$558,D27) -> 85.690488 | U27: =IF(E27="小怪",0,IF(INDEX([1]非R能力!$FK$9:$FK$558,C27)=0,0,10)) -> 0 | V27: =IF(E27="小怪",0,IF(INDEX([1]非R能力!$FH$9:$FH$558,C27)=0,0,5000)) -> 0 | W27: =HLOOKUP(W$5,[2]人物技能基础!$O$3:$Q$553,$C27+1,0) -> 3.6371429 | X27: =HLOOKUP(X$5,[2]人物技能基础!$O$3:$Q$553,$C27+1,0) -> 2.0186429 | Y27: =HLOOKUP(Y$5,[2]人物技能基础!$O$3:$Q$553,$C27+1,0) -> 99.964286 | Z27: =INT(((P27-AB27)*X27+(Y27+T27))*G27*J27*$D$2) -> 31856 | AA27: =IF(H27=0,IF(U27=0,INT(Q27/5),IF(V27=0,INT(Q27/5),INT((V27/U27)/(1/N27*M27)/L27+Q27))),INT((IF(U27=0,0,V27/U27/(1/N27*M27))+O27/H27)/L27+Q27)) -> 668 | AB27: =INT(P27*I27) -> 0 | AC27: =INT(K27*S27) -> 1497 | AD27: =INT(R27/J27) -> 1053
A28: 23 | B28: ="关卡"&A28&E28 -> 关卡23小怪 | C28: =INDEX([3]关卡!$J$19:$J$2018,A28) -> 88 | D28: =INDEX([3]关卡!$N$19:$N$2018,A28) -> 88 | E28: 小怪 | F28: 非R | G28: 3 | H28: 0 | I28: 0 | J28: 1 | K28: 1 | L28: 2 | M28: 15 | N28: 2 | O28: =HLOOKUP(O$5,[1]非R能力!$B$8:$F$558,$C28+1,0) -> 26791.306 | P28: =HLOOKUP(P$5,[1]非R能力!$B$8:$F$558,$C28+1,0) -> 6678.8465 | Q28: =HLOOKUP(Q$5,[1]非R能力!$B$8:$F$558,$C28+1,0) -> 3769.5999 | R28: =HLOOKUP(R$5,[1]非R能力!$B$8:$F$558,$C28+1,0) -> 1099.7785 | S28: =HLOOKUP(S$5,[1]非R能力!$B$8:$F$558,$C28+1,0) -> 1521.6952 | T28: =INDEX([1]非R能力!$H$9:$H$558,D28) -> 85.690488 | U28: =IF(E28="小怪",0,IF(INDEX([1]非R能力!$FK$9:$FK$558,C28)=0,0,10)) -> 0 | V28: =IF(E28="小怪",0,IF(INDEX([1]非R能力!$FH$9:$FH$558,C28)=0,0,5000)) -> 0 | W28: =HLOOKUP(W$5,[2]人物技能基础!$O$3:$Q$553,$C28+1,0) -> 3.6371429 | X28: =HLOOKUP(X$5,[2]人物技能基础!$O$3:$Q$553,$C28+1,0) -> 2.0186429 | Y28: =HLOOKUP(Y$5,[2]人物技能基础!$O$3:$Q$553,$C28+1,0) -> 99.964286 | Z28: =INT(((P28-AB28)*X28+(Y28+T28))*G28*J28*$D$2) -> 32802 | AA28: =IF(H28=0,IF(U28=0,INT(Q28/5),IF(V28=0,INT(Q28/5),INT((V28/U28)/(1/N28*M28)/L28+Q28))),INT((IF(U28=0,0,V28/U28/(1/N28*M28))+O28/H28)/L28+Q28)) -> 753 | AB28: =INT(P28*I28) -> 0 | AC28: =INT(K28*S28) -> 1521 | AD28: =INT(R28/J28) -> 1099
A29: 24 | B29: ="关卡"&A29&E29 -> 关卡24小怪 | C29: =INDEX([3]关卡!$J$19:$J$2018,A29) -> 89 | D29: =INDEX([3]关卡!$N$19:$N$2018,A29) -> 89 | E29: 小怪 | F29: 非R | G29: 3 | H29: 0 | I29: 0 | J29: 1 | K29: 1 | L29: 2 | M29: 15 | N29: 2 | O29: =HLOOKUP(O$5,[1]非R能力!$B$8:$F$558,$C29+1,0) -> 27256.818 | P29: =HLOOKUP(P$5,[1]非R能力!$B$8:$F$558,$C29+1,0) -> 6874.5761 | Q29: =HLOOKUP(Q$5,[1]非R能力!$B$8:$F$558,$C29+1,0) -> 3832.4978 | R29: =HLOOKUP(R$5,[1]非R能力!$B$8:$F$558,$C29+1,0) -> 1118.2451 | S29: =HLOOKUP(S$5,[1]非R能力!$B$8:$F$558,$C29+1,0) -> 1546.1229 | T29: =INDEX([1]非R能力!$H$9:$H$558,D29) -> 85.690488 | U29: =IF(E29="小怪",0,IF(INDEX([1]非R能力!$FK$9:$FK$558,C29)=0,0,10)) -> 0 | V29: =IF(E29="小怪",0,IF(INDEX([1]非R能力!$FH$9:$FH$558,C29)=0,0,5000)) -> 0 | W29: =HLOOKUP(W$5,[2]人物技能基础!$O$3:$Q$553,$C29+1,0) -> 3.6371429 | X29: =HLOOKUP(X$5,[2]人物技能基础!$O$3:$Q$553,$C29+1,0) -> 2.0186429 | Y29: =HLOOKUP(Y$5,[2]人物技能基础!$O$3:$Q$553,$C29+1,0) -> 99.964286 | Z29: =INT(((P29-AB29)*X29+(Y29+T29))*G29*J29*$D$2) -> 33751 | AA29: =IF(H29=0,IF(U29=0,INT(Q29/5),IF(V29=0,INT(Q29/5),INT((V29/U29)/(1/N29*M29)/L29+Q29))),INT((IF(U29=0,0,V29/U29/(1/N29*M29))+O29/H29)/L29+Q29)) -> 766 | AB29: =INT(P29*I29) -> 0 | AC29: =INT(K29*S29) -> 1546 | AD29: =INT(R29/J29) -> 1118
A30: 25 | B30: ="关卡"&A30&E30 -> 关卡25小怪 | C30: =INDEX([3]关卡!$J$19:$J$2018,A30) -> 90 | D30: =INDEX([3]关卡!$N$19:$N$2018,A30) -> 90 | E30: 小怪 | F30: 非R | G30: 3 | H30: 0 | I30: 0 | J30: 1 | K30: 1 | L30: 2 | M30: 15 | N30: 2 | O30: =HLOOKUP(O$5,[1]非R能力!$B$8:$F$558,$C30+1,0) -> 27722.364 | P30: =HLOOKUP(P$5,[1]非R能力!$B$8:$F$558,$C30+1,0) -> 7070.3163 | Q30: =HLOOKUP(Q$5,[1]非R能力!$B$8:$F$558,$C30+1,0) -> 3895.3993 | R30: =HLOOKUP(R$5,[1]非R能力!$B$8:$F$558,$C30+1,0) -> 1136.7128 | S30: =HLOOKUP(S$5,[1]非R能力!$B$8:$F$558,$C30+1,0) -> 1570.5517 | T30: =INDEX([1]非R能力!$H$9:$H$558,D30) -> 85.690488 | U30: =IF(E30="小怪",0,IF(INDEX([1]非R能力!$FK$9:$FK$558,C30)=0,0,10)) -> 0 | V30: =IF(E30="小怪",0,IF(INDEX([1]非R能力!$FH$9:$FH$558,C30)=0,0,5000)) -> 0 | W30: =HLOOKUP(W$5,[2]人物技能基础!$O$3:$Q$553,$C30+1,0) -> 3.6371429 | X30: =HLOOKUP(X$5,[2]人物技能基础!$O$3:$Q$553,$C30+1,0) -> 2.0186429 | Y30: =HLOOKUP(Y$5,[2]人物技能基础!$O$3:$Q$553,$C30+1,0) -> 99.964286 | Z30: =INT(((P30-AB30)*X30+(Y30+T30))*G30*J30*$D$2) -> 34699 | AA30: =IF(H30=0,IF(U30=0,INT(Q30/5),IF(V30=0,INT(Q30/5),INT((V30/U30)/(1/N30*M30)/L30+Q30))),INT((IF(U30=0,0,V30/U30/(1/N30*M30))+O30/H30)/L30+Q30)) -> 779 | AB30: =INT(P30*I30) -> 0 | AC30: =INT(K30*S30) -> 1570 | AD30: =INT(R30/J30) -> 1136
A31: 26 | B31: ="关卡"&A31&E31 -> 关卡26小怪 | C31: =INDEX([3]关卡!$J$19:$J$2018,A31) -> 91 | D31: =INDEX([3]关卡!$N$19:$N$2018,A31) -> 91 | E31: 小怪 | F31: 非R | G31: 3 | H31: 0 | I31: 0 | J31: 1 | K31: 1 | L31: 2 | M31: 15 | N31: 2 | O31: =HLOOKUP(O$5,[1]非R能力!$B$8:$F$558,$C31+1,0) -> 28264.257 | P31: =HLOOKUP(P$5,[1]非R能力!$B$8:$F$558,$C31+1,0) -> 7187.086 | Q31: =HLOOKUP(Q$5,[1]非R能力!$B$8:$F$558,$C31+1,0) -> 3958.3079 | R31: =HLOOKUP(R$5,[1]非R能力!$B$8:$F$558,$C31+1,0) -> 1155.1825 | S31: =HLOOKUP(S$5,[1]非R能力!$B$8:$F$558,$C31+1,0) -> 1594.9828 | T31: =INDEX([1]非R能力!$H$9:$H$558,D31) -> 85.690488 | U31: =IF(E31="小怪",0,IF(INDEX([1]非R能力!$FK$9:$FK$558,C31)=0,0,10)) -> 0 | V31: =IF(E31="小怪",0,IF(INDEX([1]非R能力!$FH$9:$FH$558,C31)=0,0,5000)) -> 0 | W31: =HLOOKUP(W$5,[2]人物技能基础!$O$3:$Q$553,$C31+1,0) -> 3.6371429 | X31: =HLOOKUP(X$5,[2]人物技能基础!$O$3:$Q$553,$C31+1,0) -> 2.0186429 | Y31: =HLOOKUP(Y$5,[2]人物技能基础!$O$3:$Q$553,$C31+1,0) -> 99.964286 | Z31: =INT(((P31-AB31)*X31+(Y31+T31))*G31*J31*$D$2) -> 35265 | AA31: =IF(H31=0,IF(U31=0,INT(Q31/5),IF(V31=0,INT(Q31/5),INT((V31/U31)/(1/N31*M31)/L31+Q31))),INT((IF(U31=0,0,V31/U31/(1/N31*M31))+O31/H31)/L31+Q31)) -> 791 | AB31: =INT(P31*I31) -> 0 | AC31: =INT(K31*S31) -> 1594 | AD31: =INT(R31/J31) -> 1155
A32: 27 | B32: ="关卡"&A32&E32 -> 关卡27小怪 | C32: =INDEX([3]关卡!$J$19:$J$2018,A32) -> 92 | D32: =INDEX([3]关卡!$N$19:$N$2018,A32) -> 92 | E32: 小怪 | F32: 非R | G32: 3 | H32: 0 | I32: 0 | J32: 1 | K32: 1 | L32: 2 | M32: 15 | N32: 2 | O32: =HLOOKUP(O$5,[1]非R能力!$B$8:$F$558,$C32+1,0) -> 28747.549 | P32: =HLOOKUP(P$5,[1]非R能力!$B$8:$F$558,$C32+1,0) -> 7296.5339 | Q32: =HLOOKUP(Q$5,[1]非R能力!$B$8:$F$558,$C32+1,0) -> 4018.7777 | R32: =HLOOKUP(R$5,[1]非R能力!$B$8:$F$558,$C32+1,0) -> 1173.6537 | S32: =HLOOKUP(S$5,[1]非R能力!$B$8:$F$558,$C32+1,0) -> 1619.4153 | T32: =INDEX([1]非R能力!$H$9:$H$558,D32) -> 85.690488 | U32: =IF(E32="小怪",0,IF(INDEX([1]非R能力!$FK$9:$FK$558,C32)=0,0,10)) -> 0 | V32: =IF(E32="小怪",0,IF(INDEX([1]非R能力!$FH$9:$FH$558,C32)=0,0,5000)) -> 0 | W32: =HLOOKUP(W$5,[2]人物技能基础!$O$3:$Q$553,$C32+1,0) -> 3.6371429 | X32: =HLOOKUP(X$5,[2]人物技能基础!$O$3:$Q$553,$C32+1,0) -> 2.0186429 | Y32: =HLOOKUP(Y$5,[2]人物技能基础!$O$3:$Q$553,$C32+1,0) -> 99.964286 | Z32: =INT(((P32-AB32)*X32+(Y32+T32))*G32*J32*$D$2) -> 35795 | AA32: =IF(H32=0,IF(U32=0,INT(Q32/5),IF(V32=0,INT(Q32/5),INT((V32/U32)/(1/N32*M32)/L32+Q32))),INT((IF(U32=0,0,V32/U32/(1/N32*M32))+O32/H32)/L32+Q32)) -> 803 | AB32: =INT(P32*I32) -> 0 | AC32: =INT(K32*S32) -> 1619 | AD32: =INT(R32/J32) -> 1173
A33: 28 | B33: ="关卡"&A33&E33 -> 关卡28小怪 | C33: =INDEX([3]关卡!$J$19:$J$2018,A33) -> 93 | D33: =INDEX([3]关卡!$N$19:$N$2018,A33) -> 93 | E33: 小怪 | F33: 非R | G33: 3 | H33: 0 | I33: 0 | J33: 1 | K33: 1 | L33: 2 | M33: 15 | N33: 2 | O33: =HLOOKUP(O$5,[1]非R能力!$B$8:$F$558,$C33+1,0) -> 29232.008 | P33: =HLOOKUP(P$5,[1]非R能力!$B$8:$F$558,$C33+1,0) -> 7406.1151 | Q33: =HLOOKUP(Q$5,[1]非R能力!$B$8:$F$558,$C33+1,0) -> 4079.2834 | R33: =HLOOKUP(R$5,[1]非R能力!$B$8:$F$558,$C33+1,0) -> 1192.1403 | S33: =HLOOKUP(S$5,[1]非R能力!$B$8:$F$558,$C33+1,0) -> 1643.868 | T33: =INDEX([1]非R能力!$H$9:$H$558,D33) -> 85.690488 | U33: =IF(E33="小怪",0,IF(INDEX([1]非R能力!$FK$9:$FK$558,C33)=0,0,10)) -> 0 | V33: =IF(E33="小怪",0,IF(INDEX([1]非R能力!$FH$9:$FH$558,C33)=0,0,5000)) -> 0 | W33: =HLOOKUP(W$5,[2]人物技能基础!$O$3:$Q$553,$C33+1,0) -> 3.6371429 | X33: =HLOOKUP(X$5,[2]人物技能基础!$O$3:$Q$553,$C33+1,0) -> 2.0186429 | Y33: =HLOOKUP(Y$5,[2]人物技能基础!$O$3:$Q$553,$C33+1,0) -> 99.964286 | Z33: =INT(((P33-AB33)*X33+(Y33+T33))*G33*J33*$D$2) -> 36326 | AA33: =IF(H33=0,IF(U33=0,INT(Q33/5),IF(V33=0,INT(Q33/5),INT((V33/U33)/(1/N33*M33)/L33+Q33))),INT((IF(U33=0,0,V33/U33/(1/N33*M33))+O33/H33)/L33+Q33)) -> 815 | AB33: =INT(P33*I33) -> 0 | AC33: =INT(K33*S33) -> 1643 | AD33: =INT(R33/J33) -> 1192
A34: 29 | B34: ="关卡"&A34&E34 -> 关卡29小怪 | C34: =INDEX([3]关卡!$J$19:$J$2018,A34) -> 94 | D34: =INDEX([3]关卡!$N$19:$N$2018,A34) -> 94 | E34: 小怪 | F34: 非R | G34: 3 | H34: 0 | I34: 0 | J34: 1 | K34: 1 | L34: 2 | M34: 15 | N34: 2 | O34: =HLOOKUP(O$5,[1]非R能力!$B$8:$F$558,$C34+1,0) -> 29716.512 | P34: =HLOOKUP(P$5,[1]非R能力!$B$8:$F$558,$C34+1,0) -> 7515.7049 | Q34: =HLOOKUP(Q$5,[1]非R能力!$B$8:$F$558,$C34+1,0) -> 4139.7939 | R34: =HLOOKUP(R$5,[1]非R能力!$B$8:$F$558,$C34+1,0) -> 1210.6283 | S34: =HLOOKUP(S$5,[1]非R能力!$B$8:$F$558,$C34+1,0) -> 1668.3222 | T34: =INDEX([1]非R能力!$H$9:$H$558,D34) -> 85.690488 | U34: =IF(E34="小怪",0,IF(INDEX([1]非R能力!$FK$9:$FK$558,C34)=0,0,10)) -> 0 | V34: =IF(E34="小怪",0,IF(INDEX([1]非R能力!$FH$9:$FH$558,C34)=0,0,5000)) -> 0 | W34: =HLOOKUP(W$5,[2]人物技能基础!$O$3:$Q$553,$C34+1,0) -> 3.6371429 | X34: =HLOOKUP(X$5,[2]人物技能基础!$O$3:$Q$553,$C34+1,0) -> 2.0186429 | Y34: =HLOOKUP(Y$5,[2]人物技能基础!$O$3:$Q$553,$C34+1,0) -> 99.964286 | Z34: =INT(((P34-AB34)*X34+(Y34+T34))*G34*J34*$D$2) -> 36857 | AA34: =IF(H34=0,IF(U34=0,INT(Q34/5),IF(V34=0,INT(Q34/5),INT((V34/U34)/(1/N34*M34)/L34+Q34))),INT((IF(U34=0,0,V34/U34/(1/N34*M34))+O34/H34)/L34+Q34)) -> 827 | AB34: =INT(P34*I34) -> 0 | AC34: =INT(K34*S34) -> 1668 | AD34: =INT(R34/J34) -> 1210
... A4005: 2000 | B4005: ="关卡"&A4005&E4005 -> 关卡2000boss | C4005: =INDEX([3]关卡!$J$19:$J$2018,A4005) -> 550 | D4005: =INDEX([3]关卡!$N$19:$N$2018,A4005) -> 550 | E4005: boss | F4005: 非R | G4005: 30 | H4005: 30 | I4005: 0.2 | J4005: 0.75 | K4005: 1 | L4005: 5 | M4005: 1 | N4005: 2 | O4005: =HLOOKUP(O$5,[1]非R能力!$B$8:$F$558,$C4005+1,0) -> 2674530.2 | P4005: =HLOOKUP(P$5,[1]非R能力!$B$8:$F$558,$C4005+1,0) -> 371147.95 | Q4005: =HLOOKUP(Q$5,[1]非R能力!$B$8:$F$558,$C4005+1,0) -> 180663.03 | R4005: =HLOOKUP(R$5,[1]非R能力!$B$8:$F$558,$C4005+1,0) -> 56616.731 | S4005: =HLOOKUP(S$5,[1]非R能力!$B$8:$F$558,$C4005+1,0) -> 73368.569 | T4005: =INDEX([1]非R能力!$H$9:$H$558,D4005) -> 74359.208 | U4005: =IF(E4005="小怪",0,IF(INDEX([1]非R能力!$FK$9:$FK$558,C4005)=0,0,10)) -> 10 | V4005: =IF(E4005="小怪",0,IF(INDEX([1]非R能力!$FH$9:$FH$558,C4005)=0,0,5000)) -> 5000 | W4005: =HLOOKUP(W$5,[2]人物技能基础!$O$3:$Q$553,$C4005+1,0) -> 3.6371429 | X4005: =HLOOKUP(X$5,[2]人物技能基础!$O$3:$Q$553,$C4005+1,0) -> 2.0186429 | Y4005: =HLOOKUP(Y$5,[2]人物技能基础!$O$3:$Q$553,$C4005+1,0) -> 99.964286 | Z4005: =INT(((P4005-AB4005)*X4005+(Y4005+T4005))*G4005*J4005*$D$2) -> 12128984 | AA4005: =IF(H4005=0,IF(U4005=0,INT(Q4005/5),IF(V4005=0,INT(Q4005/5),INT((V4005/U4005)/(1/N4005*M4005)/L4005+Q4005))),INT((IF(U4005=0,0,V4005/U4005/(1/N4005*M4005))+O4005/H4005)/L4005+Q4005)) -> 198693 | AB4005: =INT(P4005*I4005) -> 74229 | AC4005: =INT(K4005*S4005) -> 73368 | AD4005: =INT(R4005/J4005) -> 75488

Sheet 个人boss
D1: 伤害溢出修正 | F1: 技能目标误差修正
D2: 0.8 | F2: 0.8
D4: 怪物属性设计 | O4: 目标玩家能力（简易版，仅有计算玩家基础属性,不计算化神，宠物，以后再添加特殊属性和化神等因素） | Z4: 怪物属性
A5: boss等级 | B5: 怪物名字 | C5: 怪物等级 | D5: 属性等级 | E5: 怪物类型 | F5: 能力模板 | G5: 怪物受击 | H5: 玩家受击 | I5: 防御抵消比例 | J5: 玩家对怪物命中 | K5: 怪物对玩家命中 | L5: 怪物技能系数 | M5: 围攻怪物个数 | N5: 攻击间隔/s | O5: 生命 | P5: 攻击 | Q5: 防御 | R5: 命中 | S5: 闪避 | T5: 技能固定伤害 | U5: 回血间隔 | V5: 回血量 | W5: 每招平均目标 | X5: 每招平均技能伤害 | Y5: 每招平均固伤 | Z5: 生命 | AA5: 攻击 | AB5: 防御 | AC5: 命中 | AD5: 闪避 | AJ5: 怪物属性算法
A6: =[2]基础装备!X4 -> 50 | B6: =A6&"级个人boss" -> 50级个人boss | C6: =A6 -> 50 | D6: =C6-10 -> 40 | E6: boss | F6: 非R | G6: 15 | H6: 30 | I6: 0.1 | J6: 0.7 | K6: 1 | L6: 5 | M6: 1 | N6: 2 | O6: =HLOOKUP(O$5,[1]非R能力!$B$8:$F$558,$D6+1,0) -> 4955 | P6: =HLOOKUP(P$5,[1]非R能力!$B$8:$F$558,$D6+1,0) -> 1336 | Q6: =HLOOKUP(Q$5,[1]非R能力!$B$8:$F$558,$D6+1,0) -> 943.71429 | R6: =HLOOKUP(R$5,[1]非R能力!$B$8:$F$558,$D6+1,0) -> 290.42857 | S6: =HLOOKUP(S$5,[1]非R能力!$B$8:$F$558,$D6+1,0) -> 333.38462 | T6: =INDEX([1]非R能力!$H$9:$H$558,D6) -> 0 | U6: =IF(INDEX([1]非R能力!$FK$9:$FK$558,D6)=0,0,10) -> 0 | V6: =IF(INDEX([1]非R能力!$FH$9:$FH$558,D6)=0,0,5000) -> 0 | W6: =HLOOKUP(W$5,[2]人物技能基础!$O$3:$Q$553,$D6+1,0) -> 2.9 | X6: =HLOOKUP(X$5,[2]人物技能基础!$O$3:$Q$553,$D6+1,0) -> 1.7675 | Y6: =HLOOKUP(Y$5,[2]人物技能基础!$O$3:$Q$553,$D6+1,0) -> 78.75 | Z6: =INT(((P6-AB6)*X6+(Y6+T6))*G6*J6*$D$2) -> 18522 | AA6: =IF(H6=0,IF(U6=0,INT(Q6/5),IF(V6=0,INT(Q6/5),INT((V6/U6)/(1/N6*M6)/L6+Q6))),INT((IF(U6=0,0,V6/U6/(1/N6*M6))+O6/H6)/L6+Q6)) -> 976 | AB6: =INT(P6*I6) -> 133 | AC6: =INT(K6*S6) -> 333 | AD6: =INT(R6/J6) -> 414 | AJ6: 生命 | AK6: （（攻击-怪物防御）*技能系数+技能固伤）*怪物受击*玩家命中*伤害溢出修正
A7: =[2]基础装备!X5 -> 75 | B7: =A7&"级个人boss" -> 75级个人boss | C7: =A7 -> 75 | D7: =C7-5 -> 70 | E7: boss | F7: 非R | G7: 20 | H7: 30 | I7: 0.1 | J7: 0.7 | K7: 1 | L7: 5 | M7: 1 | N7: 2 | O7: =HLOOKUP(O$5,[1]非R能力!$B$8:$F$558,$D7+1,0) -> 12949.476 | P7: =HLOOKUP(P$5,[1]非R能力!$B$8:$F$558,$D7+1,0) -> 3264.1862 | Q7: =HLOOKUP(Q$5,[1]非R能力!$B$8:$F$558,$D7+1,0) -> 1811.8673 | R7: =HLOOKUP(R$5,[1]非R能力!$B$8:$F$558,$D7+1,0) -> 624.07384 | S7: =HLOOKUP(S$5,[1]非R能力!$B$8:$F$558,$D7+1,0) -> 910.38905 | T7: =INDEX([1]非R能力!$H$9:$H$558,D7) -> 28.459063 | U7: =IF(INDEX([1]非R能力!$FK$9:$FK$558,D7)=0,0,10) -> 0 | V7: =IF(INDEX([1]非R能力!$FH$9:$FH$558,D7)=0,0,5000) -> 0 | W7: =HLOOKUP(W$5,[2]人物技能基础!$O$3:$Q$553,$D7+1,0) -> 3.6371429 | X7: =HLOOKUP(X$5,[2]人物技能基础!$O$3:$Q$553,$D7+1,0) -> 2.0186429 | Y7: =HLOOKUP(Y$5,[2]人物技能基础!$O$3:$Q$553,$D7+1,0) -> 99.964286 | Z7: =INT(((P7-AB7)*X7+(Y7+T7))*G7*J7*$D$2) -> 67867 | AA7: =IF(H7=0,IF(U7=0,INT(Q7/5),IF(V7=0,INT(Q7/5),INT((V7/U7)/(1/N7*M7)/L7+Q7))),INT((IF(U7=0,0,V7/U7/(1/N7*M7))+O7/H7)/L7+Q7)) -> 1898 | AB7: =INT(P7*I7) -> 326 | AC7: =INT(K7*S7) -> 910 | AD7: =INT(R7/J7) -> 891
A8: =[2]基础装备!X6 -> 120 | B8: =A8&"级个人boss" -> 120级个人boss | C8: =A8 -> 120 | D8: =C8-5 -> 115 | E8: boss | F8: 非R | G8: 30 | H8: 30 | I8: 0.1 | J8: 0.7 | K8: 1 | L8: 5 | M8: 1 | N8: 2 | O8: =HLOOKUP(O$5,[1]非R能力!$B$8:$F$558,$D8+1,0) -> 40627.131 | P8: =HLOOKUP(P$5,[1]非R能力!$B$8:$F$558,$D8+1,0) -> 10015.553 | Q8: =HLOOKUP(Q$5,[1]非R能力!$B$8:$F$558,$D8+1,0) -> 5710.961 | R8: =HLOOKUP(R$5,[1]非R能力!$B$8:$F$558,$D8+1,0) -> 1616.3145 | S8: =HLOOKUP(S$5,[1]非R能力!$B$8:$F$558,$D8+1,0) -> 2330.0294 | T8: =INDEX([1]非R能力!$H$9:$H$558,D8) -> 289.38111 | U8: =IF(INDEX([1]非R能力!$FK$9:$FK$558,D8)=0,0,10) -> 10 | V8: =IF(INDEX([1]非R能力!$FH$9:$FH$558,D8)=0,0,5000) -> 5000 | W8: =HLOOKUP(W$5,[2]人物技能基础!$O$3:$Q$553,$D8+1,0) -> 3.6371429 | X8: =HLOOKUP(X$5,[2]人物技能基础!$O$3:$Q$553,$D8+1,0) -> 2.0186429 | Y8: =HLOOKUP(Y$5,[2]人物技能基础!$O$3:$Q$553,$D8+1,0) -> 99.964286 | Z8: =INT(((P8-AB8)*X8+(Y8+T8))*G8*J8*$D$2) -> 312253 | AA8: =IF(H8=0,IF(U8=0,INT(Q8/5),IF(V8=0,INT(Q8/5),INT((V8/U8)/(1/N8*M8)/L8+Q8))),INT((IF(U8=0,0,V8/U8/(1/N8*M8))+O8/H8)/L8+Q8)) -> 6181 | AB8: =INT(P8*I8) -> 1001 | AC8: =INT(K8*S8) -> 2330 | AD8: =INT(R8/J8) -> 2309
A9: =[2]基础装备!X7 -> 200 | B9: =A9&"级个人boss" -> 200级个人boss | C9: =A9 -> 200 | D9: =C9 -> 200 | E9: boss | F9: 非R | G9: 30 | H9: 30 | I9: 0.1 | J9: 0.7 | K9: 1 | L9: 5 | M9: 1 | N9: 2 | O9: =HLOOKUP(O$5,[1]非R能力!$B$8:$F$558,$D9+1,0) -> 107784.87 | P9: =HLOOKUP(P$5,[1]非R能力!$B$8:$F$558,$D9+1,0) -> 22104.517 | Q9: =HLOOKUP(Q$5,[1]非R能力!$B$8:$F$558,$D9+1,0) -> 11799.062 | R9: =HLOOKUP(R$5,[1]非R能力!$B$8:$F$558,$D9+1,0) -> 3946.3154 | S9: =HLOOKUP(S$5,[1]非R能力!$B$8:$F$558,$D9+1,0) -> 4776.8845 | T9: =INDEX([1]非R能力!$H$9:$H$558,D9) -> 7164.8291 | U9: =IF(INDEX([1]非R能力!$FK$9:$FK$558,D9)=0,0,10) -> 10 | V9: =IF(INDEX([1]非R能力!$FH$9:$FH$558,D9)=0,0,5000) -> 5000 | W9: =HLOOKUP(W$5,[2]人物技能基础!$O$3:$Q$553,$D9+1,0) -> 3.6371429 | X9: =HLOOKUP(X$5,[2]人物技能基础!$O$3:$Q$553,$D9+1,0) -> 2.0186429 | Y9: =HLOOKUP(Y$5,[2]人物技能基础!$O$3:$Q$553,$D9+1,0) -> 99.964286 | Z9: =INT(((P9-AB9)*X9+(Y9+T9))*G9*J9*$D$2) -> 796735 | AA9: =IF(H9=0,IF(U9=0,INT(Q9/5),IF(V9=0,INT(Q9/5),INT((V9/U9)/(1/N9*M9)/L9+Q9))),INT((IF(U9=0,0,V9/U9/(1/N9*M9))+O9/H9)/L9+Q9)) -> 12717 | AB9: =INT(P9*I9) -> 2210 | AC9: =INT(K9*S9) -> 4776 | AD9: =INT(R9/J9) -> 5637
A10: =[2]基础装备!X8 -> 225 | B10: =A10&"级个人boss" -> 225级个人boss | C10: =A10 -> 225 | D10: =C10 -> 225 | E10: boss | F10: 非R | G10: 30 | H10: 30 | I10: 0.1 | J10: 0.7 | K10: 1 | L10: 5 | M10: 1 | N10: 2 | O10: =HLOOKUP(O$5,[1]非R能力!$B$8:$F$558,$D10+1,0) -> 140011.21 | P10: =HLOOKUP(P$5,[1]非R能力!$B$8:$F$558,$D10+1,0) -> 27470.791 | Q10: =HLOOKUP(Q$5,[1]非R能力!$B$8:$F$558,$D10+1,0) -> 17651.095 | R10: =HLOOKUP(R$5,[1]非R能力!$B$8:$F$558,$D10+1,0) -> 4701.219 | S10: =HLOOKUP(S$5,[1]非R能力!$B$8:$F$558,$D10+1,0) -> 5734.8246 | T10: =INDEX([1]非R能力!$H$9:$H$558,D10) -> 10442.261 | U10: =IF(INDEX([1]非R能力!$FK$9:$FK$558,D10)=0,0,10) -> 10 | V10: =IF(INDEX([1]非R能力!$FH$9:$FH$558,D10)=0,0,5000) -> 5000 | W10: =HLOOKUP(W$5,[2]人物技能基础!$O$3:$Q$553,$D10+1,0) -> 3.6371429 | X10: =HLOOKUP(X$5,[2]人物技能基础!$O$3:$Q$553,$D10+1,0) -> 2.0186429 | Y10: =HLOOKUP(Y$5,[2]人物技能基础!$O$3:$Q$553,$D10+1,0) -> 99.964286 | Z10: =INT(((P10-AB10)*X10+(Y10+T10))*G10*J10*$D$2) -> 1015572 | AA10: =IF(H10=0,IF(U10=0,INT(Q10/5),IF(V10=0,INT(Q10/5),INT((V10/U10)/(1/N10*M10)/L10+Q10))),INT((IF(U10=0,0,V10/U10/(1/N10*M10))+O10/H10)/L10+Q10)) -> 18784 | AB10: =INT(P10*I10) -> 2747 | AC10: =INT(K10*S10) -> 5734 | AD10: =INT(R10/J10) -> 6716
A11: =[2]基础装备!X9 -> 250 | B11: =A11&"级个人boss" -> 250级个人boss | C11: =A11 -> 250 | D11: =C11 -> 250 | E11: boss | F11: 非R | G11: 30 | H11: 30 | I11: 0.1 | J11: 0.7 | K11: 1 | L11: 5 | M11: 1 | N11: 2 | O11: =HLOOKUP(O$5,[1]非R能力!$B$8:$F$558,$D11+1,0) -> 182781.49 | P11: =HLOOKUP(P$5,[1]非R能力!$B$8:$F$558,$D11+1,0) -> 34702.846 | Q11: =HLOOKUP(Q$5,[1]非R能力!$B$8:$F$558,$D11+1,0) -> 21102.148 | R11: =HLOOKUP(R$5,[1]非R能力!$B$8:$F$558,$D11+1,0) -> 5592.8641 | S11: =HLOOKUP(S$5,[1]非R能力!$B$8:$F$558,$D11+1,0) -> 6941.7828 | T11: =INDEX([1]非R能力!$H$9:$H$558,D11) -> 12589.769 | U11: =IF(INDEX([1]非R能力!$FK$9:$FK$558,D11)=0,0,10) -> 10 | V11: =IF(INDEX([1]非R能力!$FH$9:$FH$558,D11)=0,0,5000) -> 5000 | W11: =HLOOKUP(W$5,[2]人物技能基础!$O$3:$Q$553,$D11+1,0) -> 3.6371429 | X11: =HLOOKUP(X$5,[2]人物技能基础!$O$3:$Q$553,$D11+1,0) -> 2.0186429 | Y11: =HLOOKUP(Y$5,[2]人物技能基础!$O$3:$Q$553,$D11+1,0) -> 99.964286 | Z11: =INT(((P11-AB11)*X11+(Y11+T11))*G11*J11*$D$2) -> 1272393 | AA11: =IF(H11=0,IF(U11=0,INT(Q11/5),IF(V11=0,INT(Q11/5),INT((V11/U11)/(1/N11*M11)/L11+Q11))),INT((IF(U11=0,0,V11/U11/(1/N11*M11))+O11/H11)/L11+Q11)) -> 22520 | AB11: =INT(P11*I11) -> 3470 | AC11: =INT(K11*S11) -> 6941 | AD11: =INT(R11/J11) -> 7989
A12: =[2]基础装备!X10 -> 275 | B12: =A12&"级个人boss" -> 275级个人boss | C12: =A12 -> 275 | D12: =C12 -> 275 | E12: boss | F12: 非R | G12: 30 | H12: 30 | I12: 0.1 | J12: 0.7 | K12: 1 | L12: 5 | M12: 1 | N12: 2 | O12: =HLOOKUP(O$5,[1]非R能力!$B$8:$F$558,$D12+1,0) -> 259422.16 | P12: =HLOOKUP(P$5,[1]非R能力!$B$8:$F$558,$D12+1,0) -> 48467.014 | Q12: =HLOOKUP(Q$5,[1]非R能力!$B$8:$F$558,$D12+1,0) -> 29625.345 | R12: =HLOOKUP(R$5,[1]非R能力!$B$8:$F$558,$D12+1,0) -> 7660.5635 | S12: =HLOOKUP(S$5,[1]非R能力!$B$8:$F$558,$D12+1,0) -> 9915.2017 | T12: =INDEX([1]非R能力!$H$9:$H$558,D12) -> 15039.455 | U12: =IF(INDEX([1]非R能力!$FK$9:$FK$558,D12)=0,0,10) -> 10 | V12: =IF(INDEX([1]非R能力!$FH$9:$FH$558,D12)=0,0,5000) -> 5000 | W12: =HLOOKUP(W$5,[2]人物技能基础!$O$3:$Q$553,$D12+1,0) -> 3.6371429 | X12: =HLOOKUP(X$5,[2]人物技能基础!$O$3:$Q$553,$D12+1,0) -> 2.0186429 | Y12: =HLOOKUP(Y$5,[2]人物技能基础!$O$3:$Q$553,$D12+1,0) -> 99.964286 | Z12: =INT(((P12-AB12)*X12+(Y12+T12))*G12*J12*$D$2) -> 1733670 | AA12: =IF(H12=0,IF(U12=0,INT(Q12/5),IF(V12=0,INT(Q12/5),INT((V12/U12)/(1/N12*M12)/L12+Q12))),INT((IF(U12=0,0,V12/U12/(1/N12*M12))+O12/H12)/L12+Q12)) -> 31554 | AB12: =INT(P12*I12) -> 4846 | AC12: =INT(K12*S12) -> 9915 | AD12: =INT(R12/J12) -> 10943
A13: =[2]基础装备!X11 -> 300 | B13: =A13&"级个人boss" -> 300级个人boss | C13: =A13 -> 300 | D13: =C13 -> 300 | E13: boss | F13: 非R | G13: 30 | H13: 30 | I13: 0.1 | J13: 0.7 | K13: 1 | L13: 5 | M13: 1 | N13: 2 | O13: =HLOOKUP(O$5,[1]非R能力!$B$8:$F$558,$D13+1,0) -> 409002.32 | P13: =HLOOKUP(P$5,[1]非R能力!$B$8:$F$558,$D13+1,0) -> 70358.046 | Q13: =HLOOKUP(Q$5,[1]非R能力!$B$8:$F$558,$D13+1,0) -> 42521.249 | R13: =HLOOKUP(R$5,[1]非R能力!$B$8:$F$558,$D13+1,0) -> 56463.899 | S13: =HLOOKUP(S$5,[1]非R能力!$B$8:$F$558,$D13+1,0) -> 15445.657 | T13: =INDEX([1]非R能力!$H$9:$H$558,D13) -> 17828.778 | U13: =IF(INDEX([1]非R能力!$FK$9:$FK$558,D13)=0,0,10) -> 10 | V13: =IF(INDEX([1]非R能力!$FH$9:$FH$558,D13)=0,0,5000) -> 5000 | W13: =HLOOKUP(W$5,[2]人物技能基础!$O$3:$Q$553,$D13+1,0) -> 3.6371429 | X13: =HLOOKUP(X$5,[2]人物技能基础!$O$3:$Q$553,$D13+1,0) -> 2.0186429 | Y13: =HLOOKUP(Y$5,[2]人物技能基础!$O$3:$Q$553,$D13+1,0) -> 99.964286 | Z13: =INT(((P13-AB13)*X13+(Y13+T13))*G13*J13*$D$2) -> 2448690 | AA13: =IF(H13=0,IF(U13=0,INT(Q13/5),IF(V13=0,INT(Q13/5),INT((V13/U13)/(1/N13*M13)/L13+Q13))),INT((IF(U13=0,0,V13/U13/(1/N13*M13))+O13/H13)/L13+Q13)) -> 45447 | AB13: =INT(P13*I13) -> 7035 | AC13: =INT(K13*S13) -> 15445 | AD13: =INT(R13/J13) -> 80662
A14: =[2]基础装备!X12 -> 325 | B14: =A14&"级个人boss" -> 325级个人boss | C14: =A14 -> 325 | D14: =C14 -> 325 | E14: boss | F14: 非R | G14: 30 | H14: 30 | I14: 0.1 | J14: 0.7 | K14: 1 | L14: 5 | M14: 1 | N14: 2 | O14: =HLOOKUP(O$5,[1]非R能力!$B$8:$F$558,$D14+1,0) -> 623773.64 | P14: =HLOOKUP(P$5,[1]非R能力!$B$8:$F$558,$D14+1,0) -> 97671.389 | Q14: =HLOOKUP(Q$5,[1]非R能力!$B$8:$F$558,$D14+1,0) -> 56956.215 | R14: =HLOOKUP(R$5,[1]非R能力!$B$8:$F$558,$D14+1,0) -> 61820.457 | S14: =HLOOKUP(S$5,[1]非R能力!$B$8:$F$558,$D14+1,0) -> 21333.565 | T14: =INDEX([1]非R能力!$H$9:$H$558,D14) -> 20997.595 | U14: =IF(INDEX([1]非R能力!$FK$9:$FK$558,D14)=0,0,10) -> 10 | V14: =IF(INDEX([1]非R能力!$FH$9:$FH$558,D14)=0,0,5000) -> 5000 | W14: =HLOOKUP(W$5,[2]人物技能基础!$O$3:$Q$553,$D14+1,0) -> 3.6371429 | X14: =HLOOKUP(X$5,[2]人物技能基础!$O$3:$Q$553,$D14+1,0) -> 2.0186429 | Y14: =HLOOKUP(Y$5,[2]人物技能基础!$O$3:$Q$553,$D14+1,0) -> 99.964286 | Z14: =INT(((P14-AB14)*X14+(Y14+T14))*G14*J14*$D$2) -> 3335558 | AA14: =IF(H14=0,IF(U14=0,INT(Q14/5),IF(V14=0,INT(Q14/5),INT((V14/U14)/(1/N14*M14)/L14+Q14))),INT((IF(U14=0,0,V14/U14/(1/N14*M14))+O14/H14)/L14+Q14)) -> 61314 | AB14: =INT(P14*I14) -> 9767 | AC14: =INT(K14*S14) -> 21333 | AD14: =INT(R14/J14) -> 88314
A15: =[2]基础装备!X13 -> 350 | B15: =A15&"级个人boss" -> 350级个人boss | C15: =A15 -> 350 | D15: =C15 -> 350 | E15: boss | F15: 非R | G15: 30 | H15: 30 | I15: 0.1 | J15: 0.7 | K15: 1 | L15: 5 | M15: 1 | N15: 2 | O15: =HLOOKUP(O$5,[1]非R能力!$B$8:$F$558,$D15+1,0) -> 810712.74 | P15: =HLOOKUP(P$5,[1]非R能力!$B$8:$F$558,$D15+1,0) -> 121774.47 | Q15: =HLOOKUP(Q$5,[1]非R能力!$B$8:$F$558,$D15+1,0) -> 68368.938 | R15: =HLOOKUP(R$5,[1]非R能力!$B$8:$F$558,$D15+1,0) -> 19987.25 | S15: =HLOOKUP(S$5,[1]非R能力!$B$8:$F$558,$D15+1,0) -> 26649.6 | T15: =INDEX([1]非R能力!$H$9:$H$558,D15) -> 24588.164 | U15: =IF(INDEX([1]非R能力!$FK$9:$FK$558,D15)=0,0,10) -> 10 | V15: =IF(INDEX([1]非R能力!$FH$9:$FH$558,D15)=0,0,5000) -> 5000 | W15: =HLOOKUP(W$5,[2]人物技能基础!$O$3:$Q$553,$D15+1,0) -> 3.6371429 | X15: =HLOOKUP(X$5,[2]人物技能基础!$O$3:$Q$553,$D15+1,0) -> 2.0186429 | Y15: =HLOOKUP(Y$5,[2]人物技能基础!$O$3:$Q$553,$D15+1,0) -> 99.964286 | Z15: =INT(((P15-AB15)*X15+(Y15+T15))*G15*J15*$D$2) -> 4131561 | AA15: =IF(H15=0,IF(U15=0,INT(Q15/5),IF(V15=0,INT(Q15/5),INT((V15/U15)/(1/N15*M15)/L15+Q15))),INT((IF(U15=0,0,V15/U15/(1/N15*M15))+O15/H15)/L15+Q15)) -> 73973 | AB15: =INT(P15*I15) -> 12177 | AC15: =INT(K15*S15) -> 26649 | AD15: =INT(R15/J15) -> 28553
A16: =[2]基础装备!X14 -> 375 | B16: =A16&"级个人boss" -> 375级个人boss | C16: =A16 -> 375 | D16: =C16 -> 375 | E16: boss | F16: 非R | G16: 30 | H16: 30 | I16: 0.1 | J16: 0.7 | K16: 1 | L16: 5 | M16: 1 | N16: 2 | O16: =HLOOKUP(O$5,[1]非R能力!$B$8:$F$558,$D16+1,0) -> 1049754.8 | P16: =HLOOKUP(P$5,[1]非R能力!$B$8:$F$558,$D16+1,0) -> 155689.92 | Q16: =HLOOKUP(Q$5,[1]非R能力!$B$8:$F$558,$D16+1,0) -> 87574.97 | R16: =HLOOKUP(R$5,[1]非R能力!$B$8:$F$558,$D16+1,0) -> 26286.01 | S16: =HLOOKUP(S$5,[1]非R能力!$B$8:$F$558,$D16+1,0) -> 35920.736 | T16: =INDEX([1]非R能力!$H$9:$H$558,D16) -> 28645.145 | U16: =IF(INDEX([1]非R能力!$FK$9:$FK$558,D16)=0,0,10) -> 10 | V16: =IF(INDEX([1]非R能力!$FH$9:$FH$558,D16)=0,0,5000) -> 5000 | W16: =HLOOKUP(W$5,[2]人物技能基础!$O$3:$Q$553,$D16+1,0) -> 3.6371429 | X16: =HLOOKUP(X$5,[2]人物技能基础!$O$3:$Q$553,$D16+1,0) -> 2.0186429 | Y16: =HLOOKUP(Y$5,[2]人物技能基础!$O$3:$Q$553,$D16+1,0) -> 99.964286 | Z16: =INT(((P16-AB16)*X16+(Y16+T16))*G16*J16*$D$2) -> 5234900 | AA16: =IF(H16=0,IF(U16=0,INT(Q16/5),IF(V16=0,INT(Q16/5),INT((V16/U16)/(1/N16*M16)/L16+Q16))),INT((IF(U16=0,0,V16/U16/(1/N16*M16))+O16/H16)/L16+Q16)) -> 94773 | AB16: =INT(P16*I16) -> 15568 | AC16: =INT(K16*S16) -> 35920 | AD16: =INT(R16/J16) -> 37551
A17: =[2]基础装备!X15 -> 400 | B17: =A17&"级个人boss" -> 400级个人boss | C17: =A17 -> 400 | D17: =C17 -> 400 | E17: boss | F17: 非R | G17: 30 | H17: 30 | I17: 0.1 | J17: 0.7 | K17: 1 | L17: 5 | M17: 1 | N17: 2 | O17: =HLOOKUP(O$5,[1]非R能力!$B$8:$F$558,$D17+1,0) -> 1185370.5 | P17: =HLOOKUP(P$5,[1]非R能力!$B$8:$F$558,$D17+1,0) -> 173146.15 | Q17: =HLOOKUP(Q$5,[1]非R能力!$B$8:$F$558,$D17+1,0) -> 95408.041 | R17: =HLOOKUP(R$5,[1]非R能力!$B$8:$F$558,$D17+1,0) -> 28892.178 | S17: =HLOOKUP(S$5,[1]非R能力!$B$8:$F$558,$D17+1,0) -> 38976.283 | T17: =INDEX([1]非R能力!$H$9:$H$558,D17) -> 33215.6 | U17: =IF(INDEX([1]非R能力!$FK$9:$FK$558,D17)=0,0,10) -> 10 | V17: =IF(INDEX([1]非R能力!$FH$9:$FH$558,D17)=0,0,5000) -> 5000 | W17: =HLOOKUP(W$5,[2]人物技能基础!$O$3:$Q$553,$D17+1,0) -> 3.6371429 | X17: =HLOOKUP(X$5,[2]人物技能基础!$O$3:$Q$553,$D17+1,0) -> 2.0186429 | Y17: =HLOOKUP(Y$5,[2]人物技能基础!$O$3:$Q$553,$D17+1,0) -> 99.964286 | Z17: =INT(((P17-AB17)*X17+(Y17+T17))*G17*J17*$D$2) -> 5844468 | AA17: =IF(H17=0,IF(U17=0,INT(Q17/5),IF(V17=0,INT(Q17/5),INT((V17/U17)/(1/N17*M17)/L17+Q17))),INT((IF(U17=0,0,V17/U17/(1/N17*M17))+O17/H17)/L17+Q17)) -> 103510 | AB17: =INT(P17*I17) -> 17314 | AC17: =INT(K17*S17) -> 38976 | AD17: =INT(R17/J17) -> 41274
A18: =[2]基础装备!X16 -> 425 | B18: =A18&"级个人boss" -> 425级个人boss | C18: =A18 -> 425 | D18: =C18 -> 425 | E18: boss | F18: 非R | G18: 30 | H18: 30 | I18: 0.1 | J18: 0.7 | K18: 1 | L18: 5 | M18: 1 | N18: 2 | O18: =HLOOKUP(O$5,[1]非R能力!$B$8:$F$558,$D18+1,0) -> 1365403 | P18: =HLOOKUP(P$5,[1]非R能力!$B$8:$F$558,$D18+1,0) -> 198123.17 | Q18: =HLOOKUP(Q$5,[1]非R能力!$B$8:$F$558,$D18+1,0) -> 107166.07 | R18: =HLOOKUP(R$5,[1]非R能力!$B$8:$F$558,$D18+1,0) -> 32793.565 | S18: =HLOOKUP(S$5,[1]非R能力!$B$8:$F$558,$D18+1,0) -> 43450.681 | T18: =INDEX([1]非R能力!$H$9:$H$558,D18) -> 38348.99 | U18: =IF(INDEX([1]非R能力!$FK$9:$FK$558,D18)=0,0,10) -> 10 | V18: =IF(INDEX([1]非R能力!$FH$9:$FH$558,D18)=0,0,5000) -> 5000 | W18: =HLOOKUP(W$5,[2]人物技能基础!$O$3:$Q$553,$D18+1,0) -> 3.6371429 | X18: =HLOOKUP(X$5,[2]人物技能基础!$O$3:$Q$553,$D18+1,0) -> 2.0186429 | Y18: =HLOOKUP(Y$5,[2]人物技能基础!$O$3:$Q$553,$D18+1,0) -> 99.964286 | Z18: =INT(((P18-AB18)*X18+(Y18+T18))*G18*J18*$D$2) -> 6693044 | AA18: =IF(H18=0,IF(U18=0,INT(Q18/5),IF(V18=0,INT(Q18/5),INT((V18/U18)/(1/N18*M18)/L18+Q18))),INT((IF(U18=0,0,V18/U18/(1/N18*M18))+O18/H18)/L18+Q18)) -> 116468 | AB18: =INT(P18*I18) -> 19812 | AC18: =INT(K18*S18) -> 43450 | AD18: =INT(R18/J18) -> 46847
A19: =[2]基础装备!X17 -> 450 | B19: =A19&"级个人boss" -> 450级个人boss | C19: =A19 -> 450 | D19: =C19 -> 450 | E19: boss | F19: 非R | G19: 30 | H19: 30 | I19: 0.1 | J19: 0.7 | K19: 1 | L19: 5 | M19: 1 | N19: 2 | O19: =HLOOKUP(O$5,[1]非R能力!$B$8:$F$558,$D19+1,0) -> 1514166.9 | P19: =HLOOKUP(P$5,[1]非R能力!$B$8:$F$558,$D19+1,0) -> 215507.01 | Q19: =HLOOKUP(Q$5,[1]非R能力!$B$8:$F$558,$D19+1,0) -> 114372.35 | R19: =HLOOKUP(R$5,[1]非R能力!$B$8:$F$558,$D19+1,0) -> 35109.592 | S19: =HLOOKUP(S$5,[1]非R能力!$B$8:$F$558,$D19+1,0) -> 46259.04 | T19: =INDEX([1]非R能力!$H$9:$H$558,D19) -> 44097.178 | U19: =IF(INDEX([1]非R能力!$FK$9:$FK$558,D19)=0,0,10) -> 10 | V19: =IF(INDEX([1]非R能力!$FH$9:$FH$558,D19)=0,0,5000) -> 5000 | W19: =HLOOKUP(W$5,[2]人物技能基础!$O$3:$Q$553,$D19+1,0) -> 3.6371429 | X19: =HLOOKUP(X$5,[2]人物技能基础!$O$3:$Q$553,$D19+1,0) -> 2.0186429 | Y19: =HLOOKUP(Y$5,[2]人物技能基础!$O$3:$Q$553,$D19+1,0) -> 99.964286 | Z19: =INT(((P19-AB19)*X19+(Y19+T19))*G19*J19*$D$2) -> 7320214 | AA19: =IF(H19=0,IF(U19=0,INT(Q19/5),IF(V19=0,INT(Q19/5),INT((V19/U19)/(1/N19*M19)/L19+Q19))),INT((IF(U19=0,0,V19/U19/(1/N19*M19))+O19/H19)/L19+Q19)) -> 124666 | AB19: =INT(P19*I19) -> 21550 | AC19: =INT(K19*S19) -> 46259 | AD19: =INT(R19/J19) -> 50156
A20: =[2]基础装备!X18 -> 475 | B20: =A20&"级个人boss" -> 475级个人boss | C20: =A20 -> 475 | D20: =C20 -> 475 | E20: boss | F20: 非R | G20: 30 | H20: 30 | I20: 0.1 | J20: 0.7 | K20: 1 | L20: 5 | M20: 1 | N20: 2 | O20: =HLOOKUP(O$5,[1]非R能力!$B$8:$F$558,$D20+1,0) -> 1802644.1 | P20: =HLOOKUP(P$5,[1]非R能力!$B$8:$F$558,$D20+1,0) -> 255768.43 | Q20: =HLOOKUP(Q$5,[1]非R能力!$B$8:$F$558,$D20+1,0) -> 132839.04 | R20: =HLOOKUP(R$5,[1]非R能力!$B$8:$F$558,$D20+1,0) -> 41019.43 | S20: =HLOOKUP(S$5,[1]非R能力!$B$8:$F$558,$D20+1,0) -> 53989.178 | T20: =INDEX([1]非R能力!$H$9:$H$558,D20) -> 50514.428 | U20: =IF(INDEX([1]非R能力!$FK$9:$FK$558,D20)=0,0,10) -> 10 | V20: =IF(INDEX([1]非R能力!$FH$9:$FH$558,D20)=0,0,5000) -> 5000 | W20: =HLOOKUP(W$5,[2]人物技能基础!$O$3:$Q$553,$D20+1,0) -> 3.6371429 | X20: =HLOOKUP(X$5,[2]人物技能基础!$O$3:$Q$553,$D20+1,0) -> 2.0186429 | Y20: =HLOOKUP(Y$5,[2]人物技能基础!$O$3:$Q$553,$D20+1,0) -> 99.964286 | Z20: =INT(((P20-AB20)*X20+(Y20+T20))*G20*J20*$D$2) -> 8656883 | AA20: =IF(H20=0,IF(U20=0,INT(Q20/5),IF(V20=0,INT(Q20/5),INT((V20/U20)/(1/N20*M20)/L20+Q20))),INT((IF(U20=0,0,V20/U20/(1/N20*M20))+O20/H20)/L20+Q20)) -> 145056 | AB20: =INT(P20*I20) -> 25576 | AC20: =INT(K20*S20) -> 53989 | AD20: =INT(R20/J20) -> 58599
