Workbook

Sheet 等级经验
A1: 等级 | B1: 需完成关卡数 | C1: 关卡经验 | D1: 所需经验 | E1: 累计关卡数 | F1: 体力消耗 | G1: 累计消耗体力 | H1: 关卡时长（分） | I1: 小计时长（分） | J1: 总计（分） | K1: 总计（时）
A2: 1 | B2: 1 | C2: 500 | D2: =B2*C2 -> 500 | E2: =B2 -> 1 | F2: 6 | G2: =E2*F2 -> 6 | H2: 1 | J2: =SUM(I2:I121) -> 17829 | K2: =J2/60 -> 297.15
A3: 2 | B3: =B2 -> 1 | C3: =C2 -> 500 | D3: =B3*C3 -> 500 | E3: =B3+E2 -> 2 | F3: 6 | G3: =E3*F3 -> 12
A4: 3 | B4: =B3 -> 1 | C4: =C3 -> 500 | D4: =B4*C4 -> 500 | E4: =B4+E3 -> 3 | F4: 6 | G4: =E4*F4 -> 18
A5: 4 | B5: =B4 -> 1 | C5: =C4 -> 500 | D5: =B5*C5 -> 500 | E5: =B5+E4 -> 4 | F5: 6 | G5: =E5*F5 -> 24
A6: 5 | B6: 5 | C6: =C5 -> 500 | D6: =B6*C6 -> 2500 | E6: =B6+E5 -> 9 | F6: 6 | G6: =E6*F6 -> 54
A7: 6 | B7: =B6 -> 5 | C7: =C6 -> 500 | D7: =B7*C7 -> 2500 | E7: =B7+E6 -> 14 | F7: 6 | G7: =E7*F7 -> 84
A8: 7 | B8: =B7 -> 5 | C8: =C7 -> 500 | D8: =B8*C8 -> 2500 | E8: =B8+E7 -> 19 | F8: 6 | G8: =E8*F8 -> 114
A9: 8 | B9: =B8 -> 5 | C9: =C8 -> 500 | D9: =B9*C9 -> 2500 | E9: =B9+E8 -> 24 | F9: 6 | G9: =E9*F9 -> 144
A10: 9 | B10: =B9 -> 5 | C10: =C9 -> 500 | D10: =B10*C10 -> 2500 | E10: =B10+E9 -> 29 | F10: 6 | G10: =E10*F10 -> 174
A11: 10 | B11: 10 | C11: =C10 -> 500 | D11: =B11*C11 -> 5000 | E11: =B11+E10 -> 39 | F11: 6 | G11: =E11*F11 -> 234 | I11: =SUM(B2:B11)*H2 -> 39
A12: 11 | B12: =B11 -> 10 | C12: =C11 -> 500 | D12: =B12*C12 -> 5000 | E12: =B12+E11 -> 49 | F12: 6 | G12: =E12*F12 -> 294
A13: 12 | B13: =B12 -> 10 | C13: =C12 -> 500 | D13: =B13*C13 -> 5000 | E13: =B13+E12 -> 59 | F13: 6 | G13: =E13*F13 -> 354
A14: 13 | B14: =B13 -> 10 | C14: =C13 -> 500 | D14: =B14*C14 -> 5000 | E14: =B14+E13 -> 69 | F14: 6 | G14: =E14*F14 -> 414
A15: 14 | B15: =B14 -> 10 | C15: =C14 -> 500 | D15: =B15*C15 -> 5000 | E15: =B15+E14 -> 79 | F15: 6 | G15: =E15*F15 -> 474
A16: 15 | B16: 20 | C16: =C15 -> 500 | D16: =B16*C16 -> 10000 | E16: =B16+E15 -> 99 | F16: 6 | G16: =E16*F16 -> 594
A17: 16 | B17: =B16 -> 20 | C17: =C16 -> 500 | D17: =B17*C17 -> 10000 | E17: =B17+E16 -> 119 | F17: 6 | G17: =E17*F17 -> 714
A18: 17 | B18: =B17 -> 20 | C18: =C17 -> 500 | D18: =B18*C18 -> 10000 | E18: =B18+E17 -> 139 | F18: 6 | G18: =E18*F18 -> 834
A19: 18 | B19: =B18 -> 20 | C19: =C18 -> 500 | D19: =B19*C19 -> 10000 | E19: =B19+E18 -> 159 | F19: 6 | G19: =E19*F19 -> 954
A20: 19 | B20: =B19 -> 20 | C20: =C19 -> 500 | D20: =B20*C20 -> 10000 | E20: =B20+E19 -> 179 | F20: 6 | G20: =E20*F20 -> 1074
A21: 20 | B21: 30 | C21: =C20 -> 500 | D21: =B21*C21 -> 15000 | E21: =B21+E20 -> 209 | F21: 6 | G21: =E21*F21 -> 1254 | I21: =SUM(B12:B21)*H2 -> 170
A22: 21 | B22: =B21 -> 30 | C22: =C21 -> 500 | D22: =B22*C22 -> 15000 | E22: =B22+E21 -> 239 | F22: 6 | G22: =E22*F22 -> 1434
A23: 22 | B23: =B22 -> 30 | C23: =C22 -> 500 | D23: =B23*C23 -> 15000 | E23: =B23+E22 -> 269 | F23: 6 | G23: =E23*F23 -> 1614
A24: 23 | B24: =B23 -> 30 | C24: =C23 -> 500 | D24: =B24*C24 -> 15000 | E24: =B24+E23 -> 299 | F24: 6 | G24: =E24*F24 -> 1794
A25: 24 | B25: =B24 -> 30 | C25: =C24 -> 500 | D25: =B25*C25 -> 15000 | E25: =B25+E24 -> 329 | F25: 6 | G25: =E25*F25 -> 1974
A26: 25 | B26: =B25 -> 30 | C26: =C25 -> 500 | D26: =B26*C26 -> 15000 | E26: =B26+E25 -> 359 | F26: 6 | G26: =E26*F26 -> 2154
A27: 26 | B27: =B26 -> 30 | C27: =C26 -> 500 | D27: =B27*C27 -> 15000 | E27: =B27+E26 -> 389 | F27: 6 | G27: =E27*F27 -> 2334
A28: 27 | B28: =B27 -> 30 | C28: =C27 -> 500 | D28: =B28*C28 -> 15000 | E28: =B28+E27 -> 419 | F28: 6 | G28: =E28*F28 -> 2514
A29: 28 | B29: =B28 -> 30 | C29: =C28 -> 500 | D29: =B29*C29 -> 15000 | E29: =B29+E28 -> 449 | F29: 6 | G29: =E29*F29 -> 2694
A30: 29 | B30: =B29 -> 30 | C30: =C29 -> 500 | D30: =B30*C30 -> 15000 | E30: =B30+E29 -> 479 | F30: 6 | G30: =E30*F30 -> 2874
A31: 30 | B31: 50 | C31: =C30 -> 500 | D31: =B31*C31 -> 25000 | E31: =B31+E30 -> 529 | F31: 6 | G31: =E31*F31 -> 3174 | I31: =SUM(B22:B31)*H2 -> 320
A32: 31 | B32: =B31 -> 50 | C32: =C31 -> 500 | D32: =B32*C32 -> 25000 | E32: =B32+E31 -> 579 | F32: 6 | G32: =E32*F32 -> 3474
A33: 32 | B33: =B32 -> 50 | C33: =C32 -> 500 | D33: =B33*C33 -> 25000 | E33: =B33+E32 -> 629 | F33: 6 | G33: =E33*F33 -> 3774
A34: 33 | B34: =B33 -> 50 | C34: =C33 -> 500 | D34: =B34*C34 -> 25000 | E34: =B34+E33 -> 679 | F34: 6 | G34: =E34*F34 -> 4074
A35: 34 | B35: =B34 -> 50 | C35: =C34 -> 500 | D35: =B35*C35 -> 25000 | E35: =B35+E34 -> 729 | F35: 6 | G35: =E35*F35 -> 4374
A36: 35 | B36: =B35 -> 50 | C36: =C35 -> 500 | D36: =B36*C36 -> 25000 | E36: =B36+E35 -> 779 | F36: 6 | G36: =E36*F36 -> 4674
A37: 36 | B37: =B36 -> 50 | C37: =C36 -> 500 | D37: =B37*C37 -> 25000 | E37: =B37+E36 -> 829 | F37: 6 | G37: =E37*F37 -> 4974
A38: 37 | B38: =B37 -> 50 | C38: =C37 -> 500 | D38: =B38*C38 -> 25000 | E38: =B38+E37 -> 879 | F38: 6 | G38: =E38*F38 -> 5274
A39: 38 | B39: =B38 -> 50 | C39: =C38 -> 500 | D39: =B39*C39 -> 25000 | E39: =B39+E38 -> 929 | F39: 6 | G39: =E39*F39 -> 5574
A40: 39 | B40: =B39 -> 50 | C40: =C39 -> 500 | D40: =B40*C40 -> 25000 | E40: =B40+E39 -> 979 | F40: 6 | G40: =E40*F40 -> 5874
...

Sheet 等级经验-新
A1: 等级 | B1: 所需经验 | C1: 需完成关卡数 | D1: 关卡成长步长 | E1: 累计关卡次数 | F1: 累计消耗体力 | G1: 小计时长（分） | H1: 总计（分） | I1: 总计（时） | J1: 关卡经验 | K1: 关卡时长（分） | L1: 体力消耗
A2: 1 | B2: =C2*J2 -> 500 | C2: 1 | D2: 1 | E2: 1 | F2: =E2*L2 -> 6 | H2: =SUM(G2:G121) -> 19470 | I2: =H2/60 -> 324.5 | J2: 500 | K2: 1 | L2: 6
A3: 2 | B3: =C3*J3 -> 1000 | C3: =C2+D2 -> 2 | D3: =D2 -> 1 | E3: =C3+E2 -> 3 | F3: =E3*L3 -> 18 | J3: =J2 -> 500 | L3: 6
A4: 3 | B4: =C4*J4 -> 1500 | C4: =C3+D3 -> 3 | D4: =D3 -> 1 | E4: =C4+E3 -> 6 | F4: =E4*L4 -> 36 | J4: =J3 -> 500 | L4: 6
A5: 4 | B5: =C5*J5 -> 2000 | C5: =C4+D4 -> 4 | D5: =D4 -> 1 | E5: =C5+E4 -> 10 | F5: =E5*L5 -> 60 | J5: =J4 -> 500 | L5: 6
A6: 5 | B6: =C6*J6 -> 2500 | C6: =C5+D5 -> 5 | D6: =D5 -> 1 | E6: =C6+E5 -> 15 | F6: =E6*L6 -> 90 | J6: =J5 -> 500 | L6: 6
A7: 6 | B7: =C7*J7 -> 3000 | C7: =C6+D6 -> 6 | D7: =D6 -> 1 | E7: =C7+E6 -> 21 | F7: =E7*L7 -> 126 | J7: =J6 -> 500 | L7: 6
A8: 7 | B8: =C8*J8 -> 3500 | C8: =C7+D7 -> 7 | D8: =D7 -> 1 | E8: =C8+E7 -> 28 | F8: =E8*L8 -> 168 | J8: =J7 -> 500 | L8: 6
A9: 8 | B9: =C9*J9 -> 4000 | C9: =C8+D8 -> 8 | D9: =D8 -> 1 | E9: =C9+E8 -> 36 | F9: =E9*L9 -> 216 | J9: =J8 -> 500 | L9: 6
A10: 9 | B10: =C10*J10 -> 4500 | C10: =C9+D9 -> 9 | D10: =D9 -> 1 | E10: =C10+E9 -> 45 | F10: =E10*L10 -> 270 | J10: =J9 -> 500 | L10: 6
A11: 10 | B11: =C11*J11 -> 5000 | C11: =C10+D10 -> 10 | D11: 3 | E11: =C11+E10 -> 55 | F11: =E11*L11 -> 330 | G11: =SUM(C2:C11)*K2 -> 55 | J11: =J10 -> 500 | L11: 6
A12: 11 | B12: =C12*J12 -> 6500 | C12: =C11+D11 -> 13 | D12: =D11 -> 3 | E12: =C12+E11 -> 68 | F12: =E12*L12 -> 408 | J12: =J11 -> 500 | L12: 6
A13: 12 | B13: =C13*J13 -> 8000 | C13: =C12+D12 -> 16 | D13: =D12 -> 3 | E13: =C13+E12 -> 84 | F13: =E13*L13 -> 504 | J13: =J12 -> 500 | L13: 6
A14: 13 | B14: =C14*J14 -> 9500 | C14: =C13+D13 -> 19 | D14: =D13 -> 3 | E14: =C14+E13 -> 103 | F14: =E14*L14 -> 618 | J14: =J13 -> 500 | L14: 6
A15: 14 | B15: =C15*J15 -> 11000 | C15: =C14+D14 -> 22 | D15: =D14 -> 3 | E15: =C15+E14 -> 125 | F15: =E15*L15 -> 750 | J15: =J14 -> 500 | L15: 6
A16: 15 | B16: =C16*J16 -> 12500 | C16: =C15+D15 -> 25 | D16: =D15 -> 3 | E16: =C16+E15 -> 150 | F16: =E16*L16 -> 900 | J16: =J15 -> 500 | L16: 6
A17: 16 | B17: =C17*J17 -> 14000 | C17: =C16+D16 -> 28 | D17: =D16 -> 3 | E17: =C17+E16 -> 178 | F17: =E17*L17 -> 1068 | J17: =J16 -> 500 | L17: 6
A18: 17 | B18: =C18*J18 -> 15500 | C18: =C17+D17 -> 31 | D18: =D17 -> 3 | E18: =C18+E17 -> 209 | F18: =E18*L18 -> 1254 | J18: =J17 -> 500 | L18: 6
A19: 18 | B19: =C19*J19 -> 17000 | C19: =C18+D18 -> 34 | D19: =D18 -> 3 | E19: =C19+E18 -> 243 | F19: =E19*L19 -> 1458 | J19: =J18 -> 500 | L19: 6
A20: 19 | B20: =C20*J20 -> 18500 | C20: =C19+D19 -> 37 | D20: =D19 -> 3 | E20: =C20+E19 -> 280 | F20: =E20*L20 -> 1680 | J20: =J19 -> 500 | L20: 6
A21: 20 | B21: =C21*J21 -> 20000 | C21: =C20+D20 -> 40 | D21: =D20 -> 3 | E21: =C21+E20 -> 320 | F21: =E21*L21 -> 1920 | G21: =SUM(C12:C21)*K2 -> 265 | J21: =J20 -> 500 | L21: 6
A22: 21 | B22: =C22*J22 -> 21500 | C22: =C21+D21 -> 43 | D22: =D21 -> 3 | E22: =C22+E21 -> 363 | F22: =E22*L22 -> 2178 | J22: =J21 -> 500 | L22: 6
A23: 22 | B23: =C23*J23 -> 23000 | C23: =C22+D22 -> 46 | D23: =D22 -> 3 | E23: =C23+E22 -> 409 | F23: =E23*L23 -> 2454 | J23: =J22 -> 500 | L23: 6
A24: 23 | B24: =C24*J24 -> 24500 | C24: =C23+D23 -> 49 | D24: =D23 -> 3 | E24: =C24+E23 -> 458 | F24: =E24*L24 -> 2748 | J24: =J23 -> 500 | L24: 6
A25: 24 | B25: =C25*J25 -> 26000 | C25: =C24+D24 -> 52 | D25: =D24 -> 3 | E25: =C25+E24 -> 510 | F25: =E25*L25 -> 3060 | J25: =J24 -> 500 | L25: 6
A26: 25 | B26: =C26*J26 -> 27500 | C26: =C25+D25 -> 55 | D26: =D25 -> 3 | E26: =C26+E25 -> 565 | F26: =E26*L26 -> 3390 | J26: =J25 -> 500 | L26: 6
A27: 26 | B27: =C27*J27 -> 29000 | C27: =C26+D26 -> 58 | D27: =D26 -> 3 | E27: =C27+E26 -> 623 | F27: =E27*L27 -> 3738 | J27: =J26 -> 500 | L27: 6
A28: 27 | B28: =C28*J28 -> 30500 | C28: =C27+D27 -> 61 | D28: =D27 -> 3 | E28: =C28+E27 -> 684 | F28: =E28*L28 -> 4104 | J28: =J27 -> 500 | L28: 6
A29: 28 | B29: =C29*J29 -> 32000 | C29: =C28+D28 -> 64 | D29: =D28 -> 3 | E29: =C29+E28 -> 748 | F29: =E29*L29 -> 4488 | J29: =J28 -> 500 | L29: 6
A30: 29 | B30: =C30*J30 -> 33500 | C30: =C29+D29 -> 67 | D30: =D29 -> 3 | E30: =C30+E29 -> 815 | F30: =E30*L30 -> 4890 | J30: =J29 -> 500 | L30: 6
A31: 30 | B31: =C31*J31 -> 35000 | C31: =C30+D30 -> 70 | D31: =D30 -> 3 | E31: =C31+E30 -> 885 | F31: =E31*L31 -> 5310 | G31: =SUM(C22:C31)*K2 -> 565 | J31: =J30 -> 500 | L31: 6
A32: 31 | B32: =C32*J32 -> 36500 | C32: =C31+D31 -> 73 | D32: =D31 -> 3 | E32: =C32+E31 -> 958 | F32: =E32*L32 -> 5748 | J32: =J31 -> 500 | L32: 6
A33: 32 | B33: =C33*J33 -> 38000 | C33: =C32+D32 -> 76 | D33: =D32 -> 3 | E33: =C33+E32 -> 1034 | F33: =E33*L33 -> 6204 | J33: =J32 -> 500 | L33: 6
A34: 33 | B34: =C34*J34 -> 39500 | C34: =C33+D33 -> 79 | D34: =D33 -> 3 | E34: =C34+E33 -> 1113 | F34: =E34*L34 -> 6678 | J34: =J33 -> 500 | L34: 6
A35: 34 | B35: =C35*J35 -> 41000 | C35: =C34+D34 -> 82 | D35: =D34 -> 3 | E35: =C35+E34 -> 1195 | F35: =E35*L35 -> 7170 | J35: =J34 -> 500 | L35: 6
A36: 35 | B36: =C36*J36 -> 42500 | C36: =C35+D35 -> 85 | D36: =D35 -> 3 | E36: =C36+E35 -> 1280 | F36: =E36*L36 -> 7680 | J36: =J35 -> 500 | L36: 6
A37: 36 | B37: =C37*J37 -> 44000 | C37: =C36+D36 -> 88 | D37: =D36 -> 3 | E37: =C37+E36 -> 1368 | F37: =E37*L37 -> 8208 | J37: =J36 -> 500 | L37: 6
A38: 37 | B38: =C38*J38 -> 45500 | C38: =C37+D37 -> 91 | D38: =D37 -> 3 | E38: =C38+E37 -> 1459 | F38: =E38*L38 -> 8754 | J38: =J37 -> 500 | L38: 6
A39: 38 | B39: =C39*J39 -> 47000 | C39: =C38+D38 -> 94 | D39: =D38 -> 3 | E39: =C39+E38 -> 1553 | F39: =E39*L39 -> 9318 | J39: =J38 -> 500 | L39: 6
A40: 39 | B40: =C40*J40 -> 48500 | C40: =C39+D39 -> 97 | D40: =D39 -> 3 | E40: =C40+E39 -> 1650 | F40: =E40*L40 -> 9900 | J40: =J39 -> 500 | L40: 6
...

Sheet 攻击分赃比
B1: 武将分赃 | M1: 装备分赃 | AB1: 宝物分赃 | AL1: 战宠分赃 | AS1: 命星分赃
A2: 等级 | B2: 蓝 | C2: 紫 | D2: 橙 | E2: 红 | F2: 突破 | G2: 培养 | H2: 天命 | I2: 魂引 | J2: 觉醒 | K2: 缘份 | L2: 统计 | M2: 绿 | N2: 蓝 | O2: 紫 | P2: 橙 | Q2: 红 | R2: 精炼 | S2: 强化套 | T2: 精练套 | U2: 套装 | V2: 1星 | W2: 2星 | X2: 3星 | Y2: 4星 | Z2: 5星 | AA2: 统计 | AB2: 绿 | AC2: 蓝 | AD2: 紫 | AE2: 橙 | AF2: 红 | AG2: 精炼 | AH2: 强化套 | AI2: 精练套 | AJ2: 套装 | AK2: 统计 | AL2: 指数 | AM2: 1星 | AN2: 2星 | AO2: 3星 | AP2: 4星 | AQ2: 5星 | AR2: 统计 | AS2: 命星 | AT2: 总分赃值
A3: 1 | B3: 1.2 | C3: 1.5 | D3: 2 | E3: 2.5 | F3: 0.5 | G3: 0.3 | H3: 0.6 | I3: 0.3 | J3: 0.8 | K3: 1.2 | L3: =SUM(K3,J3,I3,H3,G3,F3,E3) -> 6.2 | M3: 1.5 | N3: 2 | O3: 2.5 | P3: 3 | Q3: 3.5 | R3: 0.75 | S3: 0.3 | T3: 0.3 | U3: 0.05 | V3: 0.2 | W3: 0.3 | X3: 0.5 | Y3: 0.8 | Z3: 1.2 | AA3: =Q3*(1+Z3)+R3+S3+T3+U3 -> 9.1 | AB3: 1 | AC3: 1.2 | AD3: 1.5 | AE3: 2 | AF3: 2.5 | AG3: 0.5 | AH3: 0.2 | AI3: 0.2 | AJ3: 0.03 | AK3: =AF3+AG3+AH3+AI3+AJ3 -> 3.43 | AL3: 1.2 | AM3: 0.2 | AN3: 0.3 | AO3: 0.5 | AP3: 0.8 | AQ3: 1.2 | AR3: =AL3*(1+AQ3) -> 2.64 | AS3: 0.2 | AT3: =SUM(L3,AA3,AK3,AR3,AS3) -> 21.57
A4: 2 | B4: =B3 -> 1.2 | C4: =C3 -> 1.5 | D4: =D3 -> 2 | E4: =E3 -> 2.5 | F4: =F3 -> 0.5 | G4: =G3 -> 0.3 | H4: =H3 -> 0.6 | I4: =I3 -> 0.3 | ... K4: =K3 -> 1.2 | M4: =M3 -> 1.5 | N4: =N3 -> 2 | O4: =O3 -> 2.5 | P4: =P3 -> 3 | Q4: =Q3 -> 3.5 | R4: =R3 -> 0.75 | S4: =S3 -> 0.3 | T4: =T3 -> 0.3 | ... Z4: =Z3 -> 1.2 | AB4: =AB3 -> 1 | AC4: =AC3 -> 1.2 | AD4: =AD3 -> 1.5 | AE4: =AE3 -> 2 | AF4: =AF3 -> 2.5 | AG4: =AG3 -> 0.5 | AH4: =AH3 -> 0.2 | AI4: =AI3 -> 0.2 | AJ4: =AJ3 -> 0.03 | AL4: =AL3 -> 1.2 | AM4: =AM3 -> 0.2 | AN4: =AN3 -> 0.3 | AO4: =AO3 -> 0.5 | AP4: =AP3 -> 0.8 | AQ4: =AQ3 -> 1.2 | AS4: =AS3 -> 0.2
A5: 3 | B5: =B4 -> 1.2 | C5: =C4 -> 1.5 | D5: =D4 -> 2 | E5: =E4 -> 2.5 | F5: =F4 -> 0.5 | G5: =G4 -> 0.3 | H5: =H4 -> 0.6 | I5: =I4 -> 0.3 | ... K5: =K4 -> 1.2 | M5: =M4 -> 1.5 | N5: =N4 -> 2 | O5: =O4 -> 2.5 | P5: =P4 -> 3 | Q5: =Q4 -> 3.5 | R5: =R4 -> 0.75 | S5: =S4 -> 0.3 | T5: =T4 -> 0.3 | ... Z5: =Z4 -> 1.2 | AB5: =AB4 -> 1 | AC5: =AC4 -> 1.2 | AD5: =AD4 -> 1.5 | AE5: =AE4 -> 2 | AF5: =AF4 -> 2.5 | AG5: =AG4 -> 0.5 | AH5: =AH4 -> 0.2 | AI5: =AI4 -> 0.2 | AJ5: =AJ4 -> 0.03 | AL5: =AL4 -> 1.2 | AM5: =AM4 -> 0.2 | AN5: =AN4 -> 0.3 | AO5: =AO4 -> 0.5 | AP5: =AP4 -> 0.8 | AQ5: =AQ4 -> 1.2 | AS5: =AS4 -> 0.2
A6: 4 | B6: =B5 -> 1.2 | C6: =C5 -> 1.5 | D6: =D5 -> 2 | E6: =E5 -> 2.5 | F6: =F5 -> 0.5 | G6: =G5 -> 0.3 | H6: =H5 -> 0.6 | I6: =I5 -> 0.3 | ... K6: =K5 -> 1.2 | M6: =M5 -> 1.5 | N6: =N5 -> 2 | O6: =O5 -> 2.5 | P6: =P5 -> 3 | Q6: =Q5 -> 3.5 | R6: =R5 -> 0.75 | S6: =S5 -> 0.3 | T6: =T5 -> 0.3 | ... Z6: =Z5 -> 1.2 | AB6: =AB5 -> 1 | AC6: =AC5 -> 1.2 | AD6: =AD5 -> 1.5 | AE6: =AE5 -> 2 | AF6: =AF5 -> 2.5 | AG6: =AG5 -> 0.5 | AH6: =AH5 -> 0.2 | AI6: =AI5 -> 0.2 | AJ6: =AJ5 -> 0.03 | AL6: =AL5 -> 1.2 | AM6: =AM5 -> 0.2 | AN6: =AN5 -> 0.3 | AO6: =AO5 -> 0.5 | AP6: =AP5 -> 0.8 | AQ6: =AQ5 -> 1.2 | AS6: =AS5 -> 0.2
A7: 5 | B7: =B6 -> 1.2 | C7: =C6 -> 1.5 | D7: =D6 -> 2 | E7: =E6 -> 2.5 | F7: =F6 -> 0.5 | G7: =G6 -> 0.3 | H7: =H6 -> 0.6 | I7: =I6 -> 0.3 | ... K7: =K6 -> 1.2 | M7: =M6 -> 1.5 | N7: =N6 -> 2 | O7: =O6 -> 2.5 | P7: =P6 -> 3 | Q7: =Q6 -> 3.5 | R7: =R6 -> 0.75 | S7: =S6 -> 0.3 | T7: =T6 -> 0.3 | ... Z7: =Z6 -> 1.2 | AB7: =AB6 -> 1 | AC7: =AC6 -> 1.2 | AD7: =AD6 -> 1.5 | AE7: =AE6 -> 2 | AF7: =AF6 -> 2.5 | AG7: =AG6 -> 0.5 | AH7: =AH6 -> 0.2 | AI7: =AI6 -> 0.2 | AJ7: =AJ6 -> 0.03 | AL7: =AL6 -> 1.2 | AM7: =AM6 -> 0.2 | AN7: =AN6 -> 0.3 | AO7: =AO6 -> 0.5 | AP7: =AP6 -> 0.8 | AQ7: =AQ6 -> 1.2 | AS7: =AS6 -> 0.2
A8: 6 | B8: =B7 -> 1.2 | C8: =C7 -> 1.5 | D8: =D7 -> 2 | E8: =E7 -> 2.5 | F8: =F7 -> 0.5 | G8: =G7 -> 0.3 | H8: =H7 -> 0.6 | I8: =I7 -> 0.3 | ... K8: =K7 -> 1.2 | M8: =M7 -> 1.5 | N8: =N7 -> 2 | O8: =O7 -> 2.5 | P8: =P7 -> 3 | Q8: =Q7 -> 3.5 | R8: =R7 -> 0.75 | S8: =S7 -> 0.3 | T8: =T7 -> 0.3 | ... Z8: =Z7 -> 1.2 | AB8: =AB7 -> 1 | AC8: =AC7 -> 1.2 | AD8: =AD7 -> 1.5 | AE8: =AE7 -> 2 | AF8: =AF7 -> 2.5 | AG8: =AG7 -> 0.5 | AH8: =AH7 -> 0.2 | AI8: =AI7 -> 0.2 | AJ8: =AJ7 -> 0.03 | AL8: =AL7 -> 1.2 | AM8: =AM7 -> 0.2 | AN8: =AN7 -> 0.3 | AO8: =AO7 -> 0.5 | AP8: =AP7 -> 0.8 | AQ8: =AQ7 -> 1.2 | AS8: =AS7 -> 0.2
A9: 7 | B9: =B8 -> 1.2 | C9: =C8 -> 1.5 | D9: =D8 -> 2 | E9: =E8 -> 2.5 | F9: =F8 -> 0.5 | G9: =G8 -> 0.3 | H9: =H8 -> 0.6 | I9: =I8 -> 0.3 | ... K9: =K8 -> 1.2 | M9: =M8 -> 1.5 | N9: =N8 -> 2 | O9: =O8 -> 2.5 | P9: =P8 -> 3 | Q9: =Q8 -> 3.5 | R9: =R8 -> 0.75 | S9: =S8 -> 0.3 | T9: =T8 -> 0.3 | ... Z9: =Z8 -> 1.2 | AB9: =AB8 -> 1 | AC9: =AC8 -> 1.2 | AD9: =AD8 -> 1.5 | AE9: =AE8 -> 2 | AF9: =AF8 -> 2.5 | AG9: =AG8 -> 0.5 | AH9: =AH8 -> 0.2 | AI9: =AI8 -> 0.2 | AJ9: =AJ8 -> 0.03 | AL9: =AL8 -> 1.2 | AM9: =AM8 -> 0.2 | AN9: =AN8 -> 0.3 | AO9: =AO8 -> 0.5 | AP9: =AP8 -> 0.8 | AQ9: =AQ8 -> 1.2 | AS9: =AS8 -> 0.2
A10: 8 | B10: =B9 -> 1.2 | C10: =C9 -> 1.5 | D10: =D9 -> 2 | E10: =E9 -> 2.5 | F10: =F9 -> 0.5 | G10: =G9 -> 0.3 | H10: =H9 -> 0.6 | I10: =I9 -> 0.3 | ... K10: =K9 -> 1.2 | M10: =M9 -> 1.5 | N10: =N9 -> 2 | O10: =O9 -> 2.5 | P10: =P9 -> 3 | Q10: =Q9 -> 3.5 | R10: =R9 -> 0.75 | S10: =S9 -> 0.3 | T10: =T9 -> 0.3 | ... Z10: =Z9 -> 1.2 | AB10: =AB9 -> 1 | AC10: =AC9 -> 1.2 | AD10: =AD9 -> 1.5 | AE10: =AE9 -> 2 | AF10: =AF9 -> 2.5 | AG10: =AG9 -> 0.5 | AH10: =AH9 -> 0.2 | AI10: =AI9 -> 0.2 | AJ10: =AJ9 -> 0.03 | AL10: =AL9 -> 1.2 | AM10: =AM9 -> 0.2 | AN10: =AN9 -> 0.3 | AO10: =AO9 -> 0.5 | AP10: =AP9 -> 0.8 | AQ10: =AQ9 -> 1.2 | AS10: =AS9 -> 0.2
A11: 9 | B11: =B10 -> 1.2 | C11: =C10 -> 1.5 | D11: =D10 -> 2 | E11: =E10 -> 2.5 | F11: =F10 -> 0.5 | G11: =G10 -> 0.3 | H11: =H10 -> 0.6 | I11: =I10 -> 0.3 | ... K11: =K10 -> 1.2 | M11: =M10 -> 1.5 | N11: =N10 -> 2 | O11: =O10 -> 2.5 | P11: =P10 -> 3 | Q11: =Q10 -> 3.5 | R11: =R10 -> 0.75 | S11: =S10 -> 0.3 | T11: =T10 -> 0.3 | ... Z11: =Z10 -> 1.2 | AB11: =AB10 -> 1 | AC11: =AC10 -> 1.2 | AD11: =AD10 -> 1.5 | AE11: =AE10 -> 2 | AF11: =AF10 -> 2.5 | AG11: =AG10 -> 0.5 | AH11: =AH10 -> 0.2 | AI11: =AI10 -> 0.2 | AJ11: =AJ10 -> 0.03 | AL11: =AL10 -> 1.2 | AM11: =AM10 -> 0.2 | AN11: =AN10 -> 0.3 | AO11: =AO10 -> 0.5 | AP11: =AP10 -> 0.8 | AQ11: =AQ10 -> 1.2 | AS11: =AS10 -> 0.2
A12: 10 | B12: =B11 -> 1.2 | C12: =C11 -> 1.5 | D12: =D11 -> 2 | E12: =E11 -> 2.5 | F12: =F11 -> 0.5 | G12: =G11 -> 0.3 | H12: =H11 -> 0.6 | I12: =I11 -> 0.3 | ... K12: =K11 -> 1.2 | M12: =M11 -> 1.5 | N12: =N11 -> 2 | O12: =O11 -> 2.5 | P12: =P11 -> 3 | Q12: =Q11 -> 3.5 | R12: =R11 -> 0.75 | S12: =S11 -> 0.3 | T12: =T11 -> 0.3 | ... Z12: =Z11 -> 1.2 | AB12: =AB11 -> 1 | AC12: =AC11 -> 1.2 | AD12: =AD11 -> 1.5 | AE12: =AE11 -> 2 | AF12: =AF11 -> 2.5 | AG12: =AG11 -> 0.5 | AH12: =AH11 -> 0.2 | AI12: =AI11 -> 0.2 | AJ12: =AJ11 -> 0.03 | AL12: =AL11 -> 1.2 | AM12: =AM11 -> 0.2 | AN12: =AN11 -> 0.3 | AO12: =AO11 -> 0.5 | AP12: =AP11 -> 0.8 | AQ12: =AQ11 -> 1.2 | AS12: =AS11 -> 0.2
A13: 11 | B13: =B12 -> 1.2 | C13: =C12 -> 1.5 | D13: =D12 -> 2 | E13: =E12 -> 2.5 | F13: =F12 -> 0.5 | G13: =G12 -> 0.3 | H13: =H12 -> 0.6 | I13: =I12 -> 0.3 | ... K13: =K12 -> 1.2 | M13: =M12 -> 1.5 | N13: =N12 -> 2 | O13: =O12 -> 2.5 | P13: =P12 -> 3 | Q13: =Q12 -> 3.5 | R13: =R12 -> 0.75 | S13: =S12 -> 0.3 | T13: =T12 -> 0.3 | ... Z13: =Z12 -> 1.2 | AB13: =AB12 -> 1 | AC13: =AC12 -> 1.2 | AD13: =AD12 -> 1.5 | AE13: =AE12 -> 2 | AF13: =AF12 -> 2.5 | AG13: =AG12 -> 0.5 | AH13: =AH12 -> 0.2 | AI13: =AI12 -> 0.2 | AJ13: =AJ12 -> 0.03 | AL13: =AL12 -> 1.2 | AM13: =AM12 -> 0.2 | AN13: =AN12 -> 0.3 | AO13: =AO12 -> 0.5 | AP13: =AP12 -> 0.8 | AQ13: =AQ12 -> 1.2 | AS13: =AS12 -> 0.2
A14: 12 | B14: =B13 -> 1.2 | C14: =C13 -> 1.5 | D14: =D13 -> 2 | E14: =E13 -> 2.5 | F14: =F13 -> 0.5 | G14: =G13 -> 0.3 | H14: =H13 -> 0.6 | I14: =I13 -> 0.3 | ... K14: =K13 -> 1.2 | M14: =M13 -> 1.5 | N14: =N13 -> 2 | O14: =O13 -> 2.5 | P14: =P13 -> 3 | Q14: =Q13 -> 3.5 | R14: =R13 -> 0.75 | S14: =S13 -> 0.3 | T14: =T13 -> 0.3 | ... Z14: =Z13 -> 1.2 | AB14: =AB13 -> 1 | AC14: =AC13 -> 1.2 | AD14: =AD13 -> 1.5 | AE14: =AE13 -> 2 | AF14: =AF13 -> 2.5 | AG14: =AG13 -> 0.5 | AH14: =AH13 -> 0.2 | AI14: =AI13 -> 0.2 | AJ14: =AJ13 -> 0.03 | AL14: =AL13 -> 1.2 | AM14: =AM13 -> 0.2 | AN14: =AN13 -> 0.3 | AO14: =AO13 -> 0.5 | AP14: =AP13 -> 0.8 | AQ14: =AQ13 -> 1.2 | AS14: =AS13 -> 0.2
A15: 13 | B15: =B14 -> 1.2 | C15: =C14 -> 1.5 | D15: =D14 -> 2 | E15: =E14 -> 2.5 | F15: =F14 -> 0.5 | G15: =G14 -> 0.3 | H15: =H14 -> 0.6 | I15: =I14 -> 0.3 | ... K15: =K14 -> 1.2 | M15: =M14 -> 1.5 | N15: =N14 -> 2 | O15: =O14 -> 2.5 | P15: =P14 -> 3 | Q15: =Q14 -> 3.5 | R15: =R14 -> 0.75 | S15: =S14 -> 0.3 | T15: =T14 -> 0.3 | ... Z15: =Z14 -> 1.2 | AB15: =AB14 -> 1 | AC15: =AC14 -> 1.2 | AD15: =AD14 -> 1.5 | AE15: =AE14 -> 2 | AF15: =AF14 -> 2.5 | AG15: =AG14 -> 0.5 | AH15: =AH14 -> 0.2 | AI15: =AI14 -> 0.2 | AJ15: =AJ14 -> 0.03 | AL15: =AL14 -> 1.2 | AM15: =AM14 -> 0.2 | AN15: =AN14 -> 0.3 | AO15: =AO14 -> 0.5 | AP15: =AP14 -> 0.8 | AQ15: =AQ14 -> 1.2 | AS15: =AS14 -> 0.2
... A122: 120 | B122: =B121 -> 1.2 | C122: =C121 -> 1.5 | D122: =D121 -> 2 | E122: =E121 -> 2.5 | F122: =F121 -> 0.5 | G122: =G121 -> 0.3 | H122: =H121 -> 0.6 | I122: =I121 -> 0.3 | ... K122: =K121 -> 1.2 | M122: =M121 -> 1.5 | N122: =N121 -> 2 | O122: =O121 -> 2.5 | P122: =P121 -> 3 | Q122: =Q121 -> 3.5 | R122: =R121 -> 0.75 | S122: =S121 -> 0.3 | T122: =T121 -> 0.3 | ... Z122: =Z121 -> 1.2 | AB122: =AB121 -> 1 | AC122: =AC121 -> 1.2 | AD122: =AD121 -> 1.5 | AE122: =AE121 -> 2 | AF122: =AF121 -> 2.5 | AG122: =AG121 -> 0.5 | AH122: =AH121 -> 0.2 | AI122: =AI121 -> 0.2 | AJ122: =AJ121 -> 0.03 | AL122: =AL121 -> 1.2 | AM122: =AM121 -> 0.2 | AN122: =AN121 -> 0.3 | AO122: =AO121 -> 0.5 | AP122: =AP121 -> 0.8 | AQ122: =AQ121 -> 1.2 | AS122: =AS121 -> 0.2

Sheet 攻击
B1: 武将 | O1: 装备 | AC1: 宝物 | AL1: 战宠 | AR1: 命星
A2: 等级 | B2: 基本值 | C2: 例子 | D2: 绿 | E2: 蓝 | F2: 紫 | G2: 橙 | H2: 红 | I2: 突破 | J2: 培养 | K2: 天命 | L2: 魂引 | M2: 觉醒 | N2: 缘份 | O2: 绿 | P2: 蓝 | Q2: 紫 | R2: 橙 | S2: 红 | T2: 精炼 | U2: 强化套 | V2: 精练套 | W2: 套装 | X2: 1星 | Y2: 2星 | Z2: 3星 | AA2: 4星 | AB2: 5星 | AC2: 绿 | AD2: 蓝 | AE2: 紫 | AF2: 橙 | AG2: 红 | AH2: 精炼 | AI2: 强化套 | AJ2: 精练套 | AK2: 套装 | AL2: 升级 | AM2: 1星 | AN2: 2星 | AO2: 3星 | AP2: 4星 | AQ2: 5星 | AR2: 命星 | AS2: 最低攻击 | AT2: 最高攻击 | AW2: 武将统计 | AX2: 装备统计 | AY2: 宝物统计 | AZ2: 战宠统计 | BA2: 命星统计 | BB2: 最高攻击比
A3: 1 | B3: 10 | C3: 10 | D3: =B3 -> 10 | E3: =$D3*攻击分赃比!B3*开放指数!B3 -> 12 | F3: =$D3*攻击分赃比!C3*开放指数!C3 -> 15 | G3: =$D3*攻击分赃比!D3*开放指数!D3 -> 20 | H3: =$D3*攻击分赃比!E3*开放指数!E3 -> 25 | I3: =$D3*攻击分赃比!F3*开放指数!F3 -> 0 | J3: =$D3*攻击分赃比!G3*开放指数!G3 -> 0 | K3: =$D3*攻击分赃比!H3*开放指数!H3 -> 0 | L3: =$D3*攻击分赃比!I3*开放指数!I3 -> 0 | ... N3: =$D3*攻击分赃比!K3*开放指数!K3 -> 12 | O3: =$D3*攻击分赃比!M3*开放指数!L3 -> 15 | P3: =$D3*攻击分赃比!N3*开放指数!M3 -> 20 | Q3: =$D3*攻击分赃比!O3*开放指数!N3 -> 25 | R3: =$D3*攻击分赃比!P3*开放指数!O3 -> 30 | S3: =$D3*攻击分赃比!Q3*开放指数!P3 -> 35 | T3: =$D3*攻击分赃比!R3*开放指数!Q3 -> 0 | U3: =$D3*攻击分赃比!S3*开放指数!R3 -> 3 | V3: =$D3*攻击分赃比!T3*开放指数!S3 -> 0 | W3: =$D3*攻击分赃比!U3*开放指数!T3 -> 0.5 | X3: =攻击分赃比!V3*开放指数!U3 -> 0 | Y3: =攻击分赃比!W3*开放指数!V3 -> 0 | Z3: =攻击分赃比!X3*开放指数!W3 -> 0 | AA3: =攻击分赃比!Y3*开放指数!X3 -> 0 | AB3: =攻击分赃比!Z3*开放指数!Y3 -> 0 | AC3: =$D3*攻击分赃比!AB3*开放指数!Z3 -> 0 | AD3: =$D3*攻击分赃比!AC3*开放指数!AA3 -> 0 | AE3: =$D3*攻击分赃比!AD3*开放指数!AB3 -> 0 | AF3: =$D3*攻击分赃比!AE3*开放指数!AC3 -> 0 | AG3: =$D3*攻击分赃比!AF3*开放指数!AD3 -> 0 | AH3: =$D3*攻击分赃比!AG3*开放指数!AE3 -> 0 | AI3: =$D3*攻击分赃比!AH3*开放指数!AF3 -> 0 | AJ3: =$D3*攻击分赃比!AI3*开放指数!AG3 -> 0 | AK3: =$D3*攻击分赃比!AJ3*开放指数!AH3 -> 0 | AL3: =$D3*攻击分赃比!AL3*开放指数!AI3 -> 0 | AM3: =攻击分赃比!AM3*开放指数!AJ3 -> 0 | AN3: =攻击分赃比!AN3*开放指数!AK3 -> 0 | AO3: =攻击分赃比!AO3*开放指数!AL3 -> 0 | AP3: =攻击分赃比!AP3*开放指数!AM3 -> 0 | AQ3: =攻击分赃比!AQ3*开放指数!AN3 -> 0 | AR3: =$D3*攻击分赃比!AS3*开放指数!AO3 -> 2 | AS3: =D3+O3+AR3+AL3+AC3 -> 27 | AT3: =H3+I3+J3+K3+L3+M3+N3+S3*(1+AB3)+T3+U3+V3+W3+AG3+AH3+AI3+AJ3+AK3+AL3*(1+AQ3)+AR3 -> 77.5 | AW3: =H3+I3+J3+K3+L3+M3+N3 -> 37 | AX3: =S3*(1+AB3)+T3+U3+V3+W3 -> 38.5 | AY3: =AG3+AH3+AI3+AJ3+AK3 -> 0 | AZ3: =AL3*(1+AQ3) -> 0 | BA3: =AR3 -> 2 | BB3: =AT3/D3 -> 7.75
A4: 2 | B4: 2 | C4: =C3+B4 -> 12 | D4: =B4+D3 -> 12 | E4: =$D4*攻击分赃比!B4*开放指数!B4 -> 14.4 | F4: =$D4*攻击分赃比!C4*开放指数!C4 -> 18 | G4: =$D4*攻击分赃比!D4*开放指数!D4 -> 24 | H4: =$D4*攻击分赃比!E4*开放指数!E4 -> 30 | I4: =$D4*攻击分赃比!F4*开放指数!F4 -> 0 | J4: =$D4*攻击分赃比!G4*开放指数!G4 -> 0 | K4: =$D4*攻击分赃比!H4*开放指数!H4 -> 0 | L4: =$D4*攻击分赃比!I4*开放指数!I4 -> 0 | ... N4: =$D4*攻击分赃比!K4*开放指数!K4 -> 14.4 | O4: =$D4*攻击分赃比!M4*开放指数!L4 -> 18 | P4: =$D4*攻击分赃比!N4*开放指数!M4 -> 24 | Q4: =$D4*攻击分赃比!O4*开放指数!N4 -> 30 | R4: =$D4*攻击分赃比!P4*开放指数!O4 -> 36 | S4: =$D4*攻击分赃比!Q4*开放指数!P4 -> 42 | T4: =$D4*攻击分赃比!R4*开放指数!Q4 -> 0 | U4: =$D4*攻击分赃比!S4*开放指数!R4 -> 3.6 | V4: =$D4*攻击分赃比!T4*开放指数!S4 -> 0 | W4: =$D4*攻击分赃比!U4*开放指数!T4 -> 0.6 | X4: =攻击分赃比!V4*开放指数!U4 -> 0 | Y4: =攻击分赃比!W4*开放指数!V4 -> 0 | Z4: =攻击分赃比!X4*开放指数!W4 -> 0 | AA4: =攻击分赃比!Y4*开放指数!X4 -> 0 | AB4: =攻击分赃比!Z4*开放指数!Y4 -> 0 | AC4: =$D4*攻击分赃比!AB4*开放指数!Z4 -> 0 | AD4: =$D4*攻击分赃比!AC4*开放指数!AA4 -> 0 | AE4: =$D4*攻击分赃比!AD4*开放指数!AB4 -> 0 | AF4: =$D4*攻击分赃比!AE4*开放指数!AC4 -> 0 | AG4: =$D4*攻击分赃比!AF4*开放指数!AD4 -> 0 | AH4: =$D4*攻击分赃比!AG4*开放指数!AE4 -> 0 | AI4: =$D4*攻击分赃比!AH4*开放指数!AF4 -> 0 | AJ4: =$D4*攻击分赃比!AI4*开放指数!AG4 -> 0 | AK4: =$D4*攻击分赃比!AJ4*开放指数!AH4 -> 0 | AL4: =$D4*攻击分赃比!AL4*开放指数!AI4 -> 0 | AM4: =攻击分赃比!AM4*开放指数!AJ4 -> 0 | AN4: =攻击分赃比!AN4*开放指数!AK4 -> 0 | AO4: =攻击分赃比!AO4*开放指数!AL4 -> 0 | AP4: =攻击分赃比!AP4*开放指数!AM4 -> 0 | AQ4: =攻击分赃比!AQ4*开放指数!AN4 -> 0 | AR4: =$D4*攻击分赃比!AS4*开放指数!AO4 -> 2.4 | AS4: =D4+O4+AR4+AL4+AC4 -> 32.4 | AT4: =H4+I4+J4+K4+L4+M4+N4+S4*(1+AB4)+T4+U4+V4+W4+AG4+AH4+AI4+AJ4+AK4+AL4*(1+AQ4)+AR4 -> 93 | AW4: =H4+I4+J4+K4+L4+M4+N4 -> 44.4 | AX4: =S4*(1+AB4)+T4+U4+V4+W4 -> 46.2 | AY4: =AG4+AH4+AI4+AJ4+AK4 -> 0 | AZ4: =AL4*(1+AQ4) -> 0 | BA4: =AR4 -> 2.4 | BB4: =AT4/D4 -> 7.75
A5: 3 | B5: =B4 -> 2 | C5: =C4+B5 -> 14 | D5: =B5+D4 -> 14 | E5: =$D5*攻击分赃比!B5*开放指数!B5 -> 16.8 | F5: =$D5*攻击分赃比!C5*开放指数!C5 -> 21 | G5: =$D5*攻击分赃比!D5*开放指数!D5 -> 28 | H5: =$D5*攻击分赃比!E5*开放指数!E5 -> 35 | I5: =$D5*攻击分赃比!F5*开放指数!F5 -> 0 | J5: =$D5*攻击分赃比!G5*开放指数!G5 -> 0 | K5: =$D5*攻击分赃比!H5*开放指数!H5 -> 0 | L5: =$D5*攻击分赃比!I5*开放指数!I5 -> 0 | ... N5: =$D5*攻击分赃比!K5*开放指数!K5 -> 16.8 | O5: =$D5*攻击分赃比!M5*开放指数!L5 -> 21 | P5: =$D5*攻击分赃比!N5*开放指数!M5 -> 28 | Q5: =$D5*攻击分赃比!O5*开放指数!N5 -> 35 | R5: =$D5*攻击分赃比!P5*开放指数!O5 -> 42 | S5: =$D5*攻击分赃比!Q5*开放指数!P5 -> 49 | T5: =$D5*攻击分赃比!R5*开放指数!Q5 -> 0 | U5: =$D5*攻击分赃比!S5*开放指数!R5 -> 4.2 | V5: =$D5*攻击分赃比!T5*开放指数!S5 -> 0 | W5: =$D5*攻击分赃比!U5*开放指数!T5 -> 0.7 | X5: =攻击分赃比!V5*开放指数!U5 -> 0 | Y5: =攻击分赃比!W5*开放指数!V5 -> 0 | Z5: =攻击分赃比!X5*开放指数!W5 -> 0 | AA5: =攻击分赃比!Y5*开放指数!X5 -> 0 | AB5: =攻击分赃比!Z5*开放指数!Y5 -> 0 | AC5: =$D5*攻击分赃比!AB5*开放指数!Z5 -> 0 | AD5: =$D5*攻击分赃比!AC5*开放指数!AA5 -> 0 | AE5: =$D5*攻击分赃比!AD5*开放指数!AB5 -> 0 | AF5: =$D5*攻击分赃比!AE5*开放指数!AC5 -> 0 | AG5: =$D5*攻击分赃比!AF5*开放指数!AD5 -> 0 | AH5: =$D5*攻击分赃比!AG5*开放指数!AE5 -> 0 | AI5: =$D5*攻击分赃比!AH5*开放指数!AF5 -> 0 | AJ5: =$D5*攻击分赃比!AI5*开放指数!AG5 -> 0 | AK5: =$D5*攻击分赃比!AJ5*开放指数!AH5 -> 0 | AL5: =$D5*攻击分赃比!AL5*开放指数!AI5 -> 0 | AM5: =攻击分赃比!AM5*开放指数!AJ5 -> 0 | AN5: =攻击分赃比!AN5*开放指数!AK5 -> 0 | AO5: =攻击分赃比!AO5*开放指数!AL5 -> 0 | AP5: =攻击分赃比!AP5*开放指数!AM5 -> 0 | AQ5: =攻击分赃比!AQ5*开放指数!AN5 -> 0 | AR5: =$D5*攻击分赃比!AS5*开放指数!AO5 -> 2.8 | AS5: =D5+O5+AR5+AL5+AC5 -> 37.8 | AT5: =H5+I5+J5+K5+L5+M5+N5+S5*(1+AB5)+T5+U5+V5+W5+AG5+AH5+AI5+AJ5+AK5+AL5*(1+AQ5)+AR5 -> 108.5 | AW5: =H5+I5+J5+K5+L5+M5+N5 -> 51.8 | AX5: =S5*(1+AB5)+T5+U5+V5+W5 -> 53.9 | AY5: =AG5+AH5+AI5+AJ5+AK5 -> 0 | AZ5: =AL5*(1+AQ5) -> 0 | BA5: =AR5 -> 2.8 | BB5: =AT5/D5 -> 7.75
A6: 4 | B6: =B5 -> 2 | C6: =C5+B6 -> 16 | D6: =B6+D5 -> 16 | E6: =$D6*攻击分赃比!B6*开放指数!B6 -> 19.2 | F6: =$D6*攻击分赃比!C6*开放指数!C6 -> 24 | G6: =$D6*攻击分赃比!D6*开放指数!D6 -> 32 | H6: =$D6*攻击分赃比!E6*开放指数!E6 -> 40 | I6: =$D6*攻击分赃比!F6*开放指数!F6 -> 0 | J6: =$D6*攻击分赃比!G6*开放指数!G6 -> 0 | K6: =$D6*攻击分赃比!H6*开放指数!H6 -> 0 | L6: =$D6*攻击分赃比!I6*开放指数!I6 -> 0 | ... N6: =$D6*攻击分赃比!K6*开放指数!K6 -> 19.2 | O6: =$D6*攻击分赃比!M6*开放指数!L6 -> 24 | P6: =$D6*攻击分赃比!N6*开放指数!M6 -> 32 | Q6: =$D6*攻击分赃比!O6*开放指数!N6 -> 40 | R6: =$D6*攻击分赃比!P6*开放指数!O6 -> 48 | S6: =$D6*攻击分赃比!Q6*开放指数!P6 -> 56 | T6: =$D6*攻击分赃比!R6*开放指数!Q6 -> 0 | U6: =$D6*攻击分赃比!S6*开放指数!R6 -> 4.8 | V6: =$D6*攻击分赃比!T6*开放指数!S6 -> 0 | W6: =$D6*攻击分赃比!U6*开放指数!T6 -> 0.8 | X6: =攻击分赃比!V6*开放指数!U6 -> 0 | Y6: =攻击分赃比!W6*开放指数!V6 -> 0 | Z6: =攻击分赃比!X6*开放指数!W6 -> 0 | AA6: =攻击分赃比!Y6*开放指数!X6 -> 0 | AB6: =攻击分赃比!Z6*开放指数!Y6 -> 0 | AC6: =$D6*攻击分赃比!AB6*开放指数!Z6 -> 0 | AD6: =$D6*攻击分赃比!AC6*开放指数!AA6 -> 0 | AE6: =$D6*攻击分赃比!AD6*开放指数!AB6 -> 0 | AF6: =$D6*攻击分赃比!AE6*开放指数!AC6 -> 0 | AG6: =$D6*攻击分赃比!AF6*开放指数!AD6 -> 0 | AH6: =$D6*攻击分赃比!AG6*开放指数!AE6 -> 0 | AI6: =$D6*攻击分赃比!AH6*开放指数!AF6 -> 0 | AJ6: =$D6*攻击分赃比!AI6*开放指数!AG6 -> 0 | AK6: =$D6*攻击分赃比!AJ6*开放指数!AH6 -> 0 | AL6: =$D6*攻击分赃比!AL6*开放指数!AI6 -> 0 | AM6: =攻击分赃比!AM6*开放指数!AJ6 -> 0 | AN6: =攻击分赃比!AN6*开放指数!AK6 -> 0 | AO6: =攻击分赃比!AO6*开放指数!AL6 -> 0 | AP6: =攻击分赃比!AP6*开放指数!AM6 -> 0 | AQ6: =攻击分赃比!AQ6*开放指数!AN6 -> 0 | AR6: =$D6*攻击分赃比!AS6*开放指数!AO6 -> 3.2 | AS6: =D6+O6+AR6+AL6+AC6 -> 43.2 | AT6: =H6+I6+J6+K6+L6+M6+N6+S6*(1+AB6)+T6+U6+V6+W6+AG6+AH6+AI6+AJ6+AK6+AL6*(1+AQ6)+AR6 -> 124 | AW6: =H6+I6+J6+K6+L6+M6+N6 -> 59.2 | AX6: =S6*(1+AB6)+T6+U6+V6+W6 -> 61.6 | AY6: =AG6+AH6+AI6+AJ6+AK6 -> 0 | AZ6: =AL6*(1+AQ6) -> 0 | BA6: =AR6 -> 3.2 | BB6: =AT6/D6 -> 7.75
A7: 5 | B7: =B6 -> 2 | C7: =C6+B7 -> 18 | D7: =B7+D6 -> 18 | E7: =$D7*攻击分赃比!B7*开放指数!B7 -> 21.6 | F7: =$D7*攻击分赃比!C7*开放指数!C7 -> 27 | G7: =$D7*攻击分赃比!D7*开放指数!D7 -> 36 | H7: =$D7*攻击分赃比!E7*开放指数!E7 -> 45 | I7: =$D7*攻击分赃比!F7*开放指数!F7 -> 9 | J7: =$D7*攻击分赃比!G7*开放指数!G7 -> 0 | K7: =$D7*攻击分赃比!H7*开放指数!H7 -> 0 | L7: =$D7*攻击分赃比!I7*开放指数!I7 -> 0 | ... N7: =$D7*攻击分赃比!K7*开放指数!K7 -> 21.6 | O7: =$D7*攻击分赃比!M7*开放指数!L7 -> 27 | P7: =$D7*攻击分赃比!N7*开放指数!M7 -> 36 | Q7: =$D7*攻击分赃比!O7*开放指数!N7 -> 45 | R7: =$D7*攻击分赃比!P7*开放指数!O7 -> 54 | S7: =$D7*攻击分赃比!Q7*开放指数!P7 -> 63 | T7: =$D7*攻击分赃比!R7*开放指数!Q7 -> 0 | U7: =$D7*攻击分赃比!S7*开放指数!R7 -> 5.4 | V7: =$D7*攻击分赃比!T7*开放指数!S7 -> 0 | W7: =$D7*攻击分赃比!U7*开放指数!T7 -> 0.9 | X7: =攻击分赃比!V7*开放指数!U7 -> 0 | Y7: =攻击分赃比!W7*开放指数!V7 -> 0 | Z7: =攻击分赃比!X7*开放指数!W7 -> 0 | AA7: =攻击分赃比!Y7*开放指数!X7 -> 0 | AB7: =攻击分赃比!Z7*开放指数!Y7 -> 0 | AC7: =$D7*攻击分赃比!AB7*开放指数!Z7 -> 0 | AD7: =$D7*攻击分赃比!AC7*开放指数!AA7 -> 0 | AE7: =$D7*攻击分赃比!AD7*开放指数!AB7 -> 0 | AF7: =$D7*攻击分赃比!AE7*开放指数!AC7 -> 0 | AG7: =$D7*攻击分赃比!AF7*开放指数!AD7 -> 0 | AH7: =$D7*攻击分赃比!AG7*开放指数!AE7 -> 0 | AI7: =$D7*攻击分赃比!AH7*开放指数!AF7 -> 0 | AJ7: =$D7*攻击分赃比!AI7*开放指数!AG7 -> 0 | AK7: =$D7*攻击分赃比!AJ7*开放指数!AH7 -> 0 | AL7: =$D7*攻击分赃比!AL7*开放指数!AI7 -> 0 | AM7: =攻击分赃比!AM7*开放指数!AJ7 -> 0 | AN7: =攻击分赃比!AN7*开放指数!AK7 -> 0 | AO7: =攻击分赃比!AO7*开放指数!AL7 -> 0 | AP7: =攻击分赃比!AP7*开放指数!AM7 -> 0 | AQ7: =攻击分赃比!AQ7*开放指数!AN7 -> 0 | AR7: =$D7*攻击分赃比!AS7*开放指数!AO7 -> 3.6 | AS7: =D7+O7+AR7+AL7+AC7 -> 48.6 | AT7: =H7+I7+J7+K7+L7+M7+N7+S7*(1+AB7)+T7+U7+V7+W7+AG7+AH7+AI7+AJ7+AK7+AL7*(1+AQ7)+AR7 -> 148.5 | AW7: =H7+I7+J7+K7+L7+M7+N7 -> 75.6 | AX7: =S7*(1+AB7)+T7+U7+V7+W7 -> 69.3 | AY7: =AG7+AH7+AI7+AJ7+AK7 -> 0 | AZ7: =AL7*(1+AQ7) -> 0 | BA7: =AR7 -> 3.6 | BB7: =AT7/D7 -> 8.25
A8: 6 | B8: =B7 -> 2 | C8: =C7+B8 -> 20 | D8: =B8+D7 -> 20 | E8: =$D8*攻击分赃比!B8*开放指数!B8 -> 24 | F8: =$D8*攻击分赃比!C8*开放指数!C8 -> 30 | G8: =$D8*攻击分赃比!D8*开放指数!D8 -> 40 | H8: =$D8*攻击分赃比!E8*开放指数!E8 -> 50 | I8: =I7 -> 9 | J8: =$D8*攻击分赃比!G8*开放指数!G8 -> 0 | K8: =$D8*攻击分赃比!H8*开放指数!H8 -> 0 | L8: =$D8*攻击分赃比!I8*开放指数!I8 -> 0 | M8: =$D8*攻击分赃比!J8*开放指数!J8 -> 0 | N8: =$D8*攻击分赃比!K8*开放指数!K8 -> 24 | O8: =$D8*攻击分赃比!M8*开放指数!L8 -> 30 | P8: =$D8*攻击分赃比!N8*开放指数!M8 -> 40 | Q8: =$D8*攻击分赃比!O8*开放指数!N8 -> 50 | R8: =$D8*攻击分赃比!P8*开放指数!O8 -> 60 | S8: =$D8*攻击分赃比!Q8*开放指数!P8 -> 70 | T8: =$D8*攻击分赃比!R8*开放指数!Q8 -> 0 | U8: =$D8*攻击分赃比!S8*开放指数!R8 -> 6 | V8: =$D8*攻击分赃比!T8*开放指数!S8 -> 0 | W8: =$D8*攻击分赃比!U8*开放指数!T8 -> 1 | X8: =攻击分赃比!V8*开放指数!U8 -> 0 | Y8: =攻击分赃比!W8*开放指数!V8 -> 0 | Z8: =攻击分赃比!X8*开放指数!W8 -> 0 | AA8: =攻击分赃比!Y8*开放指数!X8 -> 0 | AB8: =攻击分赃比!Z8*开放指数!Y8 -> 0 | AC8: =$D8*攻击分赃比!AB8*开放指数!Z8 -> 0 | AD8: =$D8*攻击分赃比!AC8*开放指数!AA8 -> 0 | AE8: =$D8*攻击分赃比!AD8*开放指数!AB8 -> 0 | AF8: =$D8*攻击分赃比!AE8*开放指数!AC8 -> 0 | AG8: =$D8*攻击分赃比!AF8*开放指数!AD8 -> 0 | AH8: =$D8*攻击分赃比!AG8*开放指数!AE8 -> 0 | AI8: =$D8*攻击分赃比!AH8*开放指数!AF8 -> 0 | AJ8: =$D8*攻击分赃比!AI8*开放指数!AG8 -> 0 | AK8: =$D8*攻击分赃比!AJ8*开放指数!AH8 -> 0 | AL8: =$D8*攻击分赃比!AL8*开放指数!AI8 -> 0 | AM8: =攻击分赃比!AM8*开放指数!AJ8 -> 0 | AN8: =攻击分赃比!AN8*开放指数!AK8 -> 0 | AO8: =攻击分赃比!AO8*开放指数!AL8 -> 0 | AP8: =攻击分赃比!AP8*开放指数!AM8 -> 0 | AQ8: =攻击分赃比!AQ8*开放指数!AN8 -> 0 | AR8: =$D8*攻击分赃比!AS8*开放指数!AO8 -> 4 | AS8: =D8+O8+AR8+AL8+AC8 -> 54 | AT8: =H8+I8+J8+K8+L8+M8+N8+S8*(1+AB8)+T8+U8+V8+W8+AG8+AH8+AI8+AJ8+AK8+AL8*(1+AQ8)+AR8 -> 164 | AW8: =H8+I8+J8+K8+L8+M8+N8 -> 83 | AX8: =S8*(1+AB8)+T8+U8+V8+W8 -> 77 | AY8: =AG8+AH8+AI8+AJ8+AK8 -> 0 | AZ8: =AL8*(1+AQ8) -> 0 | BA8: =AR8 -> 4 | BB8: =AT8/D8 -> 8.2
A9: 7 | B9: =B8 -> 2 | C9: =C8+B9 -> 22 | D9: =B9+D8 -> 22 | E9: =$D9*攻击分赃比!B9*开放指数!B9 -> 26.4 | F9: =$D9*攻击分赃比!C9*开放指数!C9 -> 33 | G9: =$D9*攻击分赃比!D9*开放指数!D9 -> 44 | H9: =$D9*攻击分赃比!E9*开放指数!E9 -> 55 | I9: =I8 -> 9 | J9: =$D9*攻击分赃比!G9*开放指数!G9 -> 0 | K9: =$D9*攻击分赃比!H9*开放指数!H9 -> 0 | L9: =$D9*攻击分赃比!I9*开放指数!I9 -> 0 | M9: =$D9*攻击分赃比!J9*开放指数!J9 -> 0 | N9: =$D9*攻击分赃比!K9*开放指数!K9 -> 26.4 | O9: =$D9*攻击分赃比!M9*开放指数!L9 -> 33 | P9: =$D9*攻击分赃比!N9*开放指数!M9 -> 44 | Q9: =$D9*攻击分赃比!O9*开放指数!N9 -> 55 | R9: =$D9*攻击分赃比!P9*开放指数!O9 -> 66 | S9: =$D9*攻击分赃比!Q9*开放指数!P9 -> 77 | T9: =$D9*攻击分赃比!R9*开放指数!Q9 -> 0 | U9: =$D9*攻击分赃比!S9*开放指数!R9 -> 6.6 | V9: =$D9*攻击分赃比!T9*开放指数!S9 -> 0 | W9: =$D9*攻击分赃比!U9*开放指数!T9 -> 1.1 | X9: =攻击分赃比!V9*开放指数!U9 -> 0 | Y9: =攻击分赃比!W9*开放指数!V9 -> 0 | Z9: =攻击分赃比!X9*开放指数!W9 -> 0 | AA9: =攻击分赃比!Y9*开放指数!X9 -> 0 | AB9: =攻击分赃比!Z9*开放指数!Y9 -> 0 | AC9: =$D9*攻击分赃比!AB9*开放指数!Z9 -> 0 | AD9: =$D9*攻击分赃比!AC9*开放指数!AA9 -> 0 | AE9: =$D9*攻击分赃比!AD9*开放指数!AB9 -> 0 | AF9: =$D9*攻击分赃比!AE9*开放指数!AC9 -> 0 | AG9: =$D9*攻击分赃比!AF9*开放指数!AD9 -> 0 | AH9: =$D9*攻击分赃比!AG9*开放指数!AE9 -> 0 | AI9: =$D9*攻击分赃比!AH9*开放指数!AF9 -> 0 | AJ9: =$D9*攻击分赃比!AI9*开放指数!AG9 -> 0 | AK9: =$D9*攻击分赃比!AJ9*开放指数!AH9 -> 0 | AL9: =$D9*攻击分赃比!AL9*开放指数!AI9 -> 0 | AM9: =攻击分赃比!AM9*开放指数!AJ9 -> 0 | AN9: =攻击分赃比!AN9*开放指数!AK9 -> 0 | AO9: =攻击分赃比!AO9*开放指数!AL9 -> 0 | AP9: =攻击分赃比!AP9*开放指数!AM9 -> 0 | AQ9: =攻击分赃比!AQ9*开放指数!AN9 -> 0 | AR9: =$D9*攻击分赃比!AS9*开放指数!AO9 -> 4.4 | AS9: =D9+O9+AR9+AL9+AC9 -> 59.4 | AT9: =H9+I9+J9+K9+L9+M9+N9+S9*(1+AB9)+T9+U9+V9+W9+AG9+AH9+AI9+AJ9+AK9+AL9*(1+AQ9)+AR9 -> 179.5 | AW9: =H9+I9+J9+K9+L9+M9+N9 -> 90.4 | AX9: =S9*(1+AB9)+T9+U9+V9+W9 -> 84.7 | AY9: =AG9+AH9+AI9+AJ9+AK9 -> 0 | AZ9: =AL9*(1+AQ9) -> 0 | BA9: =AR9 -> 4.4 | BB9: =AT9/D9 -> 8.1590909
A10: 8 | B10: =B9 -> 2 | C10: =C9+B10 -> 24 | D10: =B10+D9 -> 24 | E10: =$D10*攻击分赃比!B10*开放指数!B10 -> 28.8 | F10: =$D10*攻击分赃比!C10*开放指数!C10 -> 36 | G10: =$D10*攻击分赃比!D10*开放指数!D10 -> 48 | H10: =$D10*攻击分赃比!E10*开放指数!E10 -> 60 | I10: =I9 -> 9 | J10: =$D10*攻击分赃比!G10*开放指数!G10 -> 0 | K10: =$D10*攻击分赃比!H10*开放指数!H10 -> 0 | L10: =$D10*攻击分赃比!I10*开放指数!I10 -> 0 | M10: =$D10*攻击分赃比!J10*开放指数!J10 -> 0 | N10: =$D10*攻击分赃比!K10*开放指数!K10 -> 28.8 | O10: =$D10*攻击分赃比!M10*开放指数!L10 -> 36 | P10: =$D10*攻击分赃比!N10*开放指数!M10 -> 48 | Q10: =$D10*攻击分赃比!O10*开放指数!N10 -> 60 | R10: =$D10*攻击分赃比!P10*开放指数!O10 -> 72 | S10: =$D10*攻击分赃比!Q10*开放指数!P10 -> 84 | T10: =$D10*攻击分赃比!R10*开放指数!Q10 -> 0 | U10: =$D10*攻击分赃比!S10*开放指数!R10 -> 7.2 | V10: =$D10*攻击分赃比!T10*开放指数!S10 -> 0 | W10: =$D10*攻击分赃比!U10*开放指数!T10 -> 1.2 | X10: =攻击分赃比!V10*开放指数!U10 -> 0 | Y10: =攻击分赃比!W10*开放指数!V10 -> 0 | Z10: =攻击分赃比!X10*开放指数!W10 -> 0 | AA10: =攻击分赃比!Y10*开放指数!X10 -> 0 | AB10: =攻击分赃比!Z10*开放指数!Y10 -> 0 | AC10: =$D10*攻击分赃比!AB10*开放指数!Z10 -> 0 | AD10: =$D10*攻击分赃比!AC10*开放指数!AA10 -> 0 | AE10: =$D10*攻击分赃比!AD10*开放指数!AB10 -> 0 | AF10: =$D10*攻击分赃比!AE10*开放指数!AC10 -> 0 | AG10: =$D10*攻击分赃比!AF10*开放指数!AD10 -> 0 | AH10: =$D10*攻击分赃比!AG10*开放指数!AE10 -> 0 | AI10: =$D10*攻击分赃比!AH10*开放指数!AF10 -> 0 | AJ10: =$D10*攻击分赃比!AI10*开放指数!AG10 -> 0 | AK10: =$D10*攻击分赃比!AJ10*开放指数!AH10 -> 0 | AL10: =$D10*攻击分赃比!AL10*开放指数!AI10 -> 0 | AM10: =攻击分赃比!AM10*开放指数!AJ10 -> 0 | AN10: =攻击分赃比!AN10*开放指数!AK10 -> 0 | AO10: =攻击分赃比!AO10*开放指数!AL10 -> 0 | AP10: =攻击分赃比!AP10*开放指数!AM10 -> 0 | AQ10: =攻击分赃比!AQ10*开放指数!AN10 -> 0 | AR10: =$D10*攻击分赃比!AS10*开放指数!AO10 -> 4.8 | AS10: =D10+O10+AR10+AL10+AC10 -> 64.8 | AT10: =H10+I10+J10+K10+L10+M10+N10+S10*(1+AB10)+T10+U10+V10+W10+AG10+AH10+AI10+AJ10+AK10+AL10*(1+AQ10)+AR10 -> 195 | AW10: =H10+I10+J10+K10+L10+M10+N10 -> 97.8 | AX10: =S10*(1+AB10)+T10+U10+V10+W10 -> 92.4 | AY10: =AG10+AH10+AI10+AJ10+AK10 -> 0 | AZ10: =AL10*(1+AQ10) -> 0 | BA10: =AR10 -> 4.8 | BB10: =AT10/D10 -> 8.125
A11: 9 | B11: =B10 -> 2 | C11: =C10+B11 -> 26 | D11: =B11+D10 -> 26 | E11: =$D11*攻击分赃比!B11*开放指数!B11 -> 31.2 | F11: =$D11*攻击分赃比!C11*开放指数!C11 -> 39 | G11: =$D11*攻击分赃比!D11*开放指数!D11 -> 52 | H11: =$D11*攻击分赃比!E11*开放指数!E11 -> 65 | I11: =I10 -> 9 | J11: =$D11*攻击分赃比!G11*开放指数!G11 -> 0 | K11: =$D11*攻击分赃比!H11*开放指数!H11 -> 0 | L11: =$D11*攻击分赃比!I11*开放指数!I11 -> 0 | M11: =$D11*攻击分赃比!J11*开放指数!J11 -> 0 | N11: =$D11*攻击分赃比!K11*开放指数!K11 -> 31.2 | O11: =$D11*攻击分赃比!M11*开放指数!L11 -> 39 | P11: =$D11*攻击分赃比!N11*开放指数!M11 -> 52 | Q11: =$D11*攻击分赃比!O11*开放指数!N11 -> 65 | R11: =$D11*攻击分赃比!P11*开放指数!O11 -> 78 | S11: =$D11*攻击分赃比!Q11*开放指数!P11 -> 91 | T11: =$D11*攻击分赃比!R11*开放指数!Q11 -> 0 | U11: =$D11*攻击分赃比!S11*开放指数!R11 -> 7.8 | V11: =$D11*攻击分赃比!T11*开放指数!S11 -> 0 | W11: =$D11*攻击分赃比!U11*开放指数!T11 -> 1.3 | X11: =攻击分赃比!V11*开放指数!U11 -> 0 | Y11: =攻击分赃比!W11*开放指数!V11 -> 0 | Z11: =攻击分赃比!X11*开放指数!W11 -> 0 | AA11: =攻击分赃比!Y11*开放指数!X11 -> 0 | AB11: =攻击分赃比!Z11*开放指数!Y11 -> 0 | AC11: =$D11*攻击分赃比!AB11*开放指数!Z11 -> 0 | AD11: =$D11*攻击分赃比!AC11*开放指数!AA11 -> 0 | AE11: =$D11*攻击分赃比!AD11*开放指数!AB11 -> 0 | AF11: =$D11*攻击分赃比!AE11*开放指数!AC11 -> 0 | AG11: =$D11*攻击分赃比!AF11*开放指数!AD11 -> 0 | AH11: =$D11*攻击分赃比!AG11*开放指数!AE11 -> 0 | AI11: =$D11*攻击分赃比!AH11*开放指数!AF11 -> 0 | AJ11: =$D11*攻击分赃比!AI11*开放指数!AG11 -> 0 | AK11: =$D11*攻击分赃比!AJ11*开放指数!AH11 -> 0 | AL11: =$D11*攻击分赃比!AL11*开放指数!AI11 -> 0 | AM11: =攻击分赃比!AM11*开放指数!AJ11 -> 0 | AN11: =攻击分赃比!AN11*开放指数!AK11 -> 0 | AO11: =攻击分赃比!AO11*开放指数!AL11 -> 0 | AP11: =攻击分赃比!AP11*开放指数!AM11 -> 0 | AQ11: =攻击分赃比!AQ11*开放指数!AN11 -> 0 | AR11: =$D11*攻击分赃比!AS11*开放指数!AO11 -> 5.2 | AS11: =D11+O11+AR11+AL11+AC11 -> 70.2 | AT11: =H11+I11+J11+K11+L11+M11+N11+S11*(1+AB11)+T11+U11+V11+W11+AG11+AH11+AI11+AJ11+AK11+AL11*(1+AQ11)+AR11 -> 210.5 | AW11: =H11+I11+J11+K11+L11+M11+N11 -> 105.2 | AX11: =S11*(1+AB11)+T11+U11+V11+W11 -> 100.1 | AY11: =AG11+AH11+AI11+AJ11+AK11 -> 0 | AZ11: =AL11*(1+AQ11) -> 0 | BA11: =AR11 -> 5.2 | BB11: =AT11/D11 -> 8.0961538
A12: 10 | B12: =B11 -> 2 | C12: =C11+B12 -> 28 | D12: =B12+D11 -> 28 | E12: =$D12*攻击分赃比!B12*开放指数!B12 -> 33.6 | F12: =$D12*攻击分赃比!C12*开放指数!C12 -> 42 | G12: =$D12*攻击分赃比!D12*开放指数!D12 -> 56 | H12: =$D12*攻击分赃比!E12*开放指数!E12 -> 70 | I12: =$D12*攻击分赃比!F12*开放指数!F12 -> 14 | J12: =$D12*攻击分赃比!G12*开放指数!G12 -> 8.4 | K12: =$D12*攻击分赃比!H12*开放指数!H12 -> 0 | L12: =$D12*攻击分赃比!I12*开放指数!I12 -> 0 | ... N12: =$D12*攻击分赃比!K12*开放指数!K12 -> 33.6 | O12: =$D12*攻击分赃比!M12*开放指数!L12 -> 42 | P12: =$D12*攻击分赃比!N12*开放指数!M12 -> 56 | Q12: =$D12*攻击分赃比!O12*开放指数!N12 -> 70 | R12: =$D12*攻击分赃比!P12*开放指数!O12 -> 84 | S12: =$D12*攻击分赃比!Q12*开放指数!P12 -> 98 | T12: =$D12*攻击分赃比!R12*开放指数!Q12 -> 0 | U12: =$D12*攻击分赃比!S12*开放指数!R12 -> 8.4 | V12: =$D12*攻击分赃比!T12*开放指数!S12 -> 0 | W12: =$D12*攻击分赃比!U12*开放指数!T12 -> 1.4 | X12: =攻击分赃比!V12*开放指数!U12 -> 0 | Y12: =攻击分赃比!W12*开放指数!V12 -> 0 | Z12: =攻击分赃比!X12*开放指数!W12 -> 0 | AA12: =攻击分赃比!Y12*开放指数!X12 -> 0 | AB12: =攻击分赃比!Z12*开放指数!Y12 -> 0 | AC12: =$D12*攻击分赃比!AB12*开放指数!Z12 -> 0 | AD12: =$D12*攻击分赃比!AC12*开放指数!AA12 -> 0 | AE12: =$D12*攻击分赃比!AD12*开放指数!AB12 -> 0 | AF12: =$D12*攻击分赃比!AE12*开放指数!AC12 -> 0 | AG12: =$D12*攻击分赃比!AF12*开放指数!AD12 -> 0 | AH12: =$D12*攻击分赃比!AG12*开放指数!AE12 -> 0 | AI12: =$D12*攻击分赃比!AH12*开放指数!AF12 -> 0 | AJ12: =$D12*攻击分赃比!AI12*开放指数!AG12 -> 0 | AK12: =$D12*攻击分赃比!AJ12*开放指数!AH12 -> 0 | AL12: =$D12*攻击分赃比!AL12*开放指数!AI12 -> 0 | AM12: =攻击分赃比!AM12*开放指数!AJ12 -> 0 | AN12: =攻击分赃比!AN12*开放指数!AK12 -> 0 | AO12: =攻击分赃比!AO12*开放指数!AL12 -> 0 | AP12: =攻击分赃比!AP12*开放指数!AM12 -> 0 | AQ12: =攻击分赃比!AQ12*开放指数!AN12 -> 0 | AR12: =$D12*攻击分赃比!AS12*开放指数!AO12 -> 5.6 | AS12: =D12+O12+AR12+AL12+AC12 -> 75.6 | AT12: =H12+I12+J12+K12+L12+M12+N12+S12*(1+AB12)+T12+U12+V12+W12+AG12+AH12+AI12+AJ12+AK12+AL12*(1+AQ12)+AR12 -> 239.4 | AW12: =H12+I12+J12+K12+L12+M12+N12 -> 126 | AX12: =S12*(1+AB12)+T12+U12+V12+W12 -> 107.8 | AY12: =AG12+AH12+AI12+AJ12+AK12 -> 0 | AZ12: =AL12*(1+AQ12) -> 0 | BA12: =AR12 -> 5.6 | BB12: =AT12/D12 -> 8.55
A13: 11 | B13: =B12 -> 2 | C13: =C12+B13 -> 30 | D13: =B13+D12 -> 30 | E13: =$D13*攻击分赃比!B13*开放指数!B13 -> 36 | F13: =$D13*攻击分赃比!C13*开放指数!C13 -> 45 | G13: =$D13*攻击分赃比!D13*开放指数!D13 -> 60 | H13: =$D13*攻击分赃比!E13*开放指数!E13 -> 75 | I13: =I12 -> 14 | J13: =$D13*攻击分赃比!G13*开放指数!G13 -> 9 | K13: =$D13*攻击分赃比!H13*开放指数!H13 -> 0 | L13: =$D13*攻击分赃比!I13*开放指数!I13 -> 0 | M13: =$D13*攻击分赃比!J13*开放指数!J13 -> 0 | N13: =$D13*攻击分赃比!K13*开放指数!K13 -> 36 | O13: =$D13*攻击分赃比!M13*开放指数!L13 -> 45 | P13: =$D13*攻击分赃比!N13*开放指数!M13 -> 60 | Q13: =$D13*攻击分赃比!O13*开放指数!N13 -> 75 | R13: =$D13*攻击分赃比!P13*开放指数!O13 -> 90 | S13: =$D13*攻击分赃比!Q13*开放指数!P13 -> 105 | T13: =$D13*攻击分赃比!R13*开放指数!Q13 -> 0 | U13: =$D13*攻击分赃比!S13*开放指数!R13 -> 9 | V13: =$D13*攻击分赃比!T13*开放指数!S13 -> 0 | W13: =$D13*攻击分赃比!U13*开放指数!T13 -> 1.5 | X13: =攻击分赃比!V13*开放指数!U13 -> 0 | Y13: =攻击分赃比!W13*开放指数!V13 -> 0 | Z13: =攻击分赃比!X13*开放指数!W13 -> 0 | AA13: =攻击分赃比!Y13*开放指数!X13 -> 0 | AB13: =攻击分赃比!Z13*开放指数!Y13 -> 0 | AC13: =$D13*攻击分赃比!AB13*开放指数!Z13 -> 0 | AD13: =$D13*攻击分赃比!AC13*开放指数!AA13 -> 0 | AE13: =$D13*攻击分赃比!AD13*开放指数!AB13 -> 0 | AF13: =$D13*攻击分赃比!AE13*开放指数!AC13 -> 0 | AG13: =$D13*攻击分赃比!AF13*开放指数!AD13 -> 0 | AH13: =$D13*攻击分赃比!AG13*开放指数!AE13 -> 0 | AI13: =$D13*攻击分赃比!AH13*开放指数!AF13 -> 0 | AJ13: =$D13*攻击分赃比!AI13*开放指数!AG13 -> 0 | AK13: =$D13*攻击分赃比!AJ13*开放指数!AH13 -> 0 | AL13: =$D13*攻击分赃比!AL13*开放指数!AI13 -> 0 | AM13: =攻击分赃比!AM13*开放指数!AJ13 -> 0 | AN13: =攻击分赃比!AN13*开放指数!AK13 -> 0 | AO13: =攻击分赃比!AO13*开放指数!AL13 -> 0 | AP13: =攻击分赃比!AP13*开放指数!AM13 -> 0 | AQ13: =攻击分赃比!AQ13*开放指数!AN13 -> 0 | AR13: =$D13*攻击分赃比!AS13*开放指数!AO13 -> 6 | AS13: =D13+O13+AR13+AL13+AC13 -> 81 | AT13: =H13+I13+J13+K13+L13+M13+N13+S13*(1+AB13)+T13+U13+V13+W13+AG13+AH13+AI13+AJ13+AK13+AL13*(1+AQ13)+AR13 -> 255.5 | AW13: =H13+I13+J13+K13+L13+M13+N13 -> 134 | AX13: =S13*(1+AB13)+T13+U13+V13+W13 -> 115.5 | AY13: =AG13+AH13+AI13+AJ13+AK13 -> 0 | AZ13: =AL13*(1+AQ13) -> 0 | BA13: =AR13 -> 6 | BB13: =AT13/D13 -> 8.5166667
A14: 12 | B14: =B13 -> 2 | C14: =C13+B14 -> 32 | D14: =B14+D13 -> 32 | E14: =$D14*攻击分赃比!B14*开放指数!B14 -> 38.4 | F14: =$D14*攻击分赃比!C14*开放指数!C14 -> 48 | G14: =$D14*攻击分赃比!D14*开放指数!D14 -> 64 | H14: =$D14*攻击分赃比!E14*开放指数!E14 -> 80 | I14: =I13 -> 14 | J14: =$D14*攻击分赃比!G14*开放指数!G14 -> 9.6 | K14: =$D14*攻击分赃比!H14*开放指数!H14 -> 0 | L14: =$D14*攻击分赃比!I14*开放指数!I14 -> 0 | M14: =$D14*攻击分赃比!J14*开放指数!J14 -> 0 | N14: =$D14*攻击分赃比!K14*开放指数!K14 -> 38.4 | O14: =$D14*攻击分赃比!M14*开放指数!L14 -> 48 | P14: =$D14*攻击分赃比!N14*开放指数!M14 -> 64 | Q14: =$D14*攻击分赃比!O14*开放指数!N14 -> 80 | R14: =$D14*攻击分赃比!P14*开放指数!O14 -> 96 | S14: =$D14*攻击分赃比!Q14*开放指数!P14 -> 112 | T14: =$D14*攻击分赃比!R14*开放指数!Q14 -> 0 | U14: =$D14*攻击分赃比!S14*开放指数!R14 -> 9.6 | V14: =$D14*攻击分赃比!T14*开放指数!S14 -> 0 | W14: =$D14*攻击分赃比!U14*开放指数!T14 -> 1.6 | X14: =攻击分赃比!V14*开放指数!U14 -> 0 | Y14: =攻击分赃比!W14*开放指数!V14 -> 0 | Z14: =攻击分赃比!X14*开放指数!W14 -> 0 | AA14: =攻击分赃比!Y14*开放指数!X14 -> 0 | AB14: =攻击分赃比!Z14*开放指数!Y14 -> 0 | AC14: =$D14*攻击分赃比!AB14*开放指数!Z14 -> 0 | AD14: =$D14*攻击分赃比!AC14*开放指数!AA14 -> 0 | AE14: =$D14*攻击分赃比!AD14*开放指数!AB14 -> 0 | AF14: =$D14*攻击分赃比!AE14*开放指数!AC14 -> 0 | AG14: =$D14*攻击分赃比!AF14*开放指数!AD14 -> 0 | AH14: =$D14*攻击分赃比!AG14*开放指数!AE14 -> 0 | AI14: =$D14*攻击分赃比!AH14*开放指数!AF14 -> 0 | AJ14: =$D14*攻击分赃比!AI14*开放指数!AG14 -> 0 | AK14: =$D14*攻击分赃比!AJ14*开放指数!AH14 -> 0 | AL14: =$D14*攻击分赃比!AL14*开放指数!AI14 -> 0 | AM14: =攻击分赃比!AM14*开放指数!AJ14 -> 0 | AN14: =攻击分赃比!AN14*开放指数!AK14 -> 0 | AO14: =攻击分赃比!AO14*开放指数!AL14 -> 0 | AP14: =攻击分赃比!AP14*开放指数!AM14 -> 0 | AQ14: =攻击分赃比!AQ14*开放指数!AN14 -> 0 | AR14: =$D14*攻击分赃比!AS14*开放指数!AO14 -> 6.4 | AS14: =D14+O14+AR14+AL14+AC14 -> 86.4 | AT14: =H14+I14+J14+K14+L14+M14+N14+S14*(1+AB14)+T14+U14+V14+W14+AG14+AH14+AI14+AJ14+AK14+AL14*(1+AQ14)+AR14 -> 271.6 | AW14: =H14+I14+J14+K14+L14+M14+N14 -> 142 | AX14: =S14*(1+AB14)+T14+U14+V14+W14 -> 123.2 | AY14: =AG14+AH14+AI14+AJ14+AK14 -> 0 | AZ14: =AL14*(1+AQ14) -> 0 | BA14: =AR14 -> 6.4 | BB14: =AT14/D14 -> 8.4875
A15: 13 | B15: =B14 -> 2 | C15: =C14+B15 -> 34 | D15: =B15+D14 -> 34 | E15: =$D15*攻击分赃比!B15*开放指数!B15 -> 40.8 | F15: =$D15*攻击分赃比!C15*开放指数!C15 -> 51 | G15: =$D15*攻击分赃比!D15*开放指数!D15 -> 68 | H15: =$D15*攻击分赃比!E15*开放指数!E15 -> 85 | I15: =I14 -> 14 | J15: =$D15*攻击分赃比!G15*开放指数!G15 -> 10.2 | K15: =$D15*攻击分赃比!H15*开放指数!H15 -> 0 | L15: =$D15*攻击分赃比!I15*开放指数!I15 -> 0 | M15: =$D15*攻击分赃比!J15*开放指数!J15 -> 0 | N15: =$D15*攻击分赃比!K15*开放指数!K15 -> 40.8 | O15: =$D15*攻击分赃比!M15*开放指数!L15 -> 51 | P15: =$D15*攻击分赃比!N15*开放指数!M15 -> 68 | Q15: =$D15*攻击分赃比!O15*开放指数!N15 -> 85 | R15: =$D15*攻击分赃比!P15*开放指数!O15 -> 102 | S15: =$D15*攻击分赃比!Q15*开放指数!P15 -> 119 | T15: =$D15*攻击分赃比!R15*开放指数!Q15 -> 0 | U15: =$D15*攻击分赃比!S15*开放指数!R15 -> 10.2 | V15: =$D15*攻击分赃比!T15*开放指数!S15 -> 0 | W15: =$D15*攻击分赃比!U15*开放指数!T15 -> 1.7 | X15: =攻击分赃比!V15*开放指数!U15 -> 0 | Y15: =攻击分赃比!W15*开放指数!V15 -> 0 | Z15: =攻击分赃比!X15*开放指数!W15 -> 0 | AA15: =攻击分赃比!Y15*开放指数!X15 -> 0 | AB15: =攻击分赃比!Z15*开放指数!Y15 -> 0 | AC15: =$D15*攻击分赃比!AB15*开放指数!Z15 -> 0 | AD15: =$D15*攻击分赃比!AC15*开放指数!AA15 -> 0 | AE15: =$D15*攻击分赃比!AD15*开放指数!AB15 -> 0 | AF15: =$D15*攻击分赃比!AE15*开放指数!AC15 -> 0 | AG15: =$D15*攻击分赃比!AF15*开放指数!AD15 -> 0 | AH15: =$D15*攻击分赃比!AG15*开放指数!AE15 -> 0 | AI15: =$D15*攻击分赃比!AH15*开放指数!AF15 -> 0 | AJ15: =$D15*攻击分赃比!AI15*开放指数!AG15 -> 0 | AK15: =$D15*攻击分赃比!AJ15*开放指数!AH15 -> 0 | AL15: =$D15*攻击分赃比!AL15*开放指数!AI15 -> 0 | AM15: =攻击分赃比!AM15*开放指数!AJ15 -> 0 | AN15: =攻击分赃比!AN15*开放指数!AK15 -> 0 | AO15: =攻击分赃比!AO15*开放指数!AL15 -> 0 | AP15: =攻击分赃比!AP15*开放指数!AM15 -> 0 | AQ15: =攻击分赃比!AQ15*开放指数!AN15 -> 0 | AR15: =$D15*攻击分赃比!AS15*开放指数!AO15 -> 6.8 | AS15: =D15+O15+AR15+AL15+AC15 -> 91.8 | AT15: =H15+I15+J15+K15+L15+M15+N15+S15*(1+AB15)+T15+U15+V15+W15+AG15+AH15+AI15+AJ15+AK15+AL15*(1+AQ15)+AR15 -> 287.7 | AW15: =H15+I15+J15+K15+L15+M15+N15 -> 150 | AX15: =S15*(1+AB15)+T15+U15+V15+W15 -> 130.9 | AY15: =AG15+AH15+AI15+AJ15+AK15 -> 0 | AZ15: =AL15*(1+AQ15) -> 0 | BA15: =AR15 -> 6.8 | BB15: =AT15/D15 -> 8.4617647
A16: 14 | B16: =B15 -> 2 | C16: =C15+B16 -> 36 | D16: =B16+D15 -> 36 | E16: =$D16*攻击分赃比!B16*开放指数!B16 -> 43.2 | F16: =$D16*攻击分赃比!C16*开放指数!C16 -> 54 | G16: =$D16*攻击分赃比!D16*开放指数!D16 -> 72 | H16: =$D16*攻击分赃比!E16*开放指数!E16 -> 90 | I16: =I15 -> 14 | J16: =$D16*攻击分赃比!G16*开放指数!G16 -> 10.8 | K16: =$D16*攻击分赃比!H16*开放指数!H16 -> 0 | L16: =$D16*攻击分赃比!I16*开放指数!I16 -> 0 | M16: =$D16*攻击分赃比!J16*开放指数!J16 -> 0 | N16: =$D16*攻击分赃比!K16*开放指数!K16 -> 43.2 | O16: =$D16*攻击分赃比!M16*开放指数!L16 -> 54 | P16: =$D16*攻击分赃比!N16*开放指数!M16 -> 72 | Q16: =$D16*攻击分赃比!O16*开放指数!N16 -> 90 | R16: =$D16*攻击分赃比!P16*开放指数!O16 -> 108 | S16: =$D16*攻击分赃比!Q16*开放指数!P16 -> 126 | T16: =$D16*攻击分赃比!R16*开放指数!Q16 -> 0 | U16: =$D16*攻击分赃比!S16*开放指数!R16 -> 10.8 | V16: =$D16*攻击分赃比!T16*开放指数!S16 -> 0 | W16: =$D16*攻击分赃比!U16*开放指数!T16 -> 1.8 | X16: =攻击分赃比!V16*开放指数!U16 -> 0 | Y16: =攻击分赃比!W16*开放指数!V16 -> 0 | Z16: =攻击分赃比!X16*开放指数!W16 -> 0 | AA16: =攻击分赃比!Y16*开放指数!X16 -> 0 | AB16: =攻击分赃比!Z16*开放指数!Y16 -> 0 | AC16: =$D16*攻击分赃比!AB16*开放指数!Z16 -> 0 | AD16: =$D16*攻击分赃比!AC16*开放指数!AA16 -> 0 | AE16: =$D16*攻击分赃比!AD16*开放指数!AB16 -> 0 | AF16: =$D16*攻击分赃比!AE16*开放指数!AC16 -> 0 | AG16: =$D16*攻击分赃比!AF16*开放指数!AD16 -> 0 | AH16: =$D16*攻击分赃比!AG16*开放指数!AE16 -> 0 | AI16: =$D16*攻击分赃比!AH16*开放指数!AF16 -> 0 | AJ16: =$D16*攻击分赃比!AI16*开放指数!AG16 -> 0 | AK16: =$D16*攻击分赃比!AJ16*开放指数!AH16 -> 0 | AL16: =$D16*攻击分赃比!AL16*开放指数!AI16 -> 0 | AM16: =攻击分赃比!AM16*开放指数!AJ16 -> 0 | AN16: =攻击分赃比!AN16*开放指数!AK16 -> 0 | AO16: =攻击分赃比!AO16*开放指数!AL16 -> 0 | AP16: =攻击分赃比!AP16*开放指数!AM16 -> 0 | AQ16: =攻击分赃比!AQ16*开放指数!AN16 -> 0 | AR16: =$D16*攻击分赃比!AS16*开放指数!AO16 -> 7.2 | AS16: =D16+O16+AR16+AL16+AC16 -> 97.2 | AT16: =H16+I16+J16+K16+L16+M16+N16+S16*(1+AB16)+T16+U16+V16+W16+AG16+AH16+AI16+AJ16+AK16+AL16*(1+AQ16)+AR16 -> 303.8 | AW16: =H16+I16+J16+K16+L16+M16+N16 -> 158 | AX16: =S16*(1+AB16)+T16+U16+V16+W16 -> 138.6 | AY16: =AG16+AH16+AI16+AJ16+AK16 -> 0 | AZ16: =AL16*(1+AQ16) -> 0 | BA16: =AR16 -> 7.2 | BB16: =AT16/D16 -> 8.4388889
A17: 15 | B17: =B16 -> 2 | C17: =C16+B17 -> 38 | D17: =B17+D16 -> 38 | E17: =$D17*攻击分赃比!B17*开放指数!B17 -> 45.6 | F17: =$D17*攻击分赃比!C17*开放指数!C17 -> 57 | G17: =$D17*攻击分赃比!D17*开放指数!D17 -> 76 | H17: =$D17*攻击分赃比!E17*开放指数!E17 -> 95 | I17: =$D17*攻击分赃比!F17*开放指数!F17 -> 19 | J17: =$D17*攻击分赃比!G17*开放指数!G17 -> 11.4 | K17: =$D17*攻击分赃比!H17*开放指数!H17 -> 22.8 | L17: =$D17*攻击分赃比!I17*开放指数!I17 -> 0 | ... N17: =$D17*攻击分赃比!K17*开放指数!K17 -> 45.6 | O17: =$D17*攻击分赃比!M17*开放指数!L17 -> 57 | P17: =$D17*攻击分赃比!N17*开放指数!M17 -> 76 | Q17: =$D17*攻击分赃比!O17*开放指数!N17 -> 95 | R17: =$D17*攻击分赃比!P17*开放指数!O17 -> 114 | S17: =$D17*攻击分赃比!Q17*开放指数!P17 -> 133 | T17: =$D17*攻击分赃比!R17*开放指数!Q17 -> 0 | U17: =$D17*攻击分赃比!S17*开放指数!R17 -> 11.4 | V17: =$D17*攻击分赃比!T17*开放指数!S17 -> 0 | W17: =$D17*攻击分赃比!U17*开放指数!T17 -> 1.9 | X17: =攻击分赃比!V17*开放指数!U17 -> 0 | Y17: =攻击分赃比!W17*开放指数!V17 -> 0 | Z17: =攻击分赃比!X17*开放指数!W17 -> 0 | AA17: =攻击分赃比!Y17*开放指数!X17 -> 0 | AB17: =攻击分赃比!Z17*开放指数!Y17 -> 0 | AC17: =$D17*攻击分赃比!AB17*开放指数!Z17 -> 38 | AD17: =$D17*攻击分赃比!AC17*开放指数!AA17 -> 45.6 | AE17: =$D17*攻击分赃比!AD17*开放指数!AB17 -> 57 | AF17: =$D17*攻击分赃比!AE17*开放指数!AC17 -> 76 | AG17: =$D17*攻击分赃比!AF17*开放指数!AD17 -> 95 | AH17: =$D17*攻击分赃比!AG17*开放指数!AE17 -> 0 | AI17: =$D17*攻击分赃比!AH17*开放指数!AF17 -> 7.6 | AJ17: =$D17*攻击分赃比!AI17*开放指数!AG17 -> 0 | AK17: =$D17*攻击分赃比!AJ17*开放指数!AH17 -> 1.14 | AL17: =$D17*攻击分赃比!AL17*开放指数!AI17 -> 0 | AM17: =攻击分赃比!AM17*开放指数!AJ17 -> 0 | AN17: =攻击分赃比!AN17*开放指数!AK17 -> 0 | AO17: =攻击分赃比!AO17*开放指数!AL17 -> 0 | AP17: =攻击分赃比!AP17*开放指数!AM17 -> 0 | AQ17: =攻击分赃比!AQ17*开放指数!AN17 -> 0 | AR17: =$D17*攻击分赃比!AS17*开放指数!AO17 -> 7.6 | AS17: =D17+O17+AR17+AL17+AC17 -> 140.6 | AT17: =H17+I17+J17+K17+L17+M17+N17+S17*(1+AB17)+T17+U17+V17+W17+AG17+AH17+AI17+AJ17+AK17+AL17*(1+AQ17)+AR17 -> 451.44 | AW17: =H17+I17+J17+K17+L17+M17+N17 -> 193.8 | AX17: =S17*(1+AB17)+T17+U17+V17+W17 -> 146.3 | AY17: =AG17+AH17+AI17+AJ17+AK17 -> 103.74 | AZ17: =AL17*(1+AQ17) -> 0 | BA17: =AR17 -> 7.6 | BB17: =AT17/D17 -> 11.88
A18: 16 | B18: =B17 -> 2 | C18: =C17+B18 -> 40 | D18: =B18+D17 -> 40 | E18: =$D18*攻击分赃比!B18*开放指数!B18 -> 48 | F18: =$D18*攻击分赃比!C18*开放指数!C18 -> 60 | G18: =$D18*攻击分赃比!D18*开放指数!D18 -> 80 | H18: =$D18*攻击分赃比!E18*开放指数!E18 -> 100 | I18: =I17 -> 19 | J18: =$D18*攻击分赃比!G18*开放指数!G18 -> 12 | K18: =$D18*攻击分赃比!H18*开放指数!H18 -> 24 | L18: =$D18*攻击分赃比!I18*开放指数!I18 -> 0 | M18: =$D18*攻击分赃比!J18*开放指数!J18 -> 0 | N18: =$D18*攻击分赃比!K18*开放指数!K18 -> 48 | O18: =$D18*攻击分赃比!M18*开放指数!L18 -> 60 | P18: =$D18*攻击分赃比!N18*开放指数!M18 -> 80 | Q18: =$D18*攻击分赃比!O18*开放指数!N18 -> 100 | R18: =$D18*攻击分赃比!P18*开放指数!O18 -> 120 | S18: =$D18*攻击分赃比!Q18*开放指数!P18 -> 140 | T18: =$D18*攻击分赃比!R18*开放指数!Q18 -> 0 | U18: =$D18*攻击分赃比!S18*开放指数!R18 -> 12 | V18: =$D18*攻击分赃比!T18*开放指数!S18 -> 0 | W18: =$D18*攻击分赃比!U18*开放指数!T18 -> 2 | X18: =攻击分赃比!V18*开放指数!U18 -> 0 | Y18: =攻击分赃比!W18*开放指数!V18 -> 0 | Z18: =攻击分赃比!X18*开放指数!W18 -> 0 | AA18: =攻击分赃比!Y18*开放指数!X18 -> 0 | AB18: =攻击分赃比!Z18*开放指数!Y18 -> 0 | AC18: =$D18*攻击分赃比!AB18*开放指数!Z18 -> 40 | AD18: =$D18*攻击分赃比!AC18*开放指数!AA18 -> 48 | AE18: =$D18*攻击分赃比!AD18*开放指数!AB18 -> 60 | AF18: =$D18*攻击分赃比!AE18*开放指数!AC18 -> 80 | AG18: =$D18*攻击分赃比!AF18*开放指数!AD18 -> 100 | AH18: =$D18*攻击分赃比!AG18*开放指数!AE18 -> 0 | AI18: =$D18*攻击分赃比!AH18*开放指数!AF18 -> 8 | AJ18: =$D18*攻击分赃比!AI18*开放指数!AG18 -> 0 | AK18: =$D18*攻击分赃比!AJ18*开放指数!AH18 -> 1.2 | AL18: =$D18*攻击分赃比!AL18*开放指数!AI18 -> 0 | AM18: =攻击分赃比!AM18*开放指数!AJ18 -> 0 | AN18: =攻击分赃比!AN18*开放指数!AK18 -> 0 | AO18: =攻击分赃比!AO18*开放指数!AL18 -> 0 | AP18: =攻击分赃比!AP18*开放指数!AM18 -> 0 | AQ18: =攻击分赃比!AQ18*开放指数!AN18 -> 0 | AR18: =$D18*攻击分赃比!AS18*开放指数!AO18 -> 8 | AS18: =D18+O18+AR18+AL18+AC18 -> 148 | AT18: =H18+I18+J18+K18+L18+M18+N18+S18*(1+AB18)+T18+U18+V18+W18+AG18+AH18+AI18+AJ18+AK18+AL18*(1+AQ18)+AR18 -> 474.2 | AW18: =H18+I18+J18+K18+L18+M18+N18 -> 203 | AX18: =S18*(1+AB18)+T18+U18+V18+W18 -> 154 | AY18: =AG18+AH18+AI18+AJ18+AK18 -> 109.2 | AZ18: =AL18*(1+AQ18) -> 0 | BA18: =AR18 -> 8 | BB18: =AT18/D18 -> 11.855
A19: 17 | B19: =B18 -> 2 | C19: =C18+B19 -> 42 | D19: =B19+D18 -> 42 | E19: =$D19*攻击分赃比!B19*开放指数!B19 -> 50.4 | F19: =$D19*攻击分赃比!C19*开放指数!C19 -> 63 | G19: =$D19*攻击分赃比!D19*开放指数!D19 -> 84 | H19: =$D19*攻击分赃比!E19*开放指数!E19 -> 105 | I19: =I18 -> 19 | J19: =$D19*攻击分赃比!G19*开放指数!G19 -> 12.6 | K19: =$D19*攻击分赃比!H19*开放指数!H19 -> 25.2 | L19: =$D19*攻击分赃比!I19*开放指数!I19 -> 0 | M19: =$D19*攻击分赃比!J19*开放指数!J19 -> 0 | N19: =$D19*攻击分赃比!K19*开放指数!K19 -> 50.4 | O19: =$D19*攻击分赃比!M19*开放指数!L19 -> 63 | P19: =$D19*攻击分赃比!N19*开放指数!M19 -> 84 | Q19: =$D19*攻击分赃比!O19*开放指数!N19 -> 105 | R19: =$D19*攻击分赃比!P19*开放指数!O19 -> 126 | S19: =$D19*攻击分赃比!Q19*开放指数!P19 -> 147 | T19: =$D19*攻击分赃比!R19*开放指数!Q19 -> 0 | U19: =$D19*攻击分赃比!S19*开放指数!R19 -> 12.6 | V19: =$D19*攻击分赃比!T19*开放指数!S19 -> 0 | W19: =$D19*攻击分赃比!U19*开放指数!T19 -> 2.1 | X19: =攻击分赃比!V19*开放指数!U19 -> 0 | Y19: =攻击分赃比!W19*开放指数!V19 -> 0 | Z19: =攻击分赃比!X19*开放指数!W19 -> 0 | AA19: =攻击分赃比!Y19*开放指数!X19 -> 0 | AB19: =攻击分赃比!Z19*开放指数!Y19 -> 0 | AC19: =$D19*攻击分赃比!AB19*开放指数!Z19 -> 42 | AD19: =$D19*攻击分赃比!AC19*开放指数!AA19 -> 50.4 | AE19: =$D19*攻击分赃比!AD19*开放指数!AB19 -> 63 | AF19: =$D19*攻击分赃比!AE19*开放指数!AC19 -> 84 | AG19: =$D19*攻击分赃比!AF19*开放指数!AD19 -> 105 | AH19: =$D19*攻击分赃比!AG19*开放指数!AE19 -> 0 | AI19: =$D19*攻击分赃比!AH19*开放指数!AF19 -> 8.4 | AJ19: =$D19*攻击分赃比!AI19*开放指数!AG19 -> 0 | AK19: =$D19*攻击分赃比!AJ19*开放指数!AH19 -> 1.26 | AL19: =$D19*攻击分赃比!AL19*开放指数!AI19 -> 0 | AM19: =攻击分赃比!AM19*开放指数!AJ19 -> 0 | AN19: =攻击分赃比!AN19*开放指数!AK19 -> 0 | AO19: =攻击分赃比!AO19*开放指数!AL19 -> 0 | AP19: =攻击分赃比!AP19*开放指数!AM19 -> 0 | AQ19: =攻击分赃比!AQ19*开放指数!AN19 -> 0 | AR19: =$D19*攻击分赃比!AS19*开放指数!AO19 -> 8.4 | AS19: =D19+O19+AR19+AL19+AC19 -> 155.4 | AT19: =H19+I19+J19+K19+L19+M19+N19+S19*(1+AB19)+T19+U19+V19+W19+AG19+AH19+AI19+AJ19+AK19+AL19*(1+AQ19)+AR19 -> 496.96 | AW19: =H19+I19+J19+K19+L19+M19+N19 -> 212.2 | AX19: =S19*(1+AB19)+T19+U19+V19+W19 -> 161.7 | AY19: =AG19+AH19+AI19+AJ19+AK19 -> 114.66 | AZ19: =AL19*(1+AQ19) -> 0 | BA19: =AR19 -> 8.4 | BB19: =AT19/D19 -> 11.832381
A20: 18 | B20: =B19 -> 2 | C20: =C19+B20 -> 44 | D20: =B20+D19 -> 44 | E20: =$D20*攻击分赃比!B20*开放指数!B20 -> 52.8 | F20: =$D20*攻击分赃比!C20*开放指数!C20 -> 66 | G20: =$D20*攻击分赃比!D20*开放指数!D20 -> 88 | H20: =$D20*攻击分赃比!E20*开放指数!E20 -> 110 | I20: =I19 -> 19 | J20: =$D20*攻击分赃比!G20*开放指数!G20 -> 13.2 | K20: =$D20*攻击分赃比!H20*开放指数!H20 -> 26.4 | L20: =$D20*攻击分赃比!I20*开放指数!I20 -> 0 | M20: =$D20*攻击分赃比!J20*开放指数!J20 -> 0 | N20: =$D20*攻击分赃比!K20*开放指数!K20 -> 52.8 | O20: =$D20*攻击分赃比!M20*开放指数!L20 -> 66 | P20: =$D20*攻击分赃比!N20*开放指数!M20 -> 88 | Q20: =$D20*攻击分赃比!O20*开放指数!N20 -> 110 | R20: =$D20*攻击分赃比!P20*开放指数!O20 -> 132 | S20: =$D20*攻击分赃比!Q20*开放指数!P20 -> 154 | T20: =$D20*攻击分赃比!R20*开放指数!Q20 -> 0 | U20: =$D20*攻击分赃比!S20*开放指数!R20 -> 13.2 | V20: =$D20*攻击分赃比!T20*开放指数!S20 -> 0 | W20: =$D20*攻击分赃比!U20*开放指数!T20 -> 2.2 | X20: =攻击分赃比!V20*开放指数!U20 -> 0 | Y20: =攻击分赃比!W20*开放指数!V20 -> 0 | Z20: =攻击分赃比!X20*开放指数!W20 -> 0 | AA20: =攻击分赃比!Y20*开放指数!X20 -> 0 | AB20: =攻击分赃比!Z20*开放指数!Y20 -> 0 | AC20: =$D20*攻击分赃比!AB20*开放指数!Z20 -> 44 | AD20: =$D20*攻击分赃比!AC20*开放指数!AA20 -> 52.8 | AE20: =$D20*攻击分赃比!AD20*开放指数!AB20 -> 66 | AF20: =$D20*攻击分赃比!AE20*开放指数!AC20 -> 88 | AG20: =$D20*攻击分赃比!AF20*开放指数!AD20 -> 110 | AH20: =$D20*攻击分赃比!AG20*开放指数!AE20 -> 0 | AI20: =$D20*攻击分赃比!AH20*开放指数!AF20 -> 8.8 | AJ20: =$D20*攻击分赃比!AI20*开放指数!AG20 -> 0 | AK20: =$D20*攻击分赃比!AJ20*开放指数!AH20 -> 1.32 | AL20: =$D20*攻击分赃比!AL20*开放指数!AI20 -> 0 | AM20: =攻击分赃比!AM20*开放指数!AJ20 -> 0 | AN20: =攻击分赃比!AN20*开放指数!AK20 -> 0 | AO20: =攻击分赃比!AO20*开放指数!AL20 -> 0 | AP20: =攻击分赃比!AP20*开放指数!AM20 -> 0 | AQ20: =攻击分赃比!AQ20*开放指数!AN20 -> 0 | AR20: =$D20*攻击分赃比!AS20*开放指数!AO20 -> 8.8 | AS20: =D20+O20+AR20+AL20+AC20 -> 162.8 | AT20: =H20+I20+J20+K20+L20+M20+N20+S20*(1+AB20)+T20+U20+V20+W20+AG20+AH20+AI20+AJ20+AK20+AL20*(1+AQ20)+AR20 -> 519.72 | AW20: =H20+I20+J20+K20+L20+M20+N20 -> 221.4 | AX20: =S20*(1+AB20)+T20+U20+V20+W20 -> 169.4 | AY20: =AG20+AH20+AI20+AJ20+AK20 -> 120.12 | AZ20: =AL20*(1+AQ20) -> 0 | BA20: =AR20 -> 8.8 | BB20: =AT20/D20 -> 11.811818
A21: 19 | B21: =B20 -> 2 | C21: =C20+B21 -> 46 | D21: =B21+D20 -> 46 | E21: =$D21*攻击分赃比!B21*开放指数!B21 -> 55.2 | F21: =$D21*攻击分赃比!C21*开放指数!C21 -> 69 | G21: =$D21*攻击分赃比!D21*开放指数!D21 -> 92 | H21: =$D21*攻击分赃比!E21*开放指数!E21 -> 115 | I21: =I20 -> 19 | J21: =$D21*攻击分赃比!G21*开放指数!G21 -> 13.8 | K21: =$D21*攻击分赃比!H21*开放指数!H21 -> 27.6 | L21: =$D21*攻击分赃比!I21*开放指数!I21 -> 0 | M21: =$D21*攻击分赃比!J21*开放指数!J21 -> 0 | N21: =$D21*攻击分赃比!K21*开放指数!K21 -> 55.2 | O21: =$D21*攻击分赃比!M21*开放指数!L21 -> 69 | P21: =$D21*攻击分赃比!N21*开放指数!M21 -> 92 | Q21: =$D21*攻击分赃比!O21*开放指数!N21 -> 115 | R21: =$D21*攻击分赃比!P21*开放指数!O21 -> 138 | S21: =$D21*攻击分赃比!Q21*开放指数!P21 -> 161 | T21: =$D21*攻击分赃比!R21*开放指数!Q21 -> 0 | U21: =$D21*攻击分赃比!S21*开放指数!R21 -> 13.8 | V21: =$D21*攻击分赃比!T21*开放指数!S21 -> 0 | W21: =$D21*攻击分赃比!U21*开放指数!T21 -> 2.3 | X21: =攻击分赃比!V21*开放指数!U21 -> 0 | Y21: =攻击分赃比!W21*开放指数!V21 -> 0 | Z21: =攻击分赃比!X21*开放指数!W21 -> 0 | AA21: =攻击分赃比!Y21*开放指数!X21 -> 0 | AB21: =攻击分赃比!Z21*开放指数!Y21 -> 0 | AC21: =$D21*攻击分赃比!AB21*开放指数!Z21 -> 46 | AD21: =$D21*攻击分赃比!AC21*开放指数!AA21 -> 55.2 | AE21: =$D21*攻击分赃比!AD21*开放指数!AB21 -> 69 | AF21: =$D21*攻击分赃比!AE21*开放指数!AC21 -> 92 | AG21: =$D21*攻击分赃比!AF21*开放指数!AD21 -> 115 | AH21: =$D21*攻击分赃比!AG21*开放指数!AE21 -> 0 | AI21: =$D21*攻击分赃比!AH21*开放指数!AF21 -> 9.2 | AJ21: =$D21*攻击分赃比!AI21*开放指数!AG21 -> 0 | AK21: =$D21*攻击分赃比!AJ21*开放指数!AH21 -> 1.38 | AL21: =$D21*攻击分赃比!AL21*开放指数!AI21 -> 0 | AM21: =攻击分赃比!AM21*开放指数!AJ21 -> 0 | AN21: =攻击分赃比!AN21*开放指数!AK21 -> 0 | AO21: =攻击分赃比!AO21*开放指数!AL21 -> 0 | AP21: =攻击分赃比!AP21*开放指数!AM21 -> 0 | AQ21: =攻击分赃比!AQ21*开放指数!AN21 -> 0 | AR21: =$D21*攻击分赃比!AS21*开放指数!AO21 -> 9.2 | AS21: =D21+O21+AR21+AL21+AC21 -> 170.2 | AT21: =H21+I21+J21+K21+L21+M21+N21+S21*(1+AB21)+T21+U21+V21+W21+AG21+AH21+AI21+AJ21+AK21+AL21*(1+AQ21)+AR21 -> 542.48 | AW21: =H21+I21+J21+K21+L21+M21+N21 -> 230.6 | AX21: =S21*(1+AB21)+T21+U21+V21+W21 -> 177.1 | AY21: =AG21+AH21+AI21+AJ21+AK21 -> 125.58 | AZ21: =AL21*(1+AQ21) -> 0 | BA21: =AR21 -> 9.2 | BB21: =AT21/D21 -> 11.793043
A22: 20 | B22: =B21 -> 2 | C22: =C21+B22 -> 48 | D22: =B22+D21 -> 48 | E22: =$D22*攻击分赃比!B22*开放指数!B22 -> 57.6 | F22: =$D22*攻击分赃比!C22*开放指数!C22 -> 72 | G22: =$D22*攻击分赃比!D22*开放指数!D22 -> 96 | H22: =$D22*攻击分赃比!E22*开放指数!E22 -> 120 | I22: =$D22*攻击分赃比!F22*开放指数!F22 -> 24 | J22: =$D22*攻击分赃比!G22*开放指数!G22 -> 14.4 | K22: =$D22*攻击分赃比!H22*开放指数!H22 -> 28.8 | L22: =$D22*攻击分赃比!I22*开放指数!I22 -> 0 | ... N22: =$D22*攻击分赃比!K22*开放指数!K22 -> 57.6 | O22: =$D22*攻击分赃比!M22*开放指数!L22 -> 72 | P22: =$D22*攻击分赃比!N22*开放指数!M22 -> 96 | Q22: =$D22*攻击分赃比!O22*开放指数!N22 -> 120 | R22: =$D22*攻击分赃比!P22*开放指数!O22 -> 144 | S22: =$D22*攻击分赃比!Q22*开放指数!P22 -> 168 | T22: =$D22*攻击分赃比!R22*开放指数!Q22 -> 0 | U22: =$D22*攻击分赃比!S22*开放指数!R22 -> 14.4 | V22: =$D22*攻击分赃比!T22*开放指数!S22 -> 0 | W22: =$D22*攻击分赃比!U22*开放指数!T22 -> 2.4 | X22: =攻击分赃比!V22*开放指数!U22 -> 0 | Y22: =攻击分赃比!W22*开放指数!V22 -> 0 | Z22: =攻击分赃比!X22*开放指数!W22 -> 0 | AA22: =攻击分赃比!Y22*开放指数!X22 -> 0 | AB22: =攻击分赃比!Z22*开放指数!Y22 -> 0 | AC22: =$D22*攻击分赃比!AB22*开放指数!Z22 -> 48 | AD22: =$D22*攻击分赃比!AC22*开放指数!AA22 -> 57.6 | AE22: =$D22*攻击分赃比!AD22*开放指数!AB22 -> 72 | AF22: =$D22*攻击分赃比!AE22*开放指数!AC22 -> 96 | AG22: =$D22*攻击分赃比!AF22*开放指数!AD22 -> 120 | AH22: =$D22*攻击分赃比!AG22*开放指数!AE22 -> 0 | AI22: =$D22*攻击分赃比!AH22*开放指数!AF22 -> 9.6 | AJ22: =$D22*攻击分赃比!AI22*开放指数!AG22 -> 0 | AK22: =$D22*攻击分赃比!AJ22*开放指数!AH22 -> 1.44 | AL22: =$D22*攻击分赃比!AL22*开放指数!AI22 -> 0 | AM22: =攻击分赃比!AM22*开放指数!AJ22 -> 0 | AN22: =攻击分赃比!AN22*开放指数!AK22 -> 0 | AO22: =攻击分赃比!AO22*开放指数!AL22 -> 0 | AP22: =攻击分赃比!AP22*开放指数!AM22 -> 0 | AQ22: =攻击分赃比!AQ22*开放指数!AN22 -> 0 | AR22: =$D22*攻击分赃比!AS22*开放指数!AO22 -> 9.6 | AS22: =D22+O22+AR22+AL22+AC22 -> 177.6 | AT22: =H22+I22+J22+K22+L22+M22+N22+S22*(1+AB22)+T22+U22+V22+W22+AG22+AH22+AI22+AJ22+AK22+AL22*(1+AQ22)+AR22 -> 570.24 | AW22: =H22+I22+J22+K22+L22+M22+N22 -> 244.8 | AX22: =S22*(1+AB22)+T22+U22+V22+W22 -> 184.8 | AY22: =AG22+AH22+AI22+AJ22+AK22 -> 131.04 | AZ22: =AL22*(1+AQ22) -> 0 | BA22: =AR22 -> 9.6 | BB22: =AT22/D22 -> 11.88
A23: 21 | B23: =B22 -> 2 | C23: =C22+B23 -> 50 | D23: =B23+D22 -> 50 | E23: =$D23*攻击分赃比!B23*开放指数!B23 -> 60 | F23: =$D23*攻击分赃比!C23*开放指数!C23 -> 75 | G23: =$D23*攻击分赃比!D23*开放指数!D23 -> 100 | H23: =$D23*攻击分赃比!E23*开放指数!E23 -> 125 | I23: =I22 -> 24 | J23: =$D23*攻击分赃比!G23*开放指数!G23 -> 15 | K23: =$D23*攻击分赃比!H23*开放指数!H23 -> 30 | L23: =$D23*攻击分赃比!I23*开放指数!I23 -> 0 | M23: =$D23*攻击分赃比!J23*开放指数!J23 -> 0 | N23: =$D23*攻击分赃比!K23*开放指数!K23 -> 60 | O23: =$D23*攻击分赃比!M23*开放指数!L23 -> 75 | P23: =$D23*攻击分赃比!N23*开放指数!M23 -> 100 | Q23: =$D23*攻击分赃比!O23*开放指数!N23 -> 125 | R23: =$D23*攻击分赃比!P23*开放指数!O23 -> 150 | S23: =$D23*攻击分赃比!Q23*开放指数!P23 -> 175 | T23: =$D23*攻击分赃比!R23*开放指数!Q23 -> 0 | U23: =$D23*攻击分赃比!S23*开放指数!R23 -> 15 | V23: =$D23*攻击分赃比!T23*开放指数!S23 -> 0 | W23: =$D23*攻击分赃比!U23*开放指数!T23 -> 2.5 | X23: =攻击分赃比!V23*开放指数!U23 -> 0 | Y23: =攻击分赃比!W23*开放指数!V23 -> 0 | Z23: =攻击分赃比!X23*开放指数!W23 -> 0 | AA23: =攻击分赃比!Y23*开放指数!X23 -> 0 | AB23: =攻击分赃比!Z23*开放指数!Y23 -> 0 | AC23: =$D23*攻击分赃比!AB23*开放指数!Z23 -> 50 | AD23: =$D23*攻击分赃比!AC23*开放指数!AA23 -> 60 | AE23: =$D23*攻击分赃比!AD23*开放指数!AB23 -> 75 | AF23: =$D23*攻击分赃比!AE23*开放指数!AC23 -> 100 | AG23: =$D23*攻击分赃比!AF23*开放指数!AD23 -> 125 | AH23: =$D23*攻击分赃比!AG23*开放指数!AE23 -> 0 | AI23: =$D23*攻击分赃比!AH23*开放指数!AF23 -> 10 | AJ23: =$D23*攻击分赃比!AI23*开放指数!AG23 -> 0 | AK23: =$D23*攻击分赃比!AJ23*开放指数!AH23 -> 1.5 | AL23: =$D23*攻击分赃比!AL23*开放指数!AI23 -> 0 | AM23: =攻击分赃比!AM23*开放指数!AJ23 -> 0 | AN23: =攻击分赃比!AN23*开放指数!AK23 -> 0 | AO23: =攻击分赃比!AO23*开放指数!AL23 -> 0 | AP23: =攻击分赃比!AP23*开放指数!AM23 -> 0 | AQ23: =攻击分赃比!AQ23*开放指数!AN23 -> 0 | AR23: =$D23*攻击分赃比!AS23*开放指数!AO23 -> 10 | AS23: =D23+O23+AR23+AL23+AC23 -> 185 | AT23: =H23+I23+J23+K23+L23+M23+N23+S23*(1+AB23)+T23+U23+V23+W23+AG23+AH23+AI23+AJ23+AK23+AL23*(1+AQ23)+AR23 -> 593 | AW23: =H23+I23+J23+K23+L23+M23+N23 -> 254 | AX23: =S23*(1+AB23)+T23+U23+V23+W23 -> 192.5 | AY23: =AG23+AH23+AI23+AJ23+AK23 -> 136.5 | AZ23: =AL23*(1+AQ23) -> 0 | BA23: =AR23 -> 10 | BB23: =AT23/D23 -> 11.86
