Workbook

Sheet 标准新手流程（非R）
A2: 首日60分钟可到达等级
A3: =MATCH(24*[1]经验产出!$R$5,[1]人物经验!$G$24:$G$573,1) -> 198
Q4: 经验投放 | V4: 金币奖励 | X4: 元宝奖励 | Z4: 钻石奖励 | AB4: 其他奖励 | AE4: 装备穿戴情况
A5: 流程 | B5: 地图 | C5: 初始等级 | D5: 结束等级 | E5: 地图总时间/分 | F5: 产出总经验 | G5: 玩法流程 | H5: 玩法内容 | I5: 用时/秒 | J5: 累计/分 | K5: 任务奖励 | L5: 任务奖励2 | M5: 任务奖励3 | N5: 其他奖励4 | O5: 其他奖励5 | P5: 期望等级 | Q5: 开始等级 | R5: 等级进度 | S5: 完成等级 | T5: 等级进度 | U5: 经验奖励 | V5: 金币投放 | W5: 金币奖励 | X5: 元宝投放 | Y5: 元宝奖励 | Z5: 钻石投放 | AA5: 钻石奖励 | AB5: 价值 | AC5: 数量 | AD5: 备注 | AE5: 武器 | AF5: 项链 | AG5: 戒指 | AH5: 护手 | AI5: 头盔 | AJ5: 衣服 | AK5: 腰带 | AL5: 靴子
A6: 1 | B6: 新手村 | C6: 1 | D6: =C15 -> 20 | E6: =SUM(I6:I14)/60 -> 1 | F6: =VLOOKUP(D6,新手阶段非R升级节奏!$A$2:$C$222,3,0)-VLOOKUP(C6,新手阶段非R升级节奏!$A$2:$C$222,3,0) -> 261 | G6: 主线任务100001 | H6: 对话 | I6: 5 | J6: =SUM($I$6:I6)/60 -> 0.083333333 | K6: 经验 | P6: 1 | Q6: 1 | R6: 0 | S6: 3 | T6: 0 | U6: =IF(K6="经验",ROUND(INDEX([1]人物经验!$N$24:$N$573,S6)*T6+INDEX([1]人物经验!$O$24:$O$573,S6)-INDEX([1]人物经验!$O$24:$O$573,Q6)-INDEX([1]人物经验!$N$24:$N$573,Q6)*R6,0),"") -> 9 | W6: =IF(K6="金币",INT(V6/[2]货币基础!$B$6*3600*INDEX([1]人物经验!$K$24:$K$573,P6)/1000+1)*1000,"") | Y6: =IF(K6="元宝",X6/[2]货币基础!$B$5,"") | AA6: =IF(K6="钻石",Z6/[2]货币基础!$B$4,"") | AD6: 第一套装备
G7: 主线任务100002 | H7: 采集武器 | I7: 5 | J7: =SUM($I$6:I7)/60 -> 0.16666667 | K7: 经验 | P7: 3 | Q7: =S6 -> 3 | R7: =T6 -> 0 | S7: 6 | T7: 0 | U7: =IF(K7="经验",ROUND(INDEX([1]人物经验!$N$24:$N$573,S7)*T7+INDEX([1]人物经验!$O$24:$O$573,S7)-INDEX([1]人物经验!$O$24:$O$573,Q7)-INDEX([1]人物经验!$N$24:$N$573,Q7)*R7,0),"") -> 21 | W7: =IF(K7="金币",INT(V7/[2]货币基础!$B$6*3600*INDEX([1]人物经验!$K$24:$K$573,P7)/1000+1)*1000,"") | Y7: =IF(K7="元宝",X7/[2]货币基础!$B$5,"") | AA7: =IF(K7="钻石",Z7/[2]货币基础!$B$4,"")
G8: 主线任务100003 | H8: 对话送武器 | I8: 5 | J8: =SUM($I$6:I8)/60 -> 0.25 | K8: 经验 | L8: 新手白武器 | P8: 6 | Q8: =S7 -> 6 | R8: =T7 -> 0 | S8: 9 | T8: 0 | U8: =IF(K8="经验",ROUND(INDEX([1]人物经验!$N$24:$N$573,S8)*T8+INDEX([1]人物经验!$O$24:$O$573,S8)-INDEX([1]人物经验!$O$24:$O$573,Q8)-INDEX([1]人物经验!$N$24:$N$573,Q8)*R8,0),"") -> 30 | W8: =IF(K8="金币",INT(V8/[2]货币基础!$B$6*3600*INDEX([1]人物经验!$K$24:$K$573,P8)/1000+1)*1000,"") | Y8: =IF(K8="元宝",X8/[2]货币基础!$B$5,"") | AA8: =IF(K8="钻石",Z8/[2]货币基础!$B$4,"")
G9: 主线任务100004 | H9: 穿戴武器 | I9: 5 | J9: =SUM($I$6:I9)/60 -> 0.33333333 | K9: 经验 | P9: 9 | Q9: =S8 -> 9 | R9: =T8 -> 0 | S9: 11 | T9: 0 | U9: =IF(K9="经验",ROUND(INDEX([1]人物经验!$N$24:$N$573,S9)*T9+INDEX([1]人物经验!$O$24:$O$573,S9)-INDEX([1]人物经验!$O$24:$O$573,Q9)-INDEX([1]人物经验!$N$24:$N$573,Q9)*R9,0),"") -> 25 | W9: =IF(K9="金币",INT(V9/[2]货币基础!$B$6*3600*INDEX([1]人物经验!$K$24:$K$573,P9)/1000+1)*1000,"") | Y9: =IF(K9="元宝",X9/[2]货币基础!$B$5,"") | AA9: =IF(K9="钻石",Z9/[2]货币基础!$B$4,"") | AE9: 1级白
G10: 主线任务100005 | H10: 对话开启坐骑 | I10: 10 | J10: =SUM($I$6:I10)/60 -> 0.5 | K10: 经验 | P10: 11 | Q10: =S9 -> 11 | R10: =T9 -> 0 | S10: 13 | T10: 0 | U10: =IF(K10="经验",ROUND(INDEX([1]人物经验!$N$24:$N$573,S10)*T10+INDEX([1]人物经验!$O$24:$O$573,S10)-INDEX([1]人物经验!$O$24:$O$573,Q10)-INDEX([1]人物经验!$N$24:$N$573,Q10)*R10,0),"") -> 29 | W10: =IF(K10="金币",INT(V10/[2]货币基础!$B$6*3600*INDEX([1]人物经验!$K$24:$K$573,P10)/1000+1)*1000,"") | Y10: =IF(K10="元宝",X10/[2]货币基础!$B$5,"") | AA10: =IF(K10="钻石",Z10/[2]货币基础!$B$4,"") | AD10: 获得坐骑 | AE10: 1级白
G11: 主线任务100006 | H11: 对话送衣服 | I11: 5 | J11: =SUM($I$6:I11)/60 -> 0.58333333 | K11: 经验 | L11: 新手白衣服 | P11: 13 | Q11: =S10 -> 13 | R11: =T10 -> 0 | S11: 15 | T11: 0 | U11: =IF(K11="经验",ROUND(INDEX([1]人物经验!$N$24:$N$573,S11)*T11+INDEX([1]人物经验!$O$24:$O$573,S11)-INDEX([1]人物经验!$O$24:$O$573,Q11)-INDEX([1]人物经验!$N$24:$N$573,Q11)*R11,0),"") -> 35 | W11: =IF(K11="金币",INT(V11/[2]货币基础!$B$6*3600*INDEX([1]人物经验!$K$24:$K$573,P11)/1000+1)*1000,"") | Y11: =IF(K11="元宝",X11/[2]货币基础!$B$5,"") | AA11: =IF(K11="钻石",Z11/[2]货币基础!$B$4,"") | AE11: 1级白
G12: 主线任务100007 | H12: 穿戴衣服 | I12: 5 | J12: =SUM($I$6:I12)/60 -> 0.66666667 | K12: 经验 | P12: 15 | Q12: =S11 -> 15 | R12: =T11 -> 0 | S12: 17 | T12: 0 | U12: =IF(K12="经验",ROUND(INDEX([1]人物经验!$N$24:$N$573,S12)*T12+INDEX([1]人物经验!$O$24:$O$573,S12)-INDEX([1]人物经验!$O$24:$O$573,Q12)-INDEX([1]人物经验!$N$24:$N$573,Q12)*R12,0),"") -> 41 | W12: =IF(K12="金币",INT(V12/[2]货币基础!$B$6*3600*INDEX([1]人物经验!$K$24:$K$573,P12)/1000+1)*1000,"") | Y12: =IF(K12="元宝",X12/[2]货币基础!$B$5,"") | AA12: =IF(K12="钻石",Z12/[2]货币基础!$B$4,"") | AE12: 1级白 | AJ12: 1级白
G13: 主线任务100008 | H13: 对话激活技能1 | I13: 10 | J13: =SUM($I$6:I13)/60 -> 0.83333333 | K13: 经验 | P13: 17 | Q13: =S12 -> 17 | R13: =T12 -> 0 | S13: 20 | T13: 0 | U13: =IF(K13="经验",ROUND(INDEX([1]人物经验!$N$24:$N$573,S13)*T13+INDEX([1]人物经验!$O$24:$O$573,S13)-INDEX([1]人物经验!$O$24:$O$573,Q13)-INDEX([1]人物经验!$N$24:$N$573,Q13)*R13,0),"") -> 71 | W13: =IF(K13="金币",INT(V13/[2]货币基础!$B$6*3600*INDEX([1]人物经验!$K$24:$K$573,P13)/1000+1)*1000,"") | Y13: =IF(K13="元宝",X13/[2]货币基础!$B$5,"") | AA13: =IF(K13="钻石",Z13/[2]货币基础!$B$4,"") | AD13: 激活技能1 | AE13: 1级白 | AJ13: 1级白
G14: 主线任务100009 | H14: 对话送头盔护手 | I14: 10 | J14: =SUM($I$6:I14)/60 -> 1 | K14: 新手白头盔 | L14: 新手白护手 | P14: 20 | Q14: =S13 -> 20 | R14: =T13 -> 0 | S14: 20 | T14: 0 | U14: =IF(K14="经验",ROUND(INDEX([1]人物经验!$N$24:$N$573,S14)*T14+INDEX([1]人物经验!$O$24:$O$573,S14)-INDEX([1]人物经验!$O$24:$O$573,Q14)-INDEX([1]人物经验!$N$24:$N$573,Q14)*R14,0),"") | W14: =IF(K14="金币",INT(V14/[2]货币基础!$B$6*3600*INDEX([1]人物经验!$K$24:$K$573,P14)/1000+1)*1000,"") | Y14: =IF(K14="元宝",X14/[2]货币基础!$B$5,"") | AA14: =IF(K14="钻石",Z14/[2]货币基础!$B$4,"") | AE14: 1级白 | AJ14: 1级白
A15: 2 | B15: 天门 | C15: 20 | D15: =C27 -> 40 | E15: =SUM(I15:I26)/60 -> 1 | F15: =VLOOKUP(D15,新手阶段非R升级节奏!$A$2:$C$222,3,0)-VLOOKUP(C15,新手阶段非R升级节奏!$A$2:$C$222,3,0) -> 725 | G15: 主线任务100010 | H15: 对话 | I15: 5 | J15: =SUM($I$6:I15)/60 -> 1.0833333 | K15: 经验 | L15: 新手白腰带 | M15: 新手白戒指 | P15: 20 | Q15: =S14 -> 20 | R15: =T14 -> 0 | S15: 22 | T15: 0 | U15: =IF(K15="经验",ROUND(INDEX([1]人物经验!$N$24:$N$573,S15)*T15+INDEX([1]人物经验!$O$24:$O$573,S15)-INDEX([1]人物经验!$O$24:$O$573,Q15)-INDEX([1]人物经验!$N$24:$N$573,Q15)*R15,0),"") -> 54 | W15: =IF(K15="金币",INT(V15/[2]货币基础!$B$6*3600*INDEX([1]人物经验!$K$24:$K$573,P15)/1000+1)*1000,"") | Y15: =IF(K15="元宝",X15/[2]货币基础!$B$5,"") | AA15: =IF(K15="钻石",Z15/[2]货币基础!$B$4,"") | AE15: 1级白 | AJ15: 1级白
G16: 主线任务100011 | H16: 一键穿戴 | I16: 5 | J16: =SUM($I$6:I16)/60 -> 1.1666667 | K16: 经验 | P16: 22 | Q16: =S15 -> 22 | R16: =T15 -> 0 | S16: 24 | T16: 0 | U16: =IF(K16="经验",ROUND(INDEX([1]人物经验!$N$24:$N$573,S16)*T16+INDEX([1]人物经验!$O$24:$O$573,S16)-INDEX([1]人物经验!$O$24:$O$573,Q16)-INDEX([1]人物经验!$N$24:$N$573,Q16)*R16,0),"") -> 58 | W16: =IF(K16="金币",INT(V16/[2]货币基础!$B$6*3600*INDEX([1]人物经验!$K$24:$K$573,P16)/1000+1)*1000,"") | Y16: =IF(K16="元宝",X16/[2]货币基础!$B$5,"") | AA16: =IF(K16="钻石",Z16/[2]货币基础!$B$4,"") | AE16: 1级白 | AG16: 1级白 | AH16: 1级白 | AI16: 1级白 | AJ16: 1级白 | AK16: 1级白
G17: 杀怪1 | I17: 6 | J17: =SUM($I$6:I17)/60 -> 1.2666667 | K17: 经验 | P17: 24 | Q17: =S16 -> 24 | R17: =T16 -> 0 | S17: 30 | T17: 0 | U17: =IF(K17="经验",ROUND(INDEX([1]人物经验!$N$24:$N$573,S17)*T17+INDEX([1]人物经验!$O$24:$O$573,S17)-INDEX([1]人物经验!$O$24:$O$573,Q17)-INDEX([1]人物经验!$N$24:$N$573,Q17)*R17,0),"") -> 194 | W17: =IF(K17="金币",INT(V17/[2]货币基础!$B$6*3600*INDEX([1]人物经验!$K$24:$K$573,P17)/1000+1)*1000,"") | Y17: =IF(K17="元宝",X17/[2]货币基础!$B$5,"") | AA17: =IF(K17="钻石",Z17/[2]货币基础!$B$4,"") | AE17: 1级白 | AG17: 1级白 | AH17: 1级白 | AI17: 1级白 | AJ17: 1级白 | AK17: 1级白
G18: 主线任务100012 | H18: 交杀怪1 | I18: 4 | J18: =SUM($I$6:I18)/60 -> 1.3333333 | K18: 经验 | P18: 30 | Q18: =S17 -> 30 | R18: =T17 -> 0 | S18: 31 | T18: 0 | U18: =IF(K18="经验",ROUND(INDEX([1]人物经验!$N$24:$N$573,S18)*T18+INDEX([1]人物经验!$O$24:$O$573,S18)-INDEX([1]人物经验!$O$24:$O$573,Q18)-INDEX([1]人物经验!$N$24:$N$573,Q18)*R18,0),"") -> 36 | W18: =IF(K18="金币",INT(V18/[2]货币基础!$B$6*3600*INDEX([1]人物经验!$K$24:$K$573,P18)/1000+1)*1000,"") | Y18: =IF(K18="元宝",X18/[2]货币基础!$B$5,"") | AA18: =IF(K18="钻石",Z18/[2]货币基础!$B$4,"") | AE18: 1级白 | AG18: 1级白 | AH18: 1级白 | AI18: 1级白 | AJ18: 1级白 | AK18: 1级白
G19: 主线任务100013 | H19: 对话 | I19: 5 | J19: =SUM($I$6:I19)/60 -> 1.4166667 | K19: 经验 | L19: 大招碎片1 | P19: 31 | Q19: =S18 -> 31 | R19: =T18 -> 0 | S19: 32 | T19: 0 | U19: =IF(K19="经验",ROUND(INDEX([1]人物经验!$N$24:$N$573,S19)*T19+INDEX([1]人物经验!$O$24:$O$573,S19)-INDEX([1]人物经验!$O$24:$O$573,Q19)-INDEX([1]人物经验!$N$24:$N$573,Q19)*R19,0),"") -> 37 | W19: =IF(K19="金币",INT(V19/[2]货币基础!$B$6*3600*INDEX([1]人物经验!$K$24:$K$573,P19)/1000+1)*1000,"") | Y19: =IF(K19="元宝",X19/[2]货币基础!$B$5,"") | AA19: =IF(K19="钻石",Z19/[2]货币基础!$B$4,"") | AE19: 1级白 | AG19: 1级白 | AH19: 1级白 | AI19: 1级白 | AJ19: 1级白 | AK19: 1级白
G20: 主线任务100014 | H20: 激活大招碎片1 | I20: 5 | J20: =SUM($I$6:I20)/60 -> 1.5 | K20: 元宝 | P20: 32 | Q20: =S19 -> 32 | R20: =T19 -> 0 | S20: 32 | T20: 0 | U20: =IF(K20="经验",ROUND(INDEX([1]人物经验!$N$24:$N$573,S20)*T20+INDEX([1]人物经验!$O$24:$O$573,S20)-INDEX([1]人物经验!$O$24:$O$573,Q20)-INDEX([1]人物经验!$N$24:$N$573,Q20)*R20,0),"") | W20: =IF(K20="金币",INT(V20/[2]货币基础!$B$6*3600*INDEX([1]人物经验!$K$24:$K$573,P20)/1000+1)*1000,"") | X20: 0.5 | Y20: =IF(K20="元宝",X20/[2]货币基础!$B$5,"") -> 5000 | AA20: =IF(K20="钻石",Z20/[2]货币基础!$B$4,"") | AE20: 1级白 | AG20: 1级白 | AH20: 1级白 | AI20: 1级白 | AJ20: 1级白 | AK20: 1级白
G21: 主线任务100015 | H21: 对话 | I21: 5 | J21: =SUM($I$6:I21)/60 -> 1.5833333 | K21: 经验 | L21: 大招碎片2 | P21: 32 | Q21: =S20 -> 32 | R21: =T20 -> 0 | S21: 33 | T21: 0 | U21: =IF(K21="经验",ROUND(INDEX([1]人物经验!$N$24:$N$573,S21)*T21+INDEX([1]人物经验!$O$24:$O$573,S21)-INDEX([1]人物经验!$O$24:$O$573,Q21)-INDEX([1]人物经验!$N$24:$N$573,Q21)*R21,0),"") -> 39 | W21: =IF(K21="金币",INT(V21/[2]货币基础!$B$6*3600*INDEX([1]人物经验!$K$24:$K$573,P21)/1000+1)*1000,"") | Y21: =IF(K21="元宝",X21/[2]货币基础!$B$5,"") | AA21: =IF(K21="钻石",Z21/[2]货币基础!$B$4,"") | AE21: 1级白 | AG21: 1级白 | AH21: 1级白 | AI21: 1级白 | AJ21: 1级白 | AK21: 1级白
G22: 主线任务100016 | H22: 激活大招碎片2 | I22: 5 | J22: =SUM($I$6:I22)/60 -> 1.6666667 | K22: 元宝 | P22: 33 | Q22: =S21 -> 33 | R22: =T21 -> 0 | S22: 33 | T22: 0 | U22: =IF(K22="经验",ROUND(INDEX([1]人物经验!$N$24:$N$573,S22)*T22+INDEX([1]人物经验!$O$24:$O$573,S22)-INDEX([1]人物经验!$O$24:$O$573,Q22)-INDEX([1]人物经验!$N$24:$N$573,Q22)*R22,0),"") | W22: =IF(K22="金币",INT(V22/[2]货币基础!$B$6*3600*INDEX([1]人物经验!$K$24:$K$573,P22)/1000+1)*1000,"") | X22: 0.5 | Y22: =IF(K22="元宝",X22/[2]货币基础!$B$5,"") -> 5000 | AA22: =IF(K22="钻石",Z22/[2]货币基础!$B$4,"") | AE22: 1级白 | AG22: 1级白 | AH22: 1级白 | AI22: 1级白 | AJ22: 1级白 | AK22: 1级白
G23: 主线任务100017 | H23: 激活神器 | I23: 0 | J23: =SUM($I$6:I23)/60 -> 1.6666667 | K23: 钻石 | P23: 33 | Q23: =S22 -> 33 | R23: =T22 -> 0 | S23: 33 | T23: 0 | U23: =IF(K23="经验",ROUND(INDEX([1]人物经验!$N$24:$N$573,S23)*T23+INDEX([1]人物经验!$O$24:$O$573,S23)-INDEX([1]人物经验!$O$24:$O$573,Q23)-INDEX([1]人物经验!$N$24:$N$573,Q23)*R23,0),"") | W23: =IF(K23="金币",INT(V23/[2]货币基础!$B$6*3600*INDEX([1]人物经验!$K$24:$K$573,P23)/1000+1)*1000,"") | Y23: =IF(K23="元宝",X23/[2]货币基础!$B$5,"") | Z23: 1 | AA23: =IF(K23="钻石",Z23/[2]货币基础!$B$4,"") -> 100 | AE23: 1级白 | AG23: 1级白 | AH23: 1级白 | AI23: 1级白 | AJ23: 1级白 | AK23: 1级白
G24: 杀怪2 | I24: 5 | J24: =SUM($I$6:I24)/60 -> 1.75 | K24: 经验 | P24: 33 | Q24: =S23 -> 33 | R24: =T23 -> 0 | S24: 39 | T24: 0 | U24: =IF(K24="经验",ROUND(INDEX([1]人物经验!$N$24:$N$573,S24)*T24+INDEX([1]人物经验!$O$24:$O$573,S24)-INDEX([1]人物经验!$O$24:$O$573,Q24)-INDEX([1]人物经验!$N$24:$N$573,Q24)*R24,0),"") -> 259 | W24: =IF(K24="金币",INT(V24/[2]货币基础!$B$6*3600*INDEX([1]人物经验!$K$24:$K$573,P24)/1000+1)*1000,"") | Y24: =IF(K24="元宝",X24/[2]货币基础!$B$5,"") | AA24: =IF(K24="钻石",Z24/[2]货币基础!$B$4,"") | AD24: 大招引导1 | AE24: 1级白 | AG24: 1级白 | AH24: 1级白 | AI24: 1级白 | AJ24: 1级白 | AK24: 1级白
G25: 主线任务100018 | H25: 交杀怪2 | I25: 5 | J25: =SUM($I$6:I25)/60 -> 1.8333333 | K25: 经验 | P25: 39 | Q25: =S24 -> 39 | R25: =T24 -> 0 | S25: 40 | T25: 0 | U25: =IF(K25="经验",ROUND(INDEX([1]人物经验!$N$24:$N$573,S25)*T25+INDEX([1]人物经验!$O$24:$O$573,S25)-INDEX([1]人物经验!$O$24:$O$573,Q25)-INDEX([1]人物经验!$N$24:$N$573,Q25)*R25,0),"") -> 48 | W25: =IF(K25="金币",INT(V25/[2]货币基础!$B$6*3600*INDEX([1]人物经验!$K$24:$K$573,P25)/1000+1)*1000,"") | Y25: =IF(K25="元宝",X25/[2]货币基础!$B$5,"") | AA25: =IF(K25="钻石",Z25/[2]货币基础!$B$4,"") | AE25: 1级白 | AG25: 1级白 | AH25: 1级白 | AI25: 1级白 | AJ25: 1级白 | AK25: 1级白
G26: 主线任务100019 | H26: 对话 | I26: 10 | J26: =SUM($I$6:I26)/60 -> 2 | K26: 新手白项链 | L26: 新手白靴子 | P26: 40 | Q26: =S25 -> 40 | R26: =T25 -> 0 | S26: 40 | T26: 0 | U26: =IF(K26="经验",ROUND(INDEX([1]人物经验!$N$24:$N$573,S26)*T26+INDEX([1]人物经验!$O$24:$O$573,S26)-INDEX([1]人物经验!$O$24:$O$573,Q26)-INDEX([1]人物经验!$N$24:$N$573,Q26)*R26,0),"") | W26: =IF(K26="金币",INT(V26/[2]货币基础!$B$6*3600*INDEX([1]人物经验!$K$24:$K$573,P26)/1000+1)*1000,"") | Y26: =IF(K26="元宝",X26/[2]货币基础!$B$5,"") | AA26: =IF(K26="钻石",Z26/[2]货币基础!$B$4,"") | AE26: 1级白 | AF26: 1级白 | AG26: 1级白 | AH26: 1级白 | AI26: 1级白 | AJ26: 1级白 | AK26: 1级白 | AL26: 1级白
A27: 3 | B27: 云梦幻境 | C27: 40 | D27: =C44 -> 50 | E27: =SUM(I27:I43)/60 -> 2 | F27: =VLOOKUP(D27,新手阶段非R升级节奏!$A$2:$C$222,3,0)-VLOOKUP(C27,新手阶段非R升级节奏!$A$2:$C$222,3,0) -> 780 | G27: 主线任务100020 | H27: 对话 | I27: 10 | J27: =SUM($I$6:I27)/60 -> 2.1666667 | K27: 经验 | P27: 40 | Q27: =S26 -> 40 | R27: =T26 -> 0 | S27: 41 | T27: 0 | U27: =IF(K27="经验",ROUND(INDEX([1]人物经验!$N$24:$N$573,S27)*T27+INDEX([1]人物经验!$O$24:$O$573,S27)-INDEX([1]人物经验!$O$24:$O$573,Q27)-INDEX([1]人物经验!$N$24:$N$573,Q27)*R27,0),"") -> 49 | W27: =IF(K27="金币",INT(V27/[2]货币基础!$B$6*3600*INDEX([1]人物经验!$K$24:$K$573,P27)/1000+1)*1000,"") | Y27: =IF(K27="元宝",X27/[2]货币基础!$B$5,"") | AA27: =IF(K27="钻石",Z27/[2]货币基础!$B$4,"") | AE27: 1级白 | AF27: 1级白 | AG27: 1级白 | AH27: 1级白 | AI27: 1级白 | AJ27: 1级白 | AK27: 1级白 | AL27: 1级白
G28: 杀怪3 | I28: 9 | J28: =SUM($I$6:I28)/60 -> 2.3166667 | K28: 经验 | P28: 41 | Q28: =S27 -> 41 | R28: =T27 -> 0 | S28: 43 | T28: 0 | U28: =IF(K28="经验",ROUND(INDEX([1]人物经验!$N$24:$N$573,S28)*T28+INDEX([1]人物经验!$O$24:$O$573,S28)-INDEX([1]人物经验!$O$24:$O$573,Q28)-INDEX([1]人物经验!$N$24:$N$573,Q28)*R28,0),"") -> 130 | W28: =IF(K28="金币",INT(V28/[2]货币基础!$B$6*3600*INDEX([1]人物经验!$K$24:$K$573,P28)/1000+1)*1000,"") | Y28: =IF(K28="元宝",X28/[2]货币基础!$B$5,"") | AA28: =IF(K28="钻石",Z28/[2]货币基础!$B$4,"") | AD28: 激活技能2 | AE28: 1级白 | AF28: 1级白 | AG28: 1级白 | AH28: 1级白 | AI28: 1级白 | AJ28: 1级白 | AK28: 1级白 | AL28: 1级白
G29: 主线任务100021 | H29: 交杀怪3 | I29: 5 | J29: =SUM($I$6:I29)/60 -> 2.4 | K29: 经验 | L29: 新手绿头盔 | P29: 43 | Q29: =S28 -> 43 | R29: =T28 -> 0 | S29: 43 | T29: 0.5 | U29: =IF(K29="经验",ROUND(INDEX([1]人物经验!$N$24:$N$573,S29)*T29+INDEX([1]人物经验!$O$24:$O$573,S29)-INDEX([1]人物经验!$O$24:$O$573,Q29)-INDEX([1]人物经验!$N$24:$N$573,Q29)*R29,0),"") -> 36 | W29: =IF(K29="金币",INT(V29/[2]货币基础!$B$6*3600*INDEX([1]人物经验!$K$24:$K$573,P29)/1000+1)*1000,"") | Y29: =IF(K29="元宝",X29/[2]货币基础!$B$5,"") | AA29: =IF(K29="钻石",Z29/[2]货币基础!$B$4,"") | AE29: 1级白 | AF29: 1级白 | AG29: 1级白 | AH29: 1级白 | AI29: 1级绿 | AJ29: 1级白 | AK29: 1级白 | AL29: 1级白
G30: 主线任务100022 | H30: 对话 | I30: 10 | J30: =SUM($I$6:I30)/60 -> 2.5666667 | K30: 经验 | L30: 新手绿衣服 | P30: 43 | Q30: =S29 -> 43 | R30: =T29 -> 0.5 | S30: 44 | T30: 0 | U30: =IF(K30="经验",ROUND(INDEX([1]人物经验!$N$24:$N$573,S30)*T30+INDEX([1]人物经验!$O$24:$O$573,S30)-INDEX([1]人物经验!$O$24:$O$573,Q30)-INDEX([1]人物经验!$N$24:$N$573,Q30)*R30,0),"") -> 36 | W30: =IF(K30="金币",INT(V30/[2]货币基础!$B$6*3600*INDEX([1]人物经验!$K$24:$K$573,P30)/1000+1)*1000,"") | Y30: =IF(K30="元宝",X30/[2]货币基础!$B$5,"") | AA30: =IF(K30="钻石",Z30/[2]货币基础!$B$4,"") | AE30: 1级白 | AF30: 1级白 | AG30: 1级白 | AH30: 1级白 | AI30: 1级绿 | AJ30: 1级绿 | AK30: 1级白 | AL30: 1级白
G31: 主线任务100023 | H31: 对话 | I31: 10 | J31: =SUM($I$6:I31)/60 -> 2.7333333 | K31: 经验 | P31: 44 | Q31: =S30 -> 44 | R31: =T30 -> 0 | S31: 44 | T31: 0.5 | U31: =IF(K31="经验",ROUND(INDEX([1]人物经验!$N$24:$N$573,S31)*T31+INDEX([1]人物经验!$O$24:$O$573,S31)-INDEX([1]人物经验!$O$24:$O$573,Q31)-INDEX([1]人物经验!$N$24:$N$573,Q31)*R31,0),"") -> 38 | W31: =IF(K31="金币",INT(V31/[2]货币基础!$B$6*3600*INDEX([1]人物经验!$K$24:$K$573,P31)/1000+1)*1000,"") | Y31: =IF(K31="元宝",X31/[2]货币基础!$B$5,"") | AA31: =IF(K31="钻石",Z31/[2]货币基础!$B$4,"") | AE31: 1级白 | AF31: 1级白 | AG31: 1级白 | AH31: 1级白 | AI31: 1级绿 | AJ31: 1级绿 | AK31: 1级白 | AL31: 1级白
G32: 主线任务100024 | H32: 对话 | I32: 10 | J32: =SUM($I$6:I32)/60 -> 2.9 | K32: 经验 | P32: 44 | Q32: =S31 -> 44 | R32: =T31 -> 0.5 | S32: 45 | T32: 0 | U32: =IF(K32="经验",ROUND(INDEX([1]人物经验!$N$24:$N$573,S32)*T32+INDEX([1]人物经验!$O$24:$O$573,S32)-INDEX([1]人物经验!$O$24:$O$573,Q32)-INDEX([1]人物经验!$N$24:$N$573,Q32)*R32,0),"") -> 38 | W32: =IF(K32="金币",INT(V32/[2]货币基础!$B$6*3600*INDEX([1]人物经验!$K$24:$K$573,P32)/1000+1)*1000,"") | Y32: =IF(K32="元宝",X32/[2]货币基础!$B$5,"") | AA32: =IF(K32="钻石",Z32/[2]货币基础!$B$4,"") | AE32: 1级白 | AF32: 1级白 | AG32: 1级白 | AH32: 1级白 | AI32: 1级绿 | AJ32: 1级绿 | AK32: 1级白 | AL32: 1级白
G33: 关卡1小怪 | I33: 2 | J33: =SUM($I$6:I33)/60 -> 2.9333333 | K33: 经验 | P33: 45 | Q33: =S32 -> 45 | R33: =T32 -> 0 | S33: 45 | T33: 0 | U33: =IF(K33="经验",ROUND(INDEX([1]人物经验!$N$24:$N$573,S33)*T33+INDEX([1]人物经验!$O$24:$O$573,S33)-INDEX([1]人物经验!$O$24:$O$573,Q33)-INDEX([1]人物经验!$N$24:$N$573,Q33)*R33,0),"") -> 0 | W33: =IF(K33="金币",INT(V33/[2]货币基础!$B$6*3600*INDEX([1]人物经验!$K$24:$K$573,P33)/1000+1)*1000,"") | Y33: =IF(K33="元宝",X33/[2]货币基础!$B$5,"") | AA33: =IF(K33="钻石",Z33/[2]货币基础!$B$4,"") | AE33: 1级白 | AF33: 1级白 | AG33: 1级白 | AH33: 1级白 | AI33: 1级绿 | AJ33: 1级绿 | AK33: 1级白 | AL33: 1级白
G34: 关卡1 | I34: 5 | J34: =SUM($I$6:I34)/60 -> 3.0166667 | K34: 经验 | N34: 新手绿护手 | P34: 45 | Q34: =S33 -> 45 | R34: =T33 -> 0 | S34: 47 | T34: 0 | U34: =IF(K34="经验",ROUND(INDEX([1]人物经验!$N$24:$N$573,S34)*T34+INDEX([1]人物经验!$O$24:$O$573,S34)-INDEX([1]人物经验!$O$24:$O$573,Q34)-INDEX([1]人物经验!$N$24:$N$573,Q34)*R34,0),"") -> 168 | W34: =IF(K34="金币",INT(V34/[2]货币基础!$B$6*3600*INDEX([1]人物经验!$K$24:$K$573,P34)/1000+1)*1000,"") | Y34: =IF(K34="元宝",X34/[2]货币基础!$B$5,"") | AA34: =IF(K34="钻石",Z34/[2]货币基础!$B$4,"") | AE34: 1级白 | AF34: 1级白 | AG34: 1级白 | AH34: 1级绿 | AI34: 1级绿 | AJ34: 1级绿 | AK34: 1级白 | AL34: 1级白
G35: 主线任务100025 | H35: 通关关卡1 | I35: 5 | K35: 元宝 | P35: 47 | Q35: =S34 -> 47 | R35: =T34 -> 0 | S35: 47 | T35: 0 | U35: =IF(K35="经验",ROUND(INDEX([1]人物经验!$N$24:$N$573,S35)*T35+INDEX([1]人物经验!$O$24:$O$573,S35)-INDEX([1]人物经验!$O$24:$O$573,Q35)-INDEX([1]人物经验!$N$24:$N$573,Q35)*R35,0),"") | W35: =IF(K35="金币",INT(V35/[2]货币基础!$B$6*3600*INDEX([1]人物经验!$K$24:$K$573,P35)/1000+1)*1000,"") | X35: 0.5 | Y35: =IF(K35="元宝",X35/[2]货币基础!$B$5,"") -> 5000 | AA35: =IF(K35="钻石",Z35/[2]货币基础!$B$4,"") | AE35: 1级白 | AF35: 1级白 | AG35: 1级白 | AH35: 1级绿 | AI35: 1级绿 | AJ35: 1级绿 | AK35: 1级白 | AL35: 1级白
G36: 关卡2小怪 | I36: 2 | J36: =SUM($I$6:I36)/60 -> 3.1333333 | K36: 经验 | P36: 47 | Q36: =S35 -> 47 | R36: =T35 -> 0 | S36: 47 | T36: 0 | U36: =IF(K36="经验",ROUND(INDEX([1]人物经验!$N$24:$N$573,S36)*T36+INDEX([1]人物经验!$O$24:$O$573,S36)-INDEX([1]人物经验!$O$24:$O$573,Q36)-INDEX([1]人物经验!$N$24:$N$573,Q36)*R36,0),"") -> 0 | W36: =IF(K36="金币",INT(V36/[2]货币基础!$B$6*3600*INDEX([1]人物经验!$K$24:$K$573,P36)/1000+1)*1000,"") | Y36: =IF(K36="元宝",X36/[2]货币基础!$B$5,"") | AA36: =IF(K36="钻石",Z36/[2]货币基础!$B$4,"") | AE36: 1级白 | AF36: 1级白 | AG36: 1级白 | AH36: 1级绿 | AI36: 1级绿 | AJ36: 1级绿 | AK36: 1级白 | AL36: 1级白
G37: 关卡2 | I37: 10 | J37: =SUM($I$6:I37)/60 -> 3.3 | K37: 经验 | N37: 新手绿腰带 | P37: 47 | Q37: =S36 -> 47 | R37: =T36 -> 0 | S37: 48 | T37: 0 | U37: =IF(K37="经验",ROUND(INDEX([1]人物经验!$N$24:$N$573,S37)*T37+INDEX([1]人物经验!$O$24:$O$573,S37)-INDEX([1]人物经验!$O$24:$O$573,Q37)-INDEX([1]人物经验!$N$24:$N$573,Q37)*R37,0),"") -> 90 | W37: =IF(K37="金币",INT(V37/[2]货币基础!$B$6*3600*INDEX([1]人物经验!$K$24:$K$573,P37)/1000+1)*1000,"") | Y37: =IF(K37="元宝",X37/[2]货币基础!$B$5,"") | AA37: =IF(K37="钻石",Z37/[2]货币基础!$B$4,"") | AE37: 1级白 | AF37: 1级白 | AG37: 1级白 | AH37: 1级绿 | AI37: 1级绿 | AJ37: 1级绿 | AK37: 1级绿 | AL37: 1级白
G38: 主线任务100026 | H38: 通关关卡2 | I38: 5 | K38: 元宝 | P38: 48 | Q38: =S37 -> 48 | R38: =T37 -> 0 | S38: 48 | T38: 0 | U38: =IF(K38="经验",ROUND(INDEX([1]人物经验!$N$24:$N$573,S38)*T38+INDEX([1]人物经验!$O$24:$O$573,S38)-INDEX([1]人物经验!$O$24:$O$573,Q38)-INDEX([1]人物经验!$N$24:$N$573,Q38)*R38,0),"") | W38: =IF(K38="金币",INT(V38/[2]货币基础!$B$6*3600*INDEX([1]人物经验!$K$24:$K$573,P38)/1000+1)*1000,"") | X38: 0.5 | Y38: =IF(K38="元宝",X38/[2]货币基础!$B$5,"") -> 5000 | AA38: =IF(K38="钻石",Z38/[2]货币基础!$B$4,"") | AD38: 激活技能3 | AE38: 1级白 | AF38: 1级白 | AG38: 1级白 | AH38: 1级绿 | AI38: 1级绿 | AJ38: 1级绿 | AK38: 1级绿 | AL38: 1级白
G39: 关卡3小怪 | I39: 2 | J39: =SUM($I$6:I39)/60 -> 3.4166667 | K39: 经验 | P39: 48 | Q39: =S38 -> 48 | R39: =T38 -> 0 | S39: 48 | T39: 0 | U39: =IF(K39="经验",ROUND(INDEX([1]人物经验!$N$24:$N$573,S39)*T39+INDEX([1]人物经验!$O$24:$O$573,S39)-INDEX([1]人物经验!$O$24:$O$573,Q39)-INDEX([1]人物经验!$N$24:$N$573,Q39)*R39,0),"") -> 0 | W39: =IF(K39="金币",INT(V39/[2]货币基础!$B$6*3600*INDEX([1]人物经验!$K$24:$K$573,P39)/1000+1)*1000,"") | Y39: =IF(K39="元宝",X39/[2]货币基础!$B$5,"") | AA39: =IF(K39="钻石",Z39/[2]货币基础!$B$4,"") | AE39: 1级白 | AF39: 1级白 | AG39: 1级白 | AH39: 1级绿 | AI39: 1级绿 | AJ39: 1级绿 | AK39: 1级绿 | AL39: 1级白
G40: 关卡3 | I40: 10 | J40: =SUM($I$6:I40)/60 -> 3.5833333 | K40: 经验 | P40: 48 | Q40: =S39 -> 48 | R40: =T39 -> 0 | S40: 49 | T40: 0 | U40: =IF(K40="经验",ROUND(INDEX([1]人物经验!$N$24:$N$573,S40)*T40+INDEX([1]人物经验!$O$24:$O$573,S40)-INDEX([1]人物经验!$O$24:$O$573,Q40)-INDEX([1]人物经验!$N$24:$N$573,Q40)*R40,0),"") -> 94 | W40: =IF(K40="金币",INT(V40/[2]货币基础!$B$6*3600*INDEX([1]人物经验!$K$24:$K$573,P40)/1000+1)*1000,"") | Y40: =IF(K40="元宝",X40/[2]货币基础!$B$5,"") | AA40: =IF(K40="钻石",Z40/[2]货币基础!$B$4,"") | AE40: 1级白 | AF40: 1级白 | AG40: 1级白 | AH40: 1级绿 | AI40: 1级绿 | AJ40: 1级绿 | AK40: 1级绿 | AL40: 1级白
G41: 主线任务100027 | H41: 通关关卡3 | I41: 5 | J41: =SUM($I$6:I41)/60 -> 3.6666667 | K41: 元宝 | P41: 49 | Q41: =S40 -> 49 | R41: =T40 -> 0 | S41: 49 | T41: 0 | U41: =IF(K41="经验",ROUND(INDEX([1]人物经验!$N$24:$N$573,S41)*T41+INDEX([1]人物经验!$O$24:$O$573,S41)-INDEX([1]人物经验!$O$24:$O$573,Q41)-INDEX([1]人物经验!$N$24:$N$573,Q41)*R41,0),"") | W41: =IF(K41="金币",INT(V41/[2]货币基础!$B$6*3600*INDEX([1]人物经验!$K$24:$K$573,P41)/1000+1)*1000,"") | X41: 0.5 | Y41: =IF(K41="元宝",X41/[2]货币基础!$B$5,"") -> 5000 | AA41: =IF(K41="钻石",Z41/[2]货币基础!$B$4,"") | AE41: 1级白 | AF41: 1级白 | AG41: 1级白 | AH41: 1级绿 | AI41: 1级绿 | AJ41: 1级绿 | AK41: 1级绿 | AL41: 1级白
...

Sheet 功能开启节奏
A3: 功能列表 | B3: 开启等级
A4: 坐骑 | B4: ='标准新手流程（非R）'!S10 -> 13
A5: 大招 | B5: ='标准新手流程（非R）'!S22 -> 33
A6: 技能升级 | B6: ='标准新手流程（非R）'!S48 -> 56
A7: 装备熔炼 | B7: ='标准新手流程（非R）'!S45 -> 54
A8: 装备强化 | B8: ='标准新手流程（非R）'!S46 -> 54
A9: 变身 | B9: ='标准新手流程（非R）'!S58 -> 67
A10: 个人boss（50级） | B10: ='标准新手流程（非R）'!S67 -> 69
A11: 转生 | B11: ='标准新手流程（非R）'!S63 -> 68
A12: 坐骑材料副本 | B12: ='标准新手流程（非R）'!S74 -> 71
A13: 仙侣 | B13: ='标准新手流程（非R）'!S94 -> 78
A14: 仙侣材料副本 | B14: ='标准新手流程（非R）'!S96 -> 78
A15: 神纹 | B15: ='标准新手流程（非R）'!S102 -> 81
A16: 通天塔 | B16: ='标准新手流程（非R）'!S102 -> 81
A17: 野外boss（75级） | B17: 75
A18: 日环 | C18: 12/29未上
A19: 日常 | B19: 90 | C19: 拍的
A20: 强化石材料副本 | B20: 90
A21: 金币材料副本 | B21: 110
A22: 灵脉 | B22: 110
A23: 血战四方 | B23: 130
A24: 装备精炼 | B24: 130
A25: 竞技场 | B25: 160 | C25: 12/29未上
A26: 羽翼 | B26: 275
A27: 宠物 | B27: 235
A28: 令牌 | B28: 150
A29: 守护神剑 | B29: 160

Sheet 转生节奏
B2: 任务推送时间 | E2: 完成时间
A3: 转生等阶 | B3: 推送等级 | C3: 游戏天数 | D3: 当天游戏时间/分钟 | E3: 对应等级 | F3: 游戏天数 | G3: 当天游戏时间/分钟
A4: 1转 | B4: 40 | C4: =INT(INDEX([1]人物经验!$H$24:$H$573,B4)+1) -> 1 | D4: =IF(C4=1,INDEX([1]人物经验!$H$24:$H$573,B4)*24*60,INT(MOD(INDEX([1]人物经验!$H$24:$H$573,B4),1)*24/[1]经验产出!$S$5*60)) -> 15 | E4: 70 | F4: =INT(INDEX([1]人物经验!$H$24:$H$573,E4)+1) -> 1 | G4: =ROUND(INDEX('标准新手流程（非R）'!J6:J144,MATCH(E4,'标准新手流程（非R）'!P6:P144,1)),2) -> 8.58 | H4: 新手前15分钟引导玩家跑地图推关卡，15~20分钟引导玩家转生
A5: 2转 | E5: 235 | F5: =INT(INDEX([1]人物经验!$H$24:$H$573,E5)+1) -> 2 | G5: =IF(F5=1,INDEX([1]人物经验!$H$24:$H$573,E5)*24*60,INT(MOD(INDEX([1]人物经验!$H$24:$H$573,E5),1)*24/[1]经验产出!$S$5*60)) -> 14 | H5: 2转的等级需求可能需要删除，50级跟240级数值差距过大，会导致挫败感
A6: 3转 | E6: 275 | F6: =INT(INDEX([1]人物经验!$H$24:$H$573,E6)+1) -> 3 | G6: =IF(F6=1,INDEX([1]人物经验!$H$24:$H$573,E6)*24*60,INT(MOD(INDEX([1]人物经验!$H$24:$H$573,E6),1)*24/[1]经验产出!$S$5*60)) -> 26
A7: 4转 | E7: 300 | F7: =INT(INDEX([1]人物经验!$H$24:$H$573,E7)+1) -> 5 | G7: =IF(F7=1,INDEX([1]人物经验!$H$24:$H$573,E7)*24*60,INT(MOD(INDEX([1]人物经验!$H$24:$H$573,E7),1)*24/[1]经验产出!$S$5*60)) -> 32
A8: 5转 | E8: 350 | F8: =INT(INDEX([1]人物经验!$H$24:$H$573,E8)+1) -> 12 | G8: =IF(F8=1,INDEX([1]人物经验!$H$24:$H$573,E8)*24*60,INT(MOD(INDEX([1]人物经验!$H$24:$H$573,E8),1)*24/[1]经验产出!$S$5*60)) -> 32
A9: 6转 | E9: 400 | F9: =INT(INDEX([1]人物经验!$H$24:$H$573,E9)+1) -> 19 | G9: =IF(F9=1,INDEX([1]人物经验!$H$24:$H$573,E9)*24*60,INT(MOD(INDEX([1]人物经验!$H$24:$H$573,E9),1)*24/[1]经验产出!$S$5*60)) -> 32
A10: 7转 | E10: 450 | F10: =INT(INDEX([1]人物经验!$H$24:$H$573,E10)+1) -> 26 | G10: =IF(F10=1,INDEX([1]人物经验!$H$24:$H$573,E10)*24*60,INT(MOD(INDEX([1]人物经验!$H$24:$H$573,E10),1)*24/[1]经验产出!$S$5*60)) -> 32
A11: 8转 | E11: 500 | F11: =INT(INDEX([1]人物经验!$H$24:$H$573,E11)+1) -> 40 | G11: =IF(F11=1,INDEX([1]人物经验!$H$24:$H$573,E11)*24*60,INT(MOD(INDEX([1]人物经验!$H$24:$H$573,E11),1)*24/[1]经验产出!$S$5*60)) -> 32
A12: 9转 | E12: 550 | F12: =INT(INDEX([1]人物经验!$H$24:$H$573,E12)+1) -> 54 | G12: =IF(F12=1,INDEX([1]人物经验!$H$24:$H$573,E12)*24*60,INT(MOD(INDEX([1]人物经验!$H$24:$H$573,E12),1)*24/[1]经验产出!$S$5*60)) -> 32
A15: 材料副本
A16: 进阶副本
A17: 各种玩法的时间节点

Sheet 基础装备节奏
A2: 装备等级 | B2: 时间/分 | C2: 备注
A3: 1 | B3: 刚进游戏 | C3: 第一套
A4: 50 | B4: 4 | C4: 第二套
A5: 75 | B5: 13 | C5: 第三套
A6: 120 | B6: 33.25 | C6: 第四套
A7: 200 | B7: 64 | C7: 第五套
A11: 基础装备属性
A12: 装备强化
A13: 掉落
A14: 关卡掉落
A15: 个人boss掉落
A16: 野外boss掉落
A17: 世界boss掉落

Sheet 通天塔对接
A2: 通天塔对接 | H2: 转盘对接
A3: 阶段 | B3: 层数 | C3: 玩家等级 | D3: 游戏时间/分 | E3: 属性等级 | F3: 人物经验 | H3: 奖励序号 | I3: 玩家等级 | J3: 玩家转生等级 | K3: 奖励 | L3: 抽奖层数
A4: 新手流程 | B4: 通天塔1 | C4: =VLOOKUP(B4,'标准新手流程（非R）'!$G$5:$P$144,10,0) -> 81 | D4: =VLOOKUP(B4,'标准新手流程（非R）'!$G$5:$P$144,4,0) -> 13.083333 | E4: =IF(COUNTA($C$4:C4)<8,C4-(8-COUNTA($C$4:C4))*2,C4) -> 67 | F4: =IF(ISNA(VLOOKUP(B4,'标准新手流程（非R）'!$G$5:$U$144,15,0)),"",VLOOKUP(B4,'标准新手流程（非R）'!$G$5:$U$144,15,0)) -> 585 | H4: 1 | I4: =C13 -> 92 | J4: =MATCH(I4,转生节奏!$E$4:$E$12,1) -> 1 | K4: 钻石*999 | L4: 10
A5: 新手流程 | B5: 通天塔2 | C5: =VLOOKUP(B5,'标准新手流程（非R）'!$G$5:$P$144,10,0) -> 82 | D5: =VLOOKUP(B5,'标准新手流程（非R）'!$G$5:$P$144,4,0) -> 13.166667 | E5: =IF(COUNTA($C$4:C5)<8,C5-(8-COUNTA($C$4:C5))*2,C5) -> 70 | F5: =IF(ISNA(VLOOKUP(B5,'标准新手流程（非R）'!$G$5:$U$144,15,0)),"",VLOOKUP(B5,'标准新手流程（非R）'!$G$5:$U$144,15,0)) -> 627 | H5: 2 | I5: =C23 -> 120 | J5: =MATCH(I5,转生节奏!$E$4:$E$12,1) -> 1 | K5: 120红武器 | L5: 20
A6: 新手流程 | B6: 通天塔3 | C6: =VLOOKUP(B6,'标准新手流程（非R）'!$G$5:$P$144,10,0) -> 83 | D6: =VLOOKUP(B6,'标准新手流程（非R）'!$G$5:$P$144,4,0) -> 13.25 | E6: =IF(COUNTA($C$4:C6)<8,C6-(8-COUNTA($C$4:C6))*2,C6) -> 73 | F6: =IF(ISNA(VLOOKUP(B6,'标准新手流程（非R）'!$G$5:$U$144,15,0)),"",VLOOKUP(B6,'标准新手流程（非R）'!$G$5:$U$144,15,0)) -> 656 | H6: 3 | I6: =C33 -> 155 | J6: =MATCH(I6,转生节奏!$E$4:$E$12,1) -> 1 | K6: 1转3星衣服 | L6: 30
A7: 新手流程 | B7: 通天塔4 | C7: =VLOOKUP(B7,'标准新手流程（非R）'!$G$5:$P$144,10,0) -> 84 | D7: =VLOOKUP(B7,'标准新手流程（非R）'!$G$5:$P$144,4,0) -> 13.833333 | E7: =IF(COUNTA($C$4:C7)<8,C7-(8-COUNTA($C$4:C7))*2,C7) -> 76 | F7: =IF(ISNA(VLOOKUP(B7,'标准新手流程（非R）'!$G$5:$U$144,15,0)),"",VLOOKUP(B7,'标准新手流程（非R）'!$G$5:$U$144,15,0)) -> 676 | H7: 4 | I7: =C43 -> 205 | J7: =MATCH(I7,转生节奏!$E$4:$E$12,1) -> 1 | K7: 200橙靴子 | L7: 40
A8: 新手流程 | B8: 通天塔5 | C8: =VLOOKUP(B8,'标准新手流程（非R）'!$G$5:$P$144,10,0) -> 85 | D8: =VLOOKUP(B8,'标准新手流程（非R）'!$G$5:$P$144,4,0) -> 14.166667 | E8: =IF(COUNTA($C$4:C8)<8,C8-(8-COUNTA($C$4:C8))*2,C8) -> 79 | F8: =IF(ISNA(VLOOKUP(B8,'标准新手流程（非R）'!$G$5:$U$144,15,0)),"",VLOOKUP(B8,'标准新手流程（非R）'!$G$5:$U$144,15,0)) -> 709 | H8: 5 | I8: =C48 -> 210 | J8: =MATCH(I8,转生节奏!$E$4:$E$12,1) -> 1 | K8: 200红头盔 | L8: 45
A9: 新手流程 | B9: 通天塔6 | C9: =VLOOKUP(B9,'标准新手流程（非R）'!$G$5:$P$144,10,0) -> 86 | D9: =VLOOKUP(B9,'标准新手流程（非R）'!$G$5:$P$144,4,0) -> 14.666667 | E9: =IF(COUNTA($C$4:C9)<8,C9-(8-COUNTA($C$4:C9))*2,C9) -> 82 | F9: =IF(ISNA(VLOOKUP(B9,'标准新手流程（非R）'!$G$5:$U$144,15,0)),"",VLOOKUP(B9,'标准新手流程（非R）'!$G$5:$U$144,15,0)) -> 714 | H9: 6 | I9: =C53 -> 215 | J9: =MATCH(I9,转生节奏!$E$4:$E$12,1) -> 1 | K9: 1转3星护手 | L9: 50
A10: 新手流程 | B10: 通天塔7 | C10: =VLOOKUP(B10,'标准新手流程（非R）'!$G$5:$P$144,10,0) -> 87 | D10: =VLOOKUP(B10,'标准新手流程（非R）'!$G$5:$P$144,4,0) -> 15.416667 | E10: =IF(COUNTA($C$4:C10)<8,C10-(8-COUNTA($C$4:C10))*2,C10) -> 85 | F10: =IF(ISNA(VLOOKUP(B10,'标准新手流程（非R）'!$G$5:$U$144,15,0)),"",VLOOKUP(B10,'标准新手流程（非R）'!$G$5:$U$144,15,0)) -> 758 | H10: 7 | I10: =C58 -> 220 | J10: =MATCH(I10,转生节奏!$E$4:$E$12,1) -> 1 | K10: 200红腰带 | L10: 55
A11: 新手流程 | B11: 通天塔8 | C11: =VLOOKUP(B11,'标准新手流程（非R）'!$G$5:$P$144,10,0) -> 89 | D11: =VLOOKUP(B11,'标准新手流程（非R）'!$G$5:$P$144,4,0) -> 16.25 | E11: =IF(COUNTA($C$4:C11)<8,C11-(8-COUNTA($C$4:C11))*2,C11) -> 89 | F11: =IF(ISNA(VLOOKUP(B11,'标准新手流程（非R）'!$G$5:$U$144,15,0)),"",VLOOKUP(B11,'标准新手流程（非R）'!$G$5:$U$144,15,0)) -> 800 | H11: 8 | I11: =C63 -> 225 | J11: =MATCH(I11,转生节奏!$E$4:$E$12,1) -> 1 | K11: 200红项链 | L11: 60
A12: 新手流程 | B12: 通天塔9 | C12: =VLOOKUP(B12,'标准新手流程（非R）'!$G$5:$P$144,10,0) -> 90 | D12: =VLOOKUP(B12,'标准新手流程（非R）'!$G$5:$P$144,4,0) -> 17.25 | E12: =IF(COUNTA($C$4:C12)<8,C12-(8-COUNTA($C$4:C12))*2,C12) -> 90 | F12: =IF(ISNA(VLOOKUP(B12,'标准新手流程（非R）'!$G$5:$U$144,15,0)),"",VLOOKUP(B12,'标准新手流程（非R）'!$G$5:$U$144,15,0)) -> 836 | H12: 9 | I12: =C68 -> 230 | J12: =MATCH(I12,转生节奏!$E$4:$E$12,1) -> 1 | K12: 1转3星戒指 | L12: 65
A13: 新手流程 | B13: 通天塔10 | C13: =VLOOKUP(B13,'标准新手流程（非R）'!$G$5:$P$144,10,0) -> 92 | D13: =VLOOKUP(B13,'标准新手流程（非R）'!$G$5:$P$144,4,0) -> 18.25 | E13: =IF(COUNTA($C$4:C13)<8,C13-(8-COUNTA($C$4:C13))*2,C13) -> 92 | F13: =IF(ISNA(VLOOKUP(B13,'标准新手流程（非R）'!$G$5:$U$144,15,0)),"",VLOOKUP(B13,'标准新手流程（非R）'!$G$5:$U$144,15,0)) -> 856 | H13: 10 | I13: =C73 -> 235 | J13: =MATCH(I13,转生节奏!$E$4:$E$12,1) -> 2 | K13: 2转3星武器 | L13: 70
A14: 新手流程 | B14: 通天塔11 | C14: =VLOOKUP(B14,'标准新手流程（非R）'!$G$5:$P$144,10,0) -> 106 | D14: =VLOOKUP(B14,'标准新手流程（非R）'!$G$5:$P$144,4,0) -> 25.583333 | E14: =IF(COUNTA($C$4:C14)<8,C14-(8-COUNTA($C$4:C14))*2,C14) -> 106 | F14: =IF(ISNA(VLOOKUP(B14,'标准新手流程（非R）'!$G$5:$U$144,15,0)),"",VLOOKUP(B14,'标准新手流程（非R）'!$G$5:$U$144,15,0)) -> 949
A15: 新手流程 | B15: 通天塔12 | C15: =VLOOKUP(B15,'标准新手流程（非R）'!$G$5:$P$144,10,0) -> 107 | D15: =VLOOKUP(B15,'标准新手流程（非R）'!$G$5:$P$144,4,0) -> 26.583333 | E15: =IF(COUNTA($C$4:C15)<8,C15-(8-COUNTA($C$4:C15))*2,C15) -> 107 | F15: =IF(ISNA(VLOOKUP(B15,'标准新手流程（非R）'!$G$5:$U$144,15,0)),"",VLOOKUP(B15,'标准新手流程（非R）'!$G$5:$U$144,15,0)) -> 959
A16: 新手流程 | B16: 通天塔13 | C16: =VLOOKUP(B16,'标准新手流程（非R）'!$G$5:$P$144,10,0) -> 108 | D16: =VLOOKUP(B16,'标准新手流程（非R）'!$G$5:$P$144,4,0) -> 27.583333 | E16: =IF(COUNTA($C$4:C16)<8,C16-(8-COUNTA($C$4:C16))*2,C16) -> 108 | F16: =IF(ISNA(VLOOKUP(B16,'标准新手流程（非R）'!$G$5:$U$144,15,0)),"",VLOOKUP(B16,'标准新手流程（非R）'!$G$5:$U$144,15,0)) -> 987
A17: 新手流程 | B17: 通天塔14 | C17: =VLOOKUP(B17,'标准新手流程（非R）'!$G$5:$P$144,10,0) -> 109 | D17: =VLOOKUP(B17,'标准新手流程（非R）'!$G$5:$P$144,4,0) -> 28.583333 | E17: =IF(COUNTA($C$4:C17)<8,C17-(8-COUNTA($C$4:C17))*2,C17) -> 109 | F17: =IF(ISNA(VLOOKUP(B17,'标准新手流程（非R）'!$G$5:$U$144,15,0)),"",VLOOKUP(B17,'标准新手流程（非R）'!$G$5:$U$144,15,0)) -> 1015
A18: 新手流程 | B18: 通天塔15 | C18: =VLOOKUP(B18,'标准新手流程（非R）'!$G$5:$P$144,10,0) -> 110 | D18: =VLOOKUP(B18,'标准新手流程（非R）'!$G$5:$P$144,4,0) -> 29.583333 | E18: =IF(COUNTA($C$4:C18)<8,C18-(8-COUNTA($C$4:C18))*2,C18) -> 110 | F18: =IF(ISNA(VLOOKUP(B18,'标准新手流程（非R）'!$G$5:$U$144,15,0)),"",VLOOKUP(B18,'标准新手流程（非R）'!$G$5:$U$144,15,0)) -> 1043
A19: 新手流程 | B19: 通天塔16 | C19: =VLOOKUP(B19,'标准新手流程（非R）'!$G$5:$P$144,10,0) -> 112 | D19: =VLOOKUP(B19,'标准新手流程（非R）'!$G$5:$P$144,4,0) -> 30.666667 | E19: =IF(COUNTA($C$4:C19)<8,C19-(8-COUNTA($C$4:C19))*2,C19) -> 112 | F19: =IF(ISNA(VLOOKUP(B19,'标准新手流程（非R）'!$G$5:$U$144,15,0)),"",VLOOKUP(B19,'标准新手流程（非R）'!$G$5:$U$144,15,0)) -> 1082
A20: 新手流程 | B20: 通天塔17 | C20: =VLOOKUP(B20,'标准新手流程（非R）'!$G$5:$P$144,10,0) -> 114 | D20: =VLOOKUP(B20,'标准新手流程（非R）'!$G$5:$P$144,4,0) -> 31.666667 | E20: =IF(COUNTA($C$4:C20)<8,C20-(8-COUNTA($C$4:C20))*2,C20) -> 114 | F20: =IF(ISNA(VLOOKUP(B20,'标准新手流程（非R）'!$G$5:$U$144,15,0)),"",VLOOKUP(B20,'标准新手流程（非R）'!$G$5:$U$144,15,0)) -> 1142
A21: 新手流程 | B21: 通天塔18 | C21: =VLOOKUP(B21,'标准新手流程（非R）'!$G$5:$P$144,10,0) -> 116 | D21: =VLOOKUP(B21,'标准新手流程（非R）'!$G$5:$P$144,4,0) -> 32.666667 | E21: =IF(COUNTA($C$4:C21)<8,C21-(8-COUNTA($C$4:C21))*2,C21) -> 116 | F21: =IF(ISNA(VLOOKUP(B21,'标准新手流程（非R）'!$G$5:$U$144,15,0)),"",VLOOKUP(B21,'标准新手流程（非R）'!$G$5:$U$144,15,0)) -> 1183
A22: 新手流程 | B22: 通天塔19 | C22: =VLOOKUP(B22,'标准新手流程（非R）'!$G$5:$P$144,10,0) -> 118 | D22: =VLOOKUP(B22,'标准新手流程（非R）'!$G$5:$P$144,4,0) -> 33.666667 | E22: =IF(COUNTA($C$4:C22)<8,C22-(8-COUNTA($C$4:C22))*2,C22) -> 118 | F22: =IF(ISNA(VLOOKUP(B22,'标准新手流程（非R）'!$G$5:$U$144,15,0)),"",VLOOKUP(B22,'标准新手流程（非R）'!$G$5:$U$144,15,0)) -> 1245
A23: 新手流程 | B23: 通天塔20 | C23: =VLOOKUP(B23,'标准新手流程（非R）'!$G$5:$P$144,10,0) -> 120 | D23: =VLOOKUP(B23,'标准新手流程（非R）'!$G$5:$P$144,4,0) -> 34.666667 | E23: =IF(COUNTA($C$4:C23)<8,C23-(8-COUNTA($C$4:C23))*2,C23) -> 120 | F23: =IF(ISNA(VLOOKUP(B23,'标准新手流程（非R）'!$G$5:$U$144,15,0)),"",VLOOKUP(B23,'标准新手流程（非R）'!$G$5:$U$144,15,0)) -> 1288
A24: 新手流程 | B24: 通天塔21 | C24: =VLOOKUP(B24,'标准新手流程（非R）'!$G$5:$P$144,10,0) -> 122 | D24: =VLOOKUP(B24,'标准新手流程（非R）'!$G$5:$P$144,4,0) -> 35.75 | E24: =IF(COUNTA($C$4:C24)<8,C24-(8-COUNTA($C$4:C24))*2,C24) -> 122 | F24: =IF(ISNA(VLOOKUP(B24,'标准新手流程（非R）'!$G$5:$U$144,15,0)),"",VLOOKUP(B24,'标准新手流程（非R）'!$G$5:$U$144,15,0)) -> 1433
A25: 新手流程 | B25: 通天塔22 | C25: =VLOOKUP(B25,'标准新手流程（非R）'!$G$5:$P$144,10,0) -> 124 | D25: =VLOOKUP(B25,'标准新手流程（非R）'!$G$5:$P$144,4,0) -> 36.75 | E25: =IF(COUNTA($C$4:C25)<8,C25-(8-COUNTA($C$4:C25))*2,C25) -> 124 | F25: =IF(ISNA(VLOOKUP(B25,'标准新手流程（非R）'!$G$5:$U$144,15,0)),"",VLOOKUP(B25,'标准新手流程（非R）'!$G$5:$U$144,15,0)) -> 1547
... A28: 新手流程 | B28: 通天塔25 | C28: =VLOOKUP(B28,'标准新手流程（非R）'!$G$5:$P$144,10,0) -> 130 | D28: =VLOOKUP(B28,'标准新手流程（非R）'!$G$5:$P$144,4,0) -> 39.75 | E28: =IF(COUNTA($C$4:C28)<8,C28-(8-COUNTA($C$4:C28))*2,C28) -> 130 | F28: =IF(ISNA(VLOOKUP(B28,'标准新手流程（非R）'!$G$5:$U$144,15,0)),"",VLOOKUP(B28,'标准新手流程（非R）'!$G$5:$U$144,15,0)) -> 1990
A29: 对接区间 | B29: 通天塔26 | C29: 135 | E29: =IF(COUNTA($C$4:C29)<8,C29-(8-COUNTA($C$4:C29))*2,C29) -> 135 | F29: =IF(ISNA(VLOOKUP(B29,'标准新手流程（非R）'!$G$5:$U$144,15,0)),"",VLOOKUP(B29,'标准新手流程（非R）'!$G$5:$U$144,15,0))
A30: 对接区间 | B30: 通天塔27 | C30: 140 | E30: =IF(COUNTA($C$4:C30)<8,C30-(8-COUNTA($C$4:C30))*2,C30) -> 140 | F30: =IF(ISNA(VLOOKUP(B30,'标准新手流程（非R）'!$G$5:$U$144,15,0)),"",VLOOKUP(B30,'标准新手流程（非R）'!$G$5:$U$144,15,0))
A31: 对接区间 | B31: 通天塔28 | C31: 145 | E31: =IF(COUNTA($C$4:C31)<8,C31-(8-COUNTA($C$4:C31))*2,C31) -> 145 | F31: =IF(ISNA(VLOOKUP(B31,'标准新手流程（非R）'!$G$5:$U$144,15,0)),"",VLOOKUP(B31,'标准新手流程（非R）'!$G$5:$U$144,15,0))
A32: 对接区间 | B32: 通天塔29 | C32: 150 | E32: =IF(COUNTA($C$4:C32)<8,C32-(8-COUNTA($C$4:C32))*2,C32) -> 150 | F32: =IF(ISNA(VLOOKUP(B32,'标准新手流程（非R）'!$G$5:$U$144,15,0)),"",VLOOKUP(B32,'标准新手流程（非R）'!$G$5:$U$144,15,0))
A33: 对接区间 | B33: 通天塔30 | C33: 155 | E33: =IF(COUNTA($C$4:C33)<8,C33-(8-COUNTA($C$4:C33))*2,C33) -> 155 | F33: =IF(ISNA(VLOOKUP(B33,'标准新手流程（非R）'!$G$5:$U$144,15,0)),"",VLOOKUP(B33,'标准新手流程（非R）'!$G$5:$U$144,15,0))
A34: 对接区间 | B34: 通天塔31 | C34: 160 | E34: =IF(COUNTA($C$4:C34)<8,C34-(8-COUNTA($C$4:C34))*2,C34) -> 160 | F34: =IF(ISNA(VLOOKUP(B34,'标准新手流程（非R）'!$G$5:$U$144,15,0)),"",VLOOKUP(B34,'标准新手流程（非R）'!$G$5:$U$144,15,0))
A35: 对接区间 | B35: 通天塔32 | C35: 165 | E35: =IF(COUNTA($C$4:C35)<8,C35-(8-COUNTA($C$4:C35))*2,C35) -> 165 | F35: =IF(ISNA(VLOOKUP(B35,'标准新手流程（非R）'!$G$5:$U$144,15,0)),"",VLOOKUP(B35,'标准新手流程（非R）'!$G$5:$U$144,15,0))
A36: 对接区间 | B36: 通天塔33 | C36: 170 | E36: =IF(COUNTA($C$4:C36)<8,C36-(8-COUNTA($C$4:C36))*2,C36) -> 170 | F36: =IF(ISNA(VLOOKUP(B36,'标准新手流程（非R）'!$G$5:$U$144,15,0)),"",VLOOKUP(B36,'标准新手流程（非R）'!$G$5:$U$144,15,0))
A37: 对接区间 | B37: 通天塔34 | C37: 180 | E37: =IF(COUNTA($C$4:C37)<8,C37-(8-COUNTA($C$4:C37))*2,C37) -> 180 | F37: =IF(ISNA(VLOOKUP(B37,'标准新手流程（非R）'!$G$5:$U$144,15,0)),"",VLOOKUP(B37,'标准新手流程（非R）'!$G$5:$U$144,15,0))
A38: 对接区间 | B38: 通天塔35 | C38: 190 | E38: =IF(COUNTA($C$4:C38)<8,C38-(8-COUNTA($C$4:C38))*2,C38) -> 190 | F38: =IF(ISNA(VLOOKUP(B38,'标准新手流程（非R）'!$G$5:$U$144,15,0)),"",VLOOKUP(B38,'标准新手流程（非R）'!$G$5:$U$144,15,0))
A39: 对接区间 | B39: 通天塔36 | C39: 201 | E39: =IF(COUNTA($C$4:C39)<8,C39-(8-COUNTA($C$4:C39))*2,C39) -> 201 | F39: =IF(ISNA(VLOOKUP(B39,'标准新手流程（非R）'!$G$5:$U$144,15,0)),"",VLOOKUP(B39,'标准新手流程（非R）'!$G$5:$U$144,15,0))
A40: 对接区间 | B40: 通天塔37 | C40: 202 | E40: =IF(COUNTA($C$4:C40)<8,C40-(8-COUNTA($C$4:C40))*2,C40) -> 202 | F40: =IF(ISNA(VLOOKUP(B40,'标准新手流程（非R）'!$G$5:$U$144,15,0)),"",VLOOKUP(B40,'标准新手流程（非R）'!$G$5:$U$144,15,0))
... A73: 对接区间 | B73: 通天塔70 | C73: 235 | E73: =IF(COUNTA($C$4:C73)<8,C73-(8-COUNTA($C$4:C73))*2,C73) -> 235 | F73: =IF(ISNA(VLOOKUP(B73,'标准新手流程（非R）'!$G$5:$U$144,15,0)),"",VLOOKUP(B73,'标准新手流程（非R）'!$G$5:$U$144,15,0))

Sheet 关卡对接
A2: 关卡对接
A3: 属性难度对接关卡
A4: 30
A6: 阶段 | B6: 层数 | C6: 玩家等级 | D6: 游戏时间/分 | E6: 属性等级 | F6: 通关经验 | H6: 理论对接关卡
A7: 新手阶段 | B7: 关卡1 | C7: =VLOOKUP(B7,'标准新手流程（非R）'!$G$5:$Q$144,11,0) -> 45 | E7: =IF(D7<15,C7-INT(15-D7),C7) -> 30 | F7: =IF(ISNA(VLOOKUP(B7,'标准新手流程（非R）'!$G$5:$U$144,15,0)),"",VLOOKUP(B7,'标准新手流程（非R）'!$G$5:$U$144,15,0)) -> 168 | I7: 特殊
A8: 新手阶段 | B8: 关卡2 | C8: =VLOOKUP(B8,'标准新手流程（非R）'!$G$5:$Q$144,11,0) -> 47 | E8: =IF(D8<15,C8-INT(15-D8),C8) -> 32 | F8: =IF(ISNA(VLOOKUP(B8,'标准新手流程（非R）'!$G$5:$U$144,15,0)),"",VLOOKUP(B8,'标准新手流程（非R）'!$G$5:$U$144,15,0)) -> 90 | I8: 特殊
A9: 新手阶段 | B9: 关卡3 | C9: =VLOOKUP(B9,'标准新手流程（非R）'!$G$5:$Q$144,11,0) -> 48 | E9: =IF(D9<15,C9-INT(15-D9),C9) -> 33 | F9: =IF(ISNA(VLOOKUP(B9,'标准新手流程（非R）'!$G$5:$U$144,15,0)),"",VLOOKUP(B9,'标准新手流程（非R）'!$G$5:$U$144,15,0)) -> 94 | I9: 特殊
A10: 新手阶段 | B10: 关卡4 | C10: =VLOOKUP(B10,'标准新手流程（非R）'!$G$5:$Q$144,11,0) -> 60 | D10: =INDEX('标准新手流程（非R）'!$J$6:$J$144,MATCH(C10,'标准新手流程（非R）'!$P$6:$P$144,1)) -> 6.25 | E10: =IF(D10<15,C10-INT(15-D10),C10) -> 52 | F10: =IF(ISNA(VLOOKUP(B10,'标准新手流程（非R）'!$G$5:$U$144,15,0)),"",VLOOKUP(B10,'标准新手流程（非R）'!$G$5:$U$144,15,0)) -> 423 | H10: =VLOOKUP(C10,[1]人物经验!$A$23:$I$573,9,0) -> 12
A11: 新手阶段 | B11: 关卡5 | C11: =VLOOKUP(B11,'标准新手流程（非R）'!$G$5:$Q$144,11,0) -> 62 | D11: =INDEX('标准新手流程（非R）'!$J$6:$J$144,MATCH(C11,'标准新手流程（非R）'!$P$6:$P$144,1)) -> 6.5 | E11: =IF(D11<15,C11-INT(15-D11),C11) -> 54 | F11: =IF(ISNA(VLOOKUP(B11,'标准新手流程（非R）'!$G$5:$U$144,15,0)),"",VLOOKUP(B11,'标准新手流程（非R）'!$G$5:$U$144,15,0)) -> 467 | H11: =VLOOKUP(C11,[1]人物经验!$A$23:$I$573,9,0) -> 13
A12: 新手阶段 | B12: 关卡6 | C12: =VLOOKUP(B12,'标准新手流程（非R）'!$G$5:$Q$144,11,0) -> 64 | D12: =INDEX('标准新手流程（非R）'!$J$6:$J$144,MATCH(C12,'标准新手流程（非R）'!$P$6:$P$144,1)) -> 6.8333333 | E12: =IF(D12<15,C12-INT(15-D12),C12) -> 56 | F12: =IF(ISNA(VLOOKUP(B12,'标准新手流程（非R）'!$G$5:$U$144,15,0)),"",VLOOKUP(B12,'标准新手流程（非R）'!$G$5:$U$144,15,0)) -> 507 | H12: =VLOOKUP(C12,[1]人物经验!$A$23:$I$573,9,0) -> 14
A13: 新手阶段 | B13: 关卡7 | C13: =VLOOKUP(B13,'标准新手流程（非R）'!$G$5:$Q$144,11,0) -> 66 | D13: =INDEX('标准新手流程（非R）'!$J$6:$J$144,MATCH(C13,'标准新手流程（非R）'!$P$6:$P$144,1)) -> 7.1666667 | E13: =IF(D13<15,C13-INT(15-D13),C13) -> 59 | F13: =IF(ISNA(VLOOKUP(B13,'标准新手流程（非R）'!$G$5:$U$144,15,0)),"",VLOOKUP(B13,'标准新手流程（非R）'!$G$5:$U$144,15,0)) -> 275 | H13: =VLOOKUP(C13,[1]人物经验!$A$23:$I$573,9,0) -> 15
A14: 新手阶段 | B14: 关卡8 | C14: =VLOOKUP(B14,'标准新手流程（非R）'!$G$5:$Q$144,11,0) -> 67 | D14: =INDEX('标准新手流程（非R）'!$J$6:$J$144,MATCH(C14,'标准新手流程（非R）'!$P$6:$P$144,1)) -> 7.4166667 | E14: =IF(D14<15,C14-INT(15-D14),C14) -> 60 | F14: =IF(ISNA(VLOOKUP(B14,'标准新手流程（非R）'!$G$5:$U$144,15,0)),"",VLOOKUP(B14,'标准新手流程（非R）'!$G$5:$U$144,15,0)) -> 284 | H14: =VLOOKUP(C14,[1]人物经验!$A$23:$I$573,9,0) -> 15
A15: 新手阶段 | B15: 关卡9 | C15: =VLOOKUP(B15,'标准新手流程（非R）'!$G$5:$Q$144,11,0) -> 69 | D15: =INDEX('标准新手流程（非R）'!$J$6:$J$144,MATCH(C15,'标准新手流程（非R）'!$P$6:$P$144,1)) -> 8.3333333 | E15: =IF(D15<15,C15-INT(15-D15),C15) -> 63 | F15: =IF(ISNA(VLOOKUP(B15,'标准新手流程（非R）'!$G$5:$U$144,15,0)),"",VLOOKUP(B15,'标准新手流程（非R）'!$G$5:$U$144,15,0)) -> 157 | H15: =VLOOKUP(C15,[1]人物经验!$A$23:$I$573,9,0) -> 16
A16: 新手阶段 | B16: 关卡10 | C16: =VLOOKUP(B16,'标准新手流程（非R）'!$G$5:$Q$144,11,0) -> 70 | D16: =INDEX('标准新手流程（非R）'!$J$6:$J$144,MATCH(C16,'标准新手流程（非R）'!$P$6:$P$144,1)) -> 8.5833333 | E16: =IF(D16<15,C16-INT(15-D16),C16) -> 64 | F16: =IF(ISNA(VLOOKUP(B16,'标准新手流程（非R）'!$G$5:$U$144,15,0)),"",VLOOKUP(B16,'标准新手流程（非R）'!$G$5:$U$144,15,0)) -> 334 | H16: =VLOOKUP(C16,[1]人物经验!$A$23:$I$573,9,0) -> 17
A17: 新手阶段 | B17: 关卡11 | C17: =VLOOKUP(B17,'标准新手流程（非R）'!$G$5:$Q$144,11,0) -> 72 | D17: =INDEX('标准新手流程（非R）'!$J$6:$J$144,MATCH(C17,'标准新手流程（非R）'!$P$6:$P$144,1)) -> 9.75 | E17: =IF(D17<15,C17-INT(15-D17),C17) -> 67 | F17: =IF(ISNA(VLOOKUP(B17,'标准新手流程（非R）'!$G$5:$U$144,15,0)),"",VLOOKUP(B17,'标准新手流程（非R）'!$G$5:$U$144,15,0)) -> 298 | H17: =VLOOKUP(C17,[1]人物经验!$A$23:$I$573,9,0) -> 18
A18: 新手阶段 | B18: 关卡12 | C18: =VLOOKUP(B18,'标准新手流程（非R）'!$G$5:$Q$144,11,0) -> 73 | D18: =INDEX('标准新手流程（非R）'!$J$6:$J$144,MATCH(C18,'标准新手流程（非R）'!$P$6:$P$144,1)) -> 10 | E18: =IF(D18<15,C18-INT(15-D18),C18) -> 68 | F18: =IF(ISNA(VLOOKUP(B18,'标准新手流程（非R）'!$G$5:$U$144,15,0)),"",VLOOKUP(B18,'标准新手流程（非R）'!$G$5:$U$144,15,0)) -> 267 | H18: =VLOOKUP(C18,[1]人物经验!$A$23:$I$573,9,0) -> 18
A19: 新手阶段 | B19: 关卡13 | C19: =VLOOKUP(B19,'标准新手流程（非R）'!$G$5:$Q$144,11,0) -> 74 | D19: =INDEX('标准新手流程（非R）'!$J$6:$J$144,MATCH(C19,'标准新手流程（非R）'!$P$6:$P$144,1)) -> 10.5 | E19: =IF(D19<15,C19-INT(15-D19),C19) -> 70 | F19: =IF(ISNA(VLOOKUP(B19,'标准新手流程（非R）'!$G$5:$U$144,15,0)),"",VLOOKUP(B19,'标准新手流程（非R）'!$G$5:$U$144,15,0)) -> 244 | H19: =VLOOKUP(C19,[1]人物经验!$A$23:$I$573,9,0) -> 19
A20: 新手阶段 | B20: 关卡14 | C20: =VLOOKUP(B20,'标准新手流程（非R）'!$G$5:$Q$144,11,0) -> 75 | D20: =INDEX('标准新手流程（非R）'!$J$6:$J$144,MATCH(C20,'标准新手流程（非R）'!$P$6:$P$144,1)) -> 10.833333 | E20: =IF(D20<15,C20-INT(15-D20),C20) -> 71 | F20: =IF(ISNA(VLOOKUP(B20,'标准新手流程（非R）'!$G$5:$U$144,15,0)),"",VLOOKUP(B20,'标准新手流程（非R）'!$G$5:$U$144,15,0)) -> 253 | H20: =VLOOKUP(C20,[1]人物经验!$A$23:$I$573,9,0) -> 19
A21: 新手阶段 | B21: 关卡15 | C21: =VLOOKUP(B21,'标准新手流程（非R）'!$G$5:$Q$144,11,0) -> 76 | D21: =INDEX('标准新手流程（非R）'!$J$6:$J$144,MATCH(C21,'标准新手流程（非R）'!$P$6:$P$144,1)) -> 11.25 | E21: =IF(D21<15,C21-INT(15-D21),C21) -> 73 | F21: =IF(ISNA(VLOOKUP(B21,'标准新手流程（非R）'!$G$5:$U$144,15,0)),"",VLOOKUP(B21,'标准新手流程（非R）'!$G$5:$U$144,15,0)) -> 269 | H21: =VLOOKUP(C21,[1]人物经验!$A$23:$I$573,9,0) -> 20
... A25: 新手阶段 | B25: 关卡19 | C25: =VLOOKUP(B25,'标准新手流程（非R）'!$G$5:$Q$144,11,0) -> 93 | D25: =INDEX('标准新手流程（非R）'!$J$6:$J$144,MATCH(C25,'标准新手流程（非R）'!$P$6:$P$144,1)) -> 18.833333 | E25: =IF(D25<15,C25-INT(15-D25),C25) -> 93 | F25: =IF(ISNA(VLOOKUP(B25,'标准新手流程（非R）'!$G$5:$U$144,15,0)),"",VLOOKUP(B25,'标准新手流程（非R）'!$G$5:$U$144,15,0)) -> 235 | H25: =VLOOKUP(C25,[1]人物经验!$A$23:$I$573,9,0) -> 29
A26: 对接阶段 | B26: 关卡20 | C26: 85 | D26: =INDEX('标准新手流程（非R）'!$J$6:$J$144,MATCH(C26,'标准新手流程（非R）'!$P$6:$P$144,1)) -> 14.166667 | E26: =IF(D26<15,C26-INT(15-D26),C26) -> 85 | F26: =IF(ISNA(VLOOKUP(B26,'标准新手流程（非R）'!$G$5:$U$144,15,0)),"",VLOOKUP(B26,'标准新手流程（非R）'!$G$5:$U$144,15,0)) -> 261 | H26: =VLOOKUP(C26,[1]人物经验!$A$23:$I$573,9,0) -> 24
A27: 对接阶段 | B27: 关卡21 | C27: 86 | D27: =INDEX('标准新手流程（非R）'!$J$6:$J$144,MATCH(C27,'标准新手流程（非R）'!$P$6:$P$144,1)) -> 14.666667 | E27: =IF(D27<15,C27-INT(15-D27),C27) -> 86 | F27: =IF(ISNA(VLOOKUP(B27,'标准新手流程（非R）'!$G$5:$U$144,15,0)),"",VLOOKUP(B27,'标准新手流程（非R）'!$G$5:$U$144,15,0)) -> 291 | H27: =VLOOKUP(C27,[1]人物经验!$A$23:$I$573,9,0) -> 25
A28: 对接阶段 | B28: 关卡22 | C28: 87 | D28: =INDEX('标准新手流程（非R）'!$J$6:$J$144,MATCH(C28,'标准新手流程（非R）'!$P$6:$P$144,1)) -> 15.416667 | E28: =IF(D28<15,C28-INT(15-D28),C28) -> 87 | F28: =IF(ISNA(VLOOKUP(B28,'标准新手流程（非R）'!$G$5:$U$144,15,0)),"",VLOOKUP(B28,'标准新手流程（非R）'!$G$5:$U$144,15,0)) -> 330 | H28: =VLOOKUP(C28,[1]人物经验!$A$23:$I$573,9,0) -> 26
A29: 对接阶段 | B29: 关卡23 | C29: 88 | D29: =INDEX('标准新手流程（非R）'!$J$6:$J$144,MATCH(C29,'标准新手流程（非R）'!$P$6:$P$144,1)) -> 15.416667 | E29: =IF(D29<15,C29-INT(15-D29),C29) -> 88 | F29: =IF(ISNA(VLOOKUP(B29,'标准新手流程（非R）'!$G$5:$U$144,15,0)),"",VLOOKUP(B29,'标准新手流程（非R）'!$G$5:$U$144,15,0)) | H29: =VLOOKUP(C29,[1]人物经验!$A$23:$I$573,9,0) -> 26
A30: 对接阶段 | B30: 关卡24 | C30: 89 | D30: =INDEX('标准新手流程（非R）'!$J$6:$J$144,MATCH(C30,'标准新手流程（非R）'!$P$6:$P$144,1)) -> 16.25 | E30: =IF(D30<15,C30-INT(15-D30),C30) -> 89 | F30: =IF(ISNA(VLOOKUP(B30,'标准新手流程（非R）'!$G$5:$U$144,15,0)),"",VLOOKUP(B30,'标准新手流程（非R）'!$G$5:$U$144,15,0)) | H30: =VLOOKUP(C30,[1]人物经验!$A$23:$I$573,9,0) -> 27
A31: 对接阶段 | B31: 关卡25 | C31: 90 | D31: =INDEX('标准新手流程（非R）'!$J$6:$J$144,MATCH(C31,'标准新手流程（非R）'!$P$6:$P$144,1)) -> 17.25 | E31: =IF(D31<15,C31-INT(15-D31),C31) -> 90 | F31: =IF(ISNA(VLOOKUP(B31,'标准新手流程（非R）'!$G$5:$U$144,15,0)),"",VLOOKUP(B31,'标准新手流程（非R）'!$G$5:$U$144,15,0)) | H31: =VLOOKUP(C31,[1]人物经验!$A$23:$I$573,9,0) -> 27
A32: 对接阶段 | B32: 关卡26 | C32: 91 | D32: =INDEX('标准新手流程（非R）'!$J$6:$J$144,MATCH(C32,'标准新手流程（非R）'!$P$6:$P$144,1)) -> 17.25 | E32: =IF(D32<15,C32-INT(15-D32),C32) -> 91 | F32: =IF(ISNA(VLOOKUP(B32,'标准新手流程（非R）'!$G$5:$U$144,15,0)),"",VLOOKUP(B32,'标准新手流程（非R）'!$G$5:$U$144,15,0)) | H32: =VLOOKUP(C32,[1]人物经验!$A$23:$I$573,9,0) -> 28
A33: 对接阶段 | B33: 关卡27 | C33: 92 | D33: =INDEX('标准新手流程（非R）'!$J$6:$J$144,MATCH(C33,'标准新手流程（非R）'!$P$6:$P$144,1)) -> 18.333333 | E33: =IF(D33<15,C33-INT(15-D33),C33) -> 92 | F33: =IF(ISNA(VLOOKUP(B33,'标准新手流程（非R）'!$G$5:$U$144,15,0)),"",VLOOKUP(B33,'标准新手流程（非R）'!$G$5:$U$144,15,0)) | H33: =VLOOKUP(C33,[1]人物经验!$A$23:$I$573,9,0) -> 28
A34: 对接阶段 | B34: 关卡28 | C34: 93 | D34: =INDEX('标准新手流程（非R）'!$J$6:$J$144,MATCH(C34,'标准新手流程（非R）'!$P$6:$P$144,1)) -> 18.833333 | E34: =IF(D34<15,C34-INT(15-D34),C34) -> 93 | F34: =IF(ISNA(VLOOKUP(B34,'标准新手流程（非R）'!$G$5:$U$144,15,0)),"",VLOOKUP(B34,'标准新手流程（非R）'!$G$5:$U$144,15,0)) | H34: =VLOOKUP(C34,[1]人物经验!$A$23:$I$573,9,0) -> 29
A35: 对接阶段 | B35: 关卡29 | C35: 94 | D35: =INDEX('标准新手流程（非R）'!$J$6:$J$144,MATCH(C35,'标准新手流程（非R）'!$P$6:$P$144,1)) -> 18.833333 | E35: =IF(D35<15,C35-INT(15-D35),C35) -> 94 | F35: =IF(ISNA(VLOOKUP(B35,'标准新手流程（非R）'!$G$5:$U$144,15,0)),"",VLOOKUP(B35,'标准新手流程（非R）'!$G$5:$U$144,15,0)) | H35: =VLOOKUP(C35,[1]人物经验!$A$23:$I$573,9,0) -> 30
A36: 对接阶段 | B36: 关卡30 | C36: 95 | D36: =INDEX('标准新手流程（非R）'!$J$6:$J$144,MATCH(C36,'标准新手流程（非R）'!$P$6:$P$144,1)) -> 19.666667 | E36: =IF(D36<15,C36-INT(15-D36),C36) -> 95 | F36: =IF(ISNA(VLOOKUP(B36,'标准新手流程（非R）'!$G$5:$U$144,15,0)),"",VLOOKUP(B36,'标准新手流程（非R）'!$G$5:$U$144,15,0)) | H36: =VLOOKUP(C36,[1]人物经验!$A$23:$I$573,9,0) -> 30
A37: 对接阶段 | B37: 关卡31 | C37: 96 | D37: =INDEX('标准新手流程（非R）'!$J$6:$J$144,MATCH(C37,'标准新手流程（非R）'!$P$6:$P$144,1)) -> 19.666667 | E37: =IF(D37<15,C37-INT(15-D37),C37) -> 96 | F37: =IF(ISNA(VLOOKUP(B37,'标准新手流程（非R）'!$G$5:$U$144,15,0)),"",VLOOKUP(B37,'标准新手流程（非R）'!$G$5:$U$144,15,0)) | H37: =VLOOKUP(C37,[1]人物经验!$A$23:$I$573,9,0) -> 31
... A141: 对接阶段 | B141: 关卡135 | C141: 200 | D141: =INDEX('标准新手流程（非R）'!$J$6:$J$144,MATCH(C141,'标准新手流程（非R）'!$P$6:$P$144,1)) -> 44.833333 | E141: =IF(D141<15,C141-INT(15-D141),C141) -> 200 | F141: =IF(ISNA(VLOOKUP(B141,'标准新手流程（非R）'!$G$5:$U$144,15,0)),"",VLOOKUP(B141,'标准新手流程（非R）'!$G$5:$U$144,15,0)) | H141: =VLOOKUP(C141,[1]人物经验!$A$23:$I$573,9,0) -> 154

Sheet 仙兵对接
A3: 仙兵编号 | B3: 碎片编号 | C3: 产出途径 | D3: 功能 | E3: 激活时间/分 | I3: 玩家等级 | J3: 碎片数量 | K3: 仙兵编号
A4: =[3]仙兵!A12 -> 1 | B4: =[3]仙兵!B12 -> 1 | C4: ='标准新手流程（非R）'!G23 -> 主线任务100017 | D4: 大招 | E4: =IF(ISNA(VLOOKUP(C4,'标准新手流程（非R）'!$G$5:$J$144,4,0)),INDEX('标准新手流程（非R）'!$J$6:$J$144,MATCH(INDEX(关卡对接!$C$7:$C$141,MATCH(C4,关卡对接!$B$7:$B$141,0)),'标准新手流程（非R）'!$P$6:$P$144,1)),VLOOKUP(C4,'标准新手流程（非R）'!$G$5:$J$144,4,0)) -> 1.6666667 | I4: 1
A5: =[3]仙兵!A13 -> 2 | B5: =[3]仙兵!B13 -> 1 | C5: ='标准新手流程（非R）'!G52 -> 关卡4 | D5: 变身 | E5: =IF(ISNA(VLOOKUP(C5,'标准新手流程（非R）'!$G$5:$J$144,4,0)),INDEX('标准新手流程（非R）'!$J$6:$J$144,MATCH(INDEX(关卡对接!$C$7:$C$141,MATCH(C5,关卡对接!$B$7:$B$141,0)),'标准新手流程（非R）'!$P$6:$P$144,1)),VLOOKUP(C5,'标准新手流程（非R）'!$G$5:$J$144,4,0)) -> 6.25 | I5: 2
A6: =[3]仙兵!A14 -> 2 | B6: =[3]仙兵!B14 -> 2 | C6: ='标准新手流程（非R）'!G54 -> 关卡5 | D6: 变身 | E6: =IF(ISNA(VLOOKUP(C6,'标准新手流程（非R）'!$G$5:$J$144,4,0)),INDEX('标准新手流程（非R）'!$J$6:$J$144,MATCH(INDEX(关卡对接!$C$7:$C$141,MATCH(C6,关卡对接!$B$7:$B$141,0)),'标准新手流程（非R）'!$P$6:$P$144,1)),VLOOKUP(C6,'标准新手流程（非R）'!$G$5:$J$144,4,0)) -> 6.5 | I6: 3
A7: =[3]仙兵!A15 -> 2 | B7: =[3]仙兵!B15 -> 3 | C7: ='标准新手流程（非R）'!G56 -> 关卡6 | D7: 变身 | E7: =IF(ISNA(VLOOKUP(C7,'标准新手流程（非R）'!$G$5:$J$144,4,0)),INDEX('标准新手流程（非R）'!$J$6:$J$144,MATCH(INDEX(关卡对接!$C$7:$C$141,MATCH(C7,关卡对接!$B$7:$B$141,0)),'标准新手流程（非R）'!$P$6:$P$144,1)),VLOOKUP(C7,'标准新手流程（非R）'!$G$5:$J$144,4,0)) -> 6.8333333 | I7: 4
A8: =[3]仙兵!A16 -> 2 | B8: =[3]仙兵!B16 -> 4 | C8: ='标准新手流程（非R）'!G58 -> 关卡7 | D8: 变身 | E8: =IF(ISNA(VLOOKUP(C8,'标准新手流程（非R）'!$G$5:$J$144,4,0)),INDEX('标准新手流程（非R）'!$J$6:$J$144,MATCH(INDEX(关卡对接!$C$7:$C$141,MATCH(C8,关卡对接!$B$7:$B$141,0)),'标准新手流程（非R）'!$P$6:$P$144,1)),VLOOKUP(C8,'标准新手流程（非R）'!$G$5:$J$144,4,0)) -> 7.1666667 | I8: 5
A9: =[3]仙兵!A17 -> 3 | B9: =[3]仙兵!B17 -> 1 | C9: ='标准新手流程（非R）'!G88 -> 关卡14 | D9: 仙侣 | E9: =IF(ISNA(VLOOKUP(C9,'标准新手流程（非R）'!$G$5:$J$144,4,0)),INDEX('标准新手流程（非R）'!$J$6:$J$144,MATCH(INDEX(关卡对接!$C$7:$C$141,MATCH(C9,关卡对接!$B$7:$B$141,0)),'标准新手流程（非R）'!$P$6:$P$144,1)),VLOOKUP(C9,'标准新手流程（非R）'!$G$5:$J$144,4,0)) -> 10.833333 | I9: 6
A10: =[3]仙兵!A18 -> 3 | B10: =[3]仙兵!B18 -> 2 | C10: ='标准新手流程（非R）'!G90 -> 关卡15 | D10: 仙侣 | E10: =IF(ISNA(VLOOKUP(C10,'标准新手流程（非R）'!$G$5:$J$144,4,0)),INDEX('标准新手流程（非R）'!$J$6:$J$144,MATCH(INDEX(关卡对接!$C$7:$C$141,MATCH(C10,关卡对接!$B$7:$B$141,0)),'标准新手流程（非R）'!$P$6:$P$144,1)),VLOOKUP(C10,'标准新手流程（非R）'!$G$5:$J$144,4,0)) -> 11.166667 | I10: 7
A11: =[3]仙兵!A19 -> 3 | B11: =[3]仙兵!B19 -> 3 | C11: ='标准新手流程（非R）'!G92 -> 关卡16 | D11: 仙侣 | E11: =IF(ISNA(VLOOKUP(C11,'标准新手流程（非R）'!$G$5:$J$144,4,0)),INDEX('标准新手流程（非R）'!$J$6:$J$144,MATCH(INDEX(关卡对接!$C$7:$C$141,MATCH(C11,关卡对接!$B$7:$B$141,0)),'标准新手流程（非R）'!$P$6:$P$144,1)),VLOOKUP(C11,'标准新手流程（非R）'!$G$5:$J$144,4,0)) -> 11.5 | I11: 8
A12: =[3]仙兵!A20 -> 3 | B12: =[3]仙兵!B20 -> 4 | C12: ='标准新手流程（非R）'!G94 -> 关卡17 | D12: 仙侣 | E12: =IF(ISNA(VLOOKUP(C12,'标准新手流程（非R）'!$G$5:$J$144,4,0)),INDEX('标准新手流程（非R）'!$J$6:$J$144,MATCH(INDEX(关卡对接!$C$7:$C$141,MATCH(C12,关卡对接!$B$7:$B$141,0)),'标准新手流程（非R）'!$P$6:$P$144,1)),VLOOKUP(C12,'标准新手流程（非R）'!$G$5:$J$144,4,0)) -> 11.833333 | I12: 9
A13: =[3]仙兵!A21 -> 4 | B13: =[3]仙兵!B21 -> 1 | C13: ='标准新手流程（非R）'!G117 -> 关卡19 | D13: 聚宝盘 | E13: =IF(ISNA(VLOOKUP(C13,'标准新手流程（非R）'!$G$5:$J$144,4,0)),INDEX('标准新手流程（非R）'!$J$6:$J$144,MATCH(INDEX(关卡对接!$C$7:$C$141,MATCH(C13,关卡对接!$B$7:$B$141,0)),'标准新手流程（非R）'!$P$6:$P$144,1)),VLOOKUP(C13,'标准新手流程（非R）'!$G$5:$J$144,4,0)) -> 18.833333 | I13: 10
A14: =[3]仙兵!A22 -> 4 | B14: =[3]仙兵!B22 -> 2 | C14: ='标准新手流程（非R）'!G118 -> 关卡20 | D14: 聚宝盘 | E14: =IF(ISNA(VLOOKUP(C14,'标准新手流程（非R）'!$G$5:$J$144,4,0)),INDEX('标准新手流程（非R）'!$J$6:$J$144,MATCH(INDEX(关卡对接!$C$7:$C$141,MATCH(C14,关卡对接!$B$7:$B$141,0)),'标准新手流程（非R）'!$P$6:$P$144,1)),VLOOKUP(C14,'标准新手流程（非R）'!$G$5:$J$144,4,0)) -> 19.583333 | I14: 11
A15: =[3]仙兵!A23 -> 4 | B15: =[3]仙兵!B23 -> 3 | C15: ='标准新手流程（非R）'!G120 -> 关卡21 | D15: 聚宝盘 | E15: =IF(ISNA(VLOOKUP(C15,'标准新手流程（非R）'!$G$5:$J$144,4,0)),INDEX('标准新手流程（非R）'!$J$6:$J$144,MATCH(INDEX(关卡对接!$C$7:$C$141,MATCH(C15,关卡对接!$B$7:$B$141,0)),'标准新手流程（非R）'!$P$6:$P$144,1)),VLOOKUP(C15,'标准新手流程（非R）'!$G$5:$J$144,4,0)) -> 20.416667 | I15: 12
A16: =[3]仙兵!A24 -> 4 | B16: =[3]仙兵!B24 -> 4 | C16: ='标准新手流程（非R）'!G121 -> 关卡22 | D16: 聚宝盘 | E16: =IF(ISNA(VLOOKUP(C16,'标准新手流程（非R）'!$G$5:$J$144,4,0)),INDEX('标准新手流程（非R）'!$J$6:$J$144,MATCH(INDEX(关卡对接!$C$7:$C$141,MATCH(C16,关卡对接!$B$7:$B$141,0)),'标准新手流程（非R）'!$P$6:$P$144,1)),VLOOKUP(C16,'标准新手流程（非R）'!$G$5:$J$144,4,0)) -> 21.416667 | I16: 13
A17: =[3]仙兵!A25 -> 5 | B17: =[3]仙兵!B25 -> 1 | C17: 关卡28 | D17: 特殊效果1 | I17: 14
A18: =[3]仙兵!A26 -> 5 | B18: =[3]仙兵!B26 -> 2 | C18: 关卡34 | D18: 特殊效果1 | I18: 15
A19: =[3]仙兵!A27 -> 5 | B19: =[3]仙兵!B27 -> 3 | C19: 关卡40 | D19: 特殊效果1 | I19: 16
A20: =[3]仙兵!A28 -> 5 | B20: =[3]仙兵!B28 -> 4 | C20: 关卡46 | D20: 特殊效果1 | I20: 17
A21: =[3]仙兵!A29 -> 5 | B21: =[3]仙兵!B29 -> 5 | C21: 关卡52 | D21: 特殊效果1 | I21: 18
A22: =[3]仙兵!A30 -> 5 | B22: =[3]仙兵!B30 -> 6 | C22: 关卡58 | D22: 特殊效果1 | I22: 19
A23: =[3]仙兵!A31 -> 6 | B23: =[3]仙兵!B31 -> 1 | C23: 关卡64 | D23: 特殊效果2 | I23: 20
A24: =[3]仙兵!A32 -> 6 | B24: =[3]仙兵!B32 -> 2 | C24: 关卡70 | D24: 特殊效果2 | I24: 21
A25: =[3]仙兵!A33 -> 6 | B25: =[3]仙兵!B33 -> 3 | C25: 关卡76 | D25: 特殊效果2 | I25: 22
A26: =[3]仙兵!A34 -> 6 | B26: =[3]仙兵!B34 -> 4 | C26: 关卡82 | D26: 特殊效果2 | I26: 23
A27: =[3]仙兵!A35 -> 6 | B27: =[3]仙兵!B35 -> 5 | C27: 关卡88 | D27: 特殊效果2 | I27: 24
A28: =[3]仙兵!A36 -> 6 | B28: =[3]仙兵!B36 -> 6 | C28: 关卡94 | D28: 特殊效果2 | I28: 25
A29: =[3]仙兵!A37 -> 7 | B29: =[3]仙兵!B37 -> 1 | C29: 关卡100 | D29: 特殊效果3 | I29: 26
A30: =[3]仙兵!A38 -> 7 | B30: =[3]仙兵!B38 -> 2 | C30: 关卡106 | D30: 特殊效果3 | I30: 27 | J30: 1 | K30: 1
A31: =[3]仙兵!A39 -> 7 | B31: =[3]仙兵!B39 -> 3 | C31: 关卡112 | D31: 特殊效果3 | I31: 28 | J31: 1 | K31: 1
A32: =[3]仙兵!A40 -> 7 | B32: =[3]仙兵!B40 -> 4 | C32: 关卡118 | D32: 特殊效果3 | I32: 29 | J32: 1 | K32: 1
A33: =[3]仙兵!A41 -> 7 | B33: =[3]仙兵!B41 -> 5 | C33: 关卡124 | D33: 特殊效果3 | I33: 30 | J33: 1 | K33: 1
A34: =[3]仙兵!A42 -> 7 | B34: =[3]仙兵!B42 -> 6 | C34: 关卡130 | D34: 特殊效果3 | I34: 31 | J34: 1 | K34: 1
I35: 32 | J35: 1 | K35: 1
I36: 33 | J36: 1 | K36: 1
I37: 34 | J37: 1 | K37: 1
I38: 35 | J38: 1 | K38: 1
I39: 36 | J39: 1 | K39: 1
I40: 37 | J40: 1 | K40: 1
I41: 38 | J41: 1 | K41: 1
I42: 39 | J42: 1 | K42: 1
...

Sheet 职业技能对接
A2: 技能名称 | B2: 开启等级
A3: 小群攻 | B3: ='标准新手流程（非R）'!S13 -> 20
A4: 飞剑 | B4: ='标准新手流程（非R）'!S27 -> 41
A5: 扇形 | B5: ='标准新手流程（非R）'!S37 -> 48
A6: 飞轮 | B6: ='标准新手流程（非R）'!S47 -> 56
A7: 落冰 | B7: ='标准新手流程（非R）'!S69 -> 70

Sheet 前3天非R装备模拟
B2: 基础装备穿戴情况 | J2: 神装穿戴情况
A3: 非R等级 | B3: 武器 | C3: 项链 | D3: 戒指 | E3: 护手 | F3: 头盔 | G3: 衣服 | H3: 腰带 | I3: 靴子 | J3: 武器 | K3: 项链 | L3: 戒指 | M3: 护手 | N3: 头盔 | O3: 衣服 | P3: 腰带 | Q3: 靴子
A4: 1 | B4: =IF(VLOOKUP($A4,'标准新手流程（非R）'!$P$5:$AL$144,MATCH(B$3,'标准新手流程（非R）'!$P$5:$AL$5,0),1)="","",VLOOKUP($A4,'标准新手流程（非R）'!$P$5:$AL$144,MATCH(B$3,'标准新手流程（非R）'!$P$5:$AL$5,0),1)) | C4: =IF(VLOOKUP($A4,'标准新手流程（非R）'!$P$5:$AL$144,MATCH(C$3,'标准新手流程（非R）'!$P$5:$AL$5,0),1)="","",VLOOKUP($A4,'标准新手流程（非R）'!$P$5:$AL$144,MATCH(C$3,'标准新手流程（非R）'!$P$5:$AL$5,0),1)) | D4: =IF(VLOOKUP($A4,'标准新手流程（非R）'!$P$5:$AL$144,MATCH(D$3,'标准新手流程（非R）'!$P$5:$AL$5,0),1)="","",VLOOKUP($A4,'标准新手流程（非R）'!$P$5:$AL$144,MATCH(D$3,'标准新手流程（非R）'!$P$5:$AL$5,0),1)) | E4: =IF(VLOOKUP($A4,'标准新手流程（非R）'!$P$5:$AL$144,MATCH(E$3,'标准新手流程（非R）'!$P$5:$AL$5,0),1)="","",VLOOKUP($A4,'标准新手流程（非R）'!$P$5:$AL$144,MATCH(E$3,'标准新手流程（非R）'!$P$5:$AL$5,0),1)) | F4: =IF(VLOOKUP($A4,'标准新手流程（非R）'!$P$5:$AL$144,MATCH(F$3,'标准新手流程（非R）'!$P$5:$AL$5,0),1)="","",VLOOKUP($A4,'标准新手流程（非R）'!$P$5:$AL$144,MATCH(F$3,'标准新手流程（非R）'!$P$5:$AL$5,0),1)) | G4: =IF(VLOOKUP($A4,'标准新手流程（非R）'!$P$5:$AL$144,MATCH(G$3,'标准新手流程（非R）'!$P$5:$AL$5,0),1)="","",VLOOKUP($A4,'标准新手流程（非R）'!$P$5:$AL$144,MATCH(G$3,'标准新手流程（非R）'!$P$5:$AL$5,0),1)) | H4: =IF(VLOOKUP($A4,'标准新手流程（非R）'!$P$5:$AL$144,MATCH(H$3,'标准新手流程（非R）'!$P$5:$AL$5,0),1)="","",VLOOKUP($A4,'标准新手流程（非R）'!$P$5:$AL$144,MATCH(H$3,'标准新手流程（非R）'!$P$5:$AL$5,0),1)) | I4: =IF(VLOOKUP($A4,'标准新手流程（非R）'!$P$5:$AL$144,MATCH(I$3,'标准新手流程（非R）'!$P$5:$AL$5,0),1)="","",VLOOKUP($A4,'标准新手流程（非R）'!$P$5:$AL$144,MATCH(I$3,'标准新手流程（非R）'!$P$5:$AL$5,0),1))
A5: 2 | B5: =IF(VLOOKUP($A5,'标准新手流程（非R）'!$P$5:$AL$144,MATCH(B$3,'标准新手流程（非R）'!$P$5:$AL$5,0),1)="","",VLOOKUP($A5,'标准新手流程（非R）'!$P$5:$AL$144,MATCH(B$3,'标准新手流程（非R）'!$P$5:$AL$5,0),1)) | C5: =IF(VLOOKUP($A5,'标准新手流程（非R）'!$P$5:$AL$144,MATCH(C$3,'标准新手流程（非R）'!$P$5:$AL$5,0),1)="","",VLOOKUP($A5,'标准新手流程（非R）'!$P$5:$AL$144,MATCH(C$3,'标准新手流程（非R）'!$P$5:$AL$5,0),1)) | D5: =IF(VLOOKUP($A5,'标准新手流程（非R）'!$P$5:$AL$144,MATCH(D$3,'标准新手流程（非R）'!$P$5:$AL$5,0),1)="","",VLOOKUP($A5,'标准新手流程（非R）'!$P$5:$AL$144,MATCH(D$3,'标准新手流程（非R）'!$P$5:$AL$5,0),1)) | E5: =IF(VLOOKUP($A5,'标准新手流程（非R）'!$P$5:$AL$144,MATCH(E$3,'标准新手流程（非R）'!$P$5:$AL$5,0),1)="","",VLOOKUP($A5,'标准新手流程（非R）'!$P$5:$AL$144,MATCH(E$3,'标准新手流程（非R）'!$P$5:$AL$5,0),1)) | F5: =IF(VLOOKUP($A5,'标准新手流程（非R）'!$P$5:$AL$144,MATCH(F$3,'标准新手流程（非R）'!$P$5:$AL$5,0),1)="","",VLOOKUP($A5,'标准新手流程（非R）'!$P$5:$AL$144,MATCH(F$3,'标准新手流程（非R）'!$P$5:$AL$5,0),1)) | G5: =IF(VLOOKUP($A5,'标准新手流程（非R）'!$P$5:$AL$144,MATCH(G$3,'标准新手流程（非R）'!$P$5:$AL$5,0),1)="","",VLOOKUP($A5,'标准新手流程（非R）'!$P$5:$AL$144,MATCH(G$3,'标准新手流程（非R）'!$P$5:$AL$5,0),1)) | H5: =IF(VLOOKUP($A5,'标准新手流程（非R）'!$P$5:$AL$144,MATCH(H$3,'标准新手流程（非R）'!$P$5:$AL$5,0),1)="","",VLOOKUP($A5,'标准新手流程（非R）'!$P$5:$AL$144,MATCH(H$3,'标准新手流程（非R）'!$P$5:$AL$5,0),1)) | I5: =IF(VLOOKUP($A5,'标准新手流程（非R）'!$P$5:$AL$144,MATCH(I$3,'标准新手流程（非R）'!$P$5:$AL$5,0),1)="","",VLOOKUP($A5,'标准新手流程（非R）'!$P$5:$AL$144,MATCH(I$3,'标准新手流程（非R）'!$P$5:$AL$5,0),1))
A6: 3 | B6: =IF(VLOOKUP($A6,'标准新手流程（非R）'!$P$5:$AL$144,MATCH(B$3,'标准新手流程（非R）'!$P$5:$AL$5,0),1)="","",VLOOKUP($A6,'标准新手流程（非R）'!$P$5:$AL$144,MATCH(B$3,'标准新手流程（非R）'!$P$5:$AL$5,0),1)) | C6: =IF(VLOOKUP($A6,'标准新手流程（非R）'!$P$5:$AL$144,MATCH(C$3,'标准新手流程（非R）'!$P$5:$AL$5,0),1)="","",VLOOKUP($A6,'标准新手流程（非R）'!$P$5:$AL$144,MATCH(C$3,'标准新手流程（非R）'!$P$5:$AL$5,0),1)) | D6: =IF(VLOOKUP($A6,'标准新手流程（非R）'!$P$5:$AL$144,MATCH(D$3,'标准新手流程（非R）'!$P$5:$AL$5,0),1)="","",VLOOKUP($A6,'标准新手流程（非R）'!$P$5:$AL$144,MATCH(D$3,'标准新手流程（非R）'!$P$5:$AL$5,0),1)) | E6: =IF(VLOOKUP($A6,'标准新手流程（非R）'!$P$5:$AL$144,MATCH(E$3,'标准新手流程（非R）'!$P$5:$AL$5,0),1)="","",VLOOKUP($A6,'标准新手流程（非R）'!$P$5:$AL$144,MATCH(E$3,'标准新手流程（非R）'!$P$5:$AL$5,0),1)) | F6: =IF(VLOOKUP($A6,'标准新手流程（非R）'!$P$5:$AL$144,MATCH(F$3,'标准新手流程（非R）'!$P$5:$AL$5,0),1)="","",VLOOKUP($A6,'标准新手流程（非R）'!$P$5:$AL$144,MATCH(F$3,'标准新手流程（非R）'!$P$5:$AL$5,0),1)) | G6: =IF(VLOOKUP($A6,'标准新手流程（非R）'!$P$5:$AL$144,MATCH(G$3,'标准新手流程（非R）'!$P$5:$AL$5,0),1)="","",VLOOKUP($A6,'标准新手流程（非R）'!$P$5:$AL$144,MATCH(G$3,'标准新手流程（非R）'!$P$5:$AL$5,0),1)) | H6: =IF(VLOOKUP($A6,'标准新手流程（非R）'!$P$5:$AL$144,MATCH(H$3,'标准新手流程（非R）'!$P$5:$AL$5,0),1)="","",VLOOKUP($A6,'标准新手流程（非R）'!$P$5:$AL$144,MATCH(H$3,'标准新手流程（非R）'!$P$5:$AL$5,0),1)) | I6: =IF(VLOOKUP($A6,'标准新手流程（非R）'!$P$5:$AL$144,MATCH(I$3,'标准新手流程（非R）'!$P$5:$AL$5,0),1)="","",VLOOKUP($A6,'标准新手流程（非R）'!$P$5:$AL$144,MATCH(I$3,'标准新手流程（非R）'!$P$5:$AL$5,0),1))
A7: 4 | B7: =IF(VLOOKUP($A7,'标准新手流程（非R）'!$P$5:$AL$144,MATCH(B$3,'标准新手流程（非R）'!$P$5:$AL$5,0),1)="","",VLOOKUP($A7,'标准新手流程（非R）'!$P$5:$AL$144,MATCH(B$3,'标准新手流程（非R）'!$P$5:$AL$5,0),1)) | C7: =IF(VLOOKUP($A7,'标准新手流程（非R）'!$P$5:$AL$144,MATCH(C$3,'标准新手流程（非R）'!$P$5:$AL$5,0),1)="","",VLOOKUP($A7,'标准新手流程（非R）'!$P$5:$AL$144,MATCH(C$3,'标准新手流程（非R）'!$P$5:$AL$5,0),1)) | D7: =IF(VLOOKUP($A7,'标准新手流程（非R）'!$P$5:$AL$144,MATCH(D$3,'标准新手流程（非R）'!$P$5:$AL$5,0),1)="","",VLOOKUP($A7,'标准新手流程（非R）'!$P$5:$AL$144,MATCH(D$3,'标准新手流程（非R）'!$P$5:$AL$5,0),1)) | E7: =IF(VLOOKUP($A7,'标准新手流程（非R）'!$P$5:$AL$144,MATCH(E$3,'标准新手流程（非R）'!$P$5:$AL$5,0),1)="","",VLOOKUP($A7,'标准新手流程（非R）'!$P$5:$AL$144,MATCH(E$3,'标准新手流程（非R）'!$P$5:$AL$5,0),1)) | F7: =IF(VLOOKUP($A7,'标准新手流程（非R）'!$P$5:$AL$144,MATCH(F$3,'标准新手流程（非R）'!$P$5:$AL$5,0),1)="","",VLOOKUP($A7,'标准新手流程（非R）'!$P$5:$AL$144,MATCH(F$3,'标准新手流程（非R）'!$P$5:$AL$5,0),1)) | G7: =IF(VLOOKUP($A7,'标准新手流程（非R）'!$P$5:$AL$144,MATCH(G$3,'标准新手流程（非R）'!$P$5:$AL$5,0),1)="","",VLOOKUP($A7,'标准新手流程（非R）'!$P$5:$AL$144,MATCH(G$3,'标准新手流程（非R）'!$P$5:$AL$5,0),1)) | H7: =IF(VLOOKUP($A7,'标准新手流程（非R）'!$P$5:$AL$144,MATCH(H$3,'标准新手流程（非R）'!$P$5:$AL$5,0),1)="","",VLOOKUP($A7,'标准新手流程（非R）'!$P$5:$AL$144,MATCH(H$3,'标准新手流程（非R）'!$P$5:$AL$5,0),1)) | I7: =IF(VLOOKUP($A7,'标准新手流程（非R）'!$P$5:$AL$144,MATCH(I$3,'标准新手流程（非R）'!$P$5:$AL$5,0),1)="","",VLOOKUP($A7,'标准新手流程（非R）'!$P$5:$AL$144,MATCH(I$3,'标准新手流程（非R）'!$P$5:$AL$5,0),1))
A8: 5 | B8: =IF(VLOOKUP($A8,'标准新手流程（非R）'!$P$5:$AL$144,MATCH(B$3,'标准新手流程（非R）'!$P$5:$AL$5,0),1)="","",VLOOKUP($A8,'标准新手流程（非R）'!$P$5:$AL$144,MATCH(B$3,'标准新手流程（非R）'!$P$5:$AL$5,0),1)) | C8: =IF(VLOOKUP($A8,'标准新手流程（非R）'!$P$5:$AL$144,MATCH(C$3,'标准新手流程（非R）'!$P$5:$AL$5,0),1)="","",VLOOKUP($A8,'标准新手流程（非R）'!$P$5:$AL$144,MATCH(C$3,'标准新手流程（非R）'!$P$5:$AL$5,0),1)) | D8: =IF(VLOOKUP($A8,'标准新手流程（非R）'!$P$5:$AL$144,MATCH(D$3,'标准新手流程（非R）'!$P$5:$AL$5,0),1)="","",VLOOKUP($A8,'标准新手流程（非R）'!$P$5:$AL$144,MATCH(D$3,'标准新手流程（非R）'!$P$5:$AL$5,0),1)) | E8: =IF(VLOOKUP($A8,'标准新手流程（非R）'!$P$5:$AL$144,MATCH(E$3,'标准新手流程（非R）'!$P$5:$AL$5,0),1)="","",VLOOKUP($A8,'标准新手流程（非R）'!$P$5:$AL$144,MATCH(E$3,'标准新手流程（非R）'!$P$5:$AL$5,0),1)) | F8: =IF(VLOOKUP($A8,'标准新手流程（非R）'!$P$5:$AL$144,MATCH(F$3,'标准新手流程（非R）'!$P$5:$AL$5,0),1)="","",VLOOKUP($A8,'标准新手流程（非R）'!$P$5:$AL$144,MATCH(F$3,'标准新手流程（非R）'!$P$5:$AL$5,0),1)) | G8: =IF(VLOOKUP($A8,'标准新手流程（非R）'!$P$5:$AL$144,MATCH(G$3,'标准新手流程（非R）'!$P$5:$AL$5,0),1)="","",VLOOKUP($A8,'标准新手流程（非R）'!$P$5:$AL$144,MATCH(G$3,'标准新手流程（非R）'!$P$5:$AL$5,0),1)) | H8: =IF(VLOOKUP($A8,'标准新手流程（非R）'!$P$5:$AL$144,MATCH(H$3,'标准新手流程（非R）'!$P$5:$AL$5,0),1)="","",VLOOKUP($A8,'标准新手流程（非R）'!$P$5:$AL$144,MATCH(H$3,'标准新手流程（非R）'!$P$5:$AL$5,0),1)) | I8: =IF(VLOOKUP($A8,'标准新手流程（非R）'!$P$5:$AL$144,MATCH(I$3,'标准新手流程（非R）'!$P$5:$AL$5,0),1)="","",VLOOKUP($A8,'标准新手流程（非R）'!$P$5:$AL$144,MATCH(I$3,'标准新手流程（非R）'!$P$5:$AL$5,0),1))
